Workbook
Name r_DWZDM_r: #REF!

Sheet 汇总表
A1: 华东区域指挥部存量逾期账款汇总表
B2: 单位：万元
A3: 序号 | B3: 所属经营部 | C3: 经营小组 | D3: 责任人 | E3: 期初逾期 | F3: 期末逾期金额（3.31） | L3: 累计回款 | M3: 回款率
F4: 逾期账龄 | K4: 合计金额
F5: 3个月以内 | G5: 3-6个月 | H5: 6-12个月 | I5: 1-3年 | J5: 3年以上
A6: 1 | B6: 浙江省经营部 | C6: 杭州经营小组 | D6: 唐作栋 | E6: 894.85204 | F6: {=(SUMPRODUCT((华东区域指挥部主办逾期!$L$3:$L$31>0)*(华东区域指挥部主办逾期!$T$3:$T$31=D6)*华东区域指挥部主办逾期!$L$3:$L$31*华东区域指挥部主办逾期!$Q$3:$Q$31*华东区域指挥部主办逾期!$U$3:$U$31)+SUMPRODUCT((华东区域指挥部主办逾期!$L$3:$L$31>0)*(华东区域指挥部主办逾期!$W$3:$W$31=D6)*华东区域指挥部主办逾期!$L$3:$L$31*华东区域指挥部主办逾期!$Q$3:$Q$31*华东区域指挥部主办逾期!$X$3:$X$31)+SUMPRODUCT((华东区域指挥协办逾期!$L$3:$L$10>0)*(华东区域指挥协办逾期!$T$3:$T$10=D6)*华东区域指挥协办逾期!$L$3:$L$10*华东区域指挥协办逾期!$Q$3:$Q$10*华东区域指挥协办逾期!$U$3:$U$10)+SUMPRODUCT((华东区域指挥协办逾期!$L$3:$L$10>0)*(华东区域指挥协办逾期!$W$3:$W$10=D6)*华东区域指挥协办逾期!$L$3:$L$10*华东区域指挥协办逾期!$Q$3:$Q$10*华东区域指挥协办逾期!$X$3:$X$10))/10000} -> 0 | G6: {=(SUMPRODUCT((华东区域指挥部主办逾期!$M$3:$M$31>0)*(华东区域指挥部主办逾期!$T$3:$T$31=D6)*华东区域指挥部主办逾期!$M$3:$M$31*华东区域指挥部主办逾期!$Q$3:$Q$31*华东区域指挥部主办逾期!$U$3:$U$31)+SUMPRODUCT((华东区域指挥部主办逾期!$M$3:$M$31>0)*(华东区域指挥部主办逾期!$W$3:$W$31=D6)*华东区域指挥部主办逾期!$M$3:$M$31*华东区域指挥部主办逾期!$Q$3:$Q$31*华东区域指挥部主办逾期!$X$3:$X$31)+SUMPRODUCT((华东区域指挥协办逾期!$M$3:$M$10>0)*(华东区域指挥协办逾期!$T$3:$T$10=D6)*华东区域指挥协办逾期!$M$3:$M$10*华东区域指挥协办逾期!$Q$3:$Q$10*华东区域指挥协办逾期!$U$3:$U$10)+SUMPRODUCT((华东区域指挥协办逾期!$M$3:$M$10>0)*(华东区域指挥协办逾期!$W$3:$W$10=D6)*华东区域指挥协办逾期!$M$3:$M$10*华东区域指挥协办逾期!$Q$3:$Q$10*华东区域指挥协办逾期!$X$3:$X$10))/10000} -> 383.9201 | H6: {=(SUMPRODUCT((华东区域指挥部主办逾期!$N$3:$N$31>0)*(华东区域指挥部主办逾期!$T$3:$T$31=D6)*华东区域指挥部主办逾期!$N$3:$N$31*华东区域指挥部主办逾期!$Q$3:$Q$31*华东区域指挥部主办逾期!$U$3:$U$31)+SUMPRODUCT((华东区域指挥部主办逾期!$N$3:$N$31>0)*(华东区域指挥部主办逾期!$W$3:$W$31=D6)*华东区域指挥部主办逾期!$N$3:$N$31*华东区域指挥部主办逾期!$Q$3:$Q$31*华东区域指挥部主办逾期!$X$3:$X$31)+SUMPRODUCT((华东区域指挥协办逾期!$N$3:$N$10>0)*(华东区域指挥协办逾期!$T$3:$T$10=D6)*华东区域指挥协办逾期!$N$3:$N$10*华东区域指挥协办逾期!$Q$3:$Q$10*华东区域指挥协办逾期!$U$3:$U$10)+SUMPRODUCT((华东区域指挥协办逾期!$N$3:$N$10>0)*(华东区域指挥协办逾期!$W$3:$W$10=D6)*华东区域指挥协办逾期!$N$3:$N$10*华东区域指挥协办逾期!$Q$3:$Q$10*华东区域指挥协办逾期!$X$3:$X$10))/10000} -> 32.07 | I6: {=(SUMPRODUCT((华东区域指挥部主办逾期!$O$3:$O$31>0)*(华东区域指挥部主办逾期!$T$3:$T$31=D6)*华东区域指挥部主办逾期!$O$3:$O$31*华东区域指挥部主办逾期!$Q$3:$Q$31*华东区域指挥部主办逾期!$U$3:$U$31)+SUMPRODUCT((华东区域指挥部主办逾期!$O$3:$O$31>0)*(华东区域指挥部主办逾期!$W$3:$W$31=D6)*华东区域指挥部主办逾期!$O$3:$O$31*华东区域指挥部主办逾期!$Q$3:$Q$31*华东区域指挥部主办逾期!$X$3:$X$31)+SUMPRODUCT((华东区域指挥协办逾期!$O$3:$O$10>0)*(华东区域指挥协办逾期!$T$3:$T$10=D6)*华东区域指挥协办逾期!$O$3:$O$10*华东区域指挥协办逾期!$Q$3:$Q$10*华东区域指挥协办逾期!$U$3:$U$10)+SUMPRODUCT((华东区域指挥协办逾期!$O$3:$O$10>0)*(华东区域指挥协办逾期!$W$3:$W$10=D6)*华东区域指挥协办逾期!$O$3:$O$10*华东区域指挥协办逾期!$Q$3:$Q$10*华东区域指挥协办逾期!$X$3:$X$10))/10000} -> 0 | J6: {=(SUMPRODUCT((华东区域指挥部主办逾期!$P$3:$P$31>0)*(华东区域指挥部主办逾期!$T$3:$T$31=D6)*华东区域指挥部主办逾期!$P$3:$P$31*华东区域指挥部主办逾期!$Q$3:$Q$31*华东区域指挥部主办逾期!$U$3:$U$31)+SUMPRODUCT((华东区域指挥部主办逾期!$P$3:$P$31>0)*(华东区域指挥部主办逾期!$W$3:$W$31=D6)*华东区域指挥部主办逾期!$P$3:$P$31*华东区域指挥部主办逾期!$Q$3:$Q$31*华东区域指挥部主办逾期!$X$3:$X$31)+SUMPRODUCT((华东区域指挥协办逾期!$P$3:$P$10>0)*(华东区域指挥协办逾期!$T$3:$T$10=D6)*华东区域指挥协办逾期!$P$3:$P$10*华东区域指挥协办逾期!$Q$3:$Q$10*华东区域指挥协办逾期!$U$3:$U$10)+SUMPRODUCT((华东区域指挥协办逾期!$P$3:$P$10>0)*(华东区域指挥协办逾期!$W$3:$W$10=D6)*华东区域指挥协办逾期!$P$3:$P$10*华东区域指挥协办逾期!$Q$3:$Q$10*华东区域指挥协办逾期!$X$3:$X$10))/10000} -> 69.9776 | K6: =SUM(F6:J6) -> 485.9677 | L6: =E6-K6 -> 408.88434 | M6: =L6/E6 -> 0.45692955
A7: 2 | D7: 刘新峥 | E7: 547.803 | F7: {=(SUMPRODUCT((华东区域指挥部主办逾期!$L$3:$L$31>0)*(华东区域指挥部主办逾期!$T$3:$T$31=D7)*华东区域指挥部主办逾期!$L$3:$L$31*华东区域指挥部主办逾期!$Q$3:$Q$31*华东区域指挥部主办逾期!$U$3:$U$31)+SUMPRODUCT((华东区域指挥部主办逾期!$L$3:$L$31>0)*(华东区域指挥部主办逾期!$W$3:$W$31=D7)*华东区域指挥部主办逾期!$L$3:$L$31*华东区域指挥部主办逾期!$Q$3:$Q$31*华东区域指挥部主办逾期!$X$3:$X$31)+SUMPRODUCT((华东区域指挥协办逾期!$L$3:$L$10>0)*(华东区域指挥协办逾期!$T$3:$T$10=D7)*华东区域指挥协办逾期!$L$3:$L$10*华东区域指挥协办逾期!$Q$3:$Q$10*华东区域指挥协办逾期!$U$3:$U$10)+SUMPRODUCT((华东区域指挥协办逾期!$L$3:$L$10>0)*(华东区域指挥协办逾期!$W$3:$W$10=D7)*华东区域指挥协办逾期!$L$3:$L$10*华东区域指挥协办逾期!$Q$3:$Q$10*华东区域指挥协办逾期!$X$3:$X$10))/10000} -> 0 | G7: {=(SUMPRODUCT((华东区域指挥部主办逾期!$M$3:$M$31>0)*(华东区域指挥部主办逾期!$T$3:$T$31=D7)*华东区域指挥部主办逾期!$M$3:$M$31*华东区域指挥部主办逾期!$Q$3:$Q$31*华东区域指挥部主办逾期!$U$3:$U$31)+SUMPRODUCT((华东区域指挥部主办逾期!$M$3:$M$31>0)*(华东区域指挥部主办逾期!$W$3:$W$31=D7)*华东区域指挥部主办逾期!$M$3:$M$31*华东区域指挥部主办逾期!$Q$3:$Q$31*华东区域指挥部主办逾期!$X$3:$X$31)+SUMPRODUCT((华东区域指挥协办逾期!$M$3:$M$10>0)*(华东区域指挥协办逾期!$T$3:$T$10=D7)*华东区域指挥协办逾期!$M$3:$M$10*华东区域指挥协办逾期!$Q$3:$Q$10*华东区域指挥协办逾期!$U$3:$U$10)+SUMPRODUCT((华东区域指挥协办逾期!$M$3:$M$10>0)*(华东区域指挥协办逾期!$W$3:$W$10=D7)*华东区域指挥协办逾期!$M$3:$M$10*华东区域指挥协办逾期!$Q$3:$Q$10*华东区域指挥协办逾期!$X$3:$X$10))/10000} -> 168.6729 | H7: {=(SUMPRODUCT((华东区域指挥部主办逾期!$N$3:$N$31>0)*(华东区域指挥部主办逾期!$T$3:$T$31=D7)*华东区域指挥部主办逾期!$N$3:$N$31*华东区域指挥部主办逾期!$Q$3:$Q$31*华东区域指挥部主办逾期!$U$3:$U$31)+SUMPRODUCT((华东区域指挥部主办逾期!$N$3:$N$31>0)*(华东区域指挥部主办逾期!$W$3:$W$31=D7)*华东区域指挥部主办逾期!$N$3:$N$31*华东区域指挥部主办逾期!$Q$3:$Q$31*华东区域指挥部主办逾期!$X$3:$X$31)+SUMPRODUCT((华东区域指挥协办逾期!$N$3:$N$10>0)*(华东区域指挥协办逾期!$T$3:$T$10=D7)*华东区域指挥协办逾期!$N$3:$N$10*华东区域指挥协办逾期!$Q$3:$Q$10*华东区域指挥协办逾期!$U$3:$U$10)+SUMPRODUCT((华东区域指挥协办逾期!$N$3:$N$10>0)*(华东区域指挥协办逾期!$W$3:$W$10=D7)*华东区域指挥协办逾期!$N$3:$N$10*华东区域指挥协办逾期!$Q$3:$Q$10*华东区域指挥协办逾期!$X$3:$X$10))/10000} -> 0 | I7: {=(SUMPRODUCT((华东区域指挥部主办逾期!$O$3:$O$31>0)*(华东区域指挥部主办逾期!$T$3:$T$31=D7)*华东区域指挥部主办逾期!$O$3:$O$31*华东区域指挥部主办逾期!$Q$3:$Q$31*华东区域指挥部主办逾期!$U$3:$U$31)+SUMPRODUCT((华东区域指挥部主办逾期!$O$3:$O$31>0)*(华东区域指挥部主办逾期!$W$3:$W$31=D7)*华东区域指挥部主办逾期!$O$3:$O$31*华东区域指挥部主办逾期!$Q$3:$Q$31*华东区域指挥部主办逾期!$X$3:$X$31)+SUMPRODUCT((华东区域指挥协办逾期!$O$3:$O$10>0)*(华东区域指挥协办逾期!$T$3:$T$10=D7)*华东区域指挥协办逾期!$O$3:$O$10*华东区域指挥协办逾期!$Q$3:$Q$10*华东区域指挥协办逾期!$U$3:$U$10)+SUMPRODUCT((华东区域指挥协办逾期!$O$3:$O$10>0)*(华东区域指挥协办逾期!$W$3:$W$10=D7)*华东区域指挥协办逾期!$O$3:$O$10*华东区域指挥协办逾期!$Q$3:$Q$10*华东区域指挥协办逾期!$X$3:$X$10))/10000} -> 0 | J7: {=(SUMPRODUCT((华东区域指挥部主办逾期!$P$3:$P$31>0)*(华东区域指挥部主办逾期!$T$3:$T$31=D7)*华东区域指挥部主办逾期!$P$3:$P$31*华东区域指挥部主办逾期!$Q$3:$Q$31*华东区域指挥部主办逾期!$U$3:$U$31)+SUMPRODUCT((华东区域指挥部主办逾期!$P$3:$P$31>0)*(华东区域指挥部主办逾期!$W$3:$W$31=D7)*华东区域指挥部主办逾期!$P$3:$P$31*华东区域指挥部主办逾期!$Q$3:$Q$31*华东区域指挥部主办逾期!$X$3:$X$31)+SUMPRODUCT((华东区域指挥协办逾期!$P$3:$P$10>0)*(华东区域指挥协办逾期!$T$3:$T$10=D7)*华东区域指挥协办逾期!$P$3:$P$10*华东区域指挥协办逾期!$Q$3:$Q$10*华东区域指挥协办逾期!$U$3:$U$10)+SUMPRODUCT((华东区域指挥协办逾期!$P$3:$P$10>0)*(华东区域指挥协办逾期!$W$3:$W$10=D7)*华东区域指挥协办逾期!$P$3:$P$10*华东区域指挥协办逾期!$Q$3:$Q$10*华东区域指挥协办逾期!$X$3:$X$10))/10000} -> 17.4944 | K7: =SUM(F7:J7) -> 186.1673 | L7: =E7-K7 -> 361.6357 | M7: =L7/E7 -> 0.66015648
A8: 3 | D8: 小计 | E8: 1442.655 | F8: =SUM(F6:F7) -> 0 | G8: =SUM(G6:G7) -> 552.593 | H8: =SUM(H6:H6) -> 32.07 | I8: =SUM(I6:I6) -> 0 | J8: =SUM(J6:J7) -> 87.472 | K8: =SUM(K6:K7) -> 672.135 | L8: =SUM(L6:L7) -> 770.52004 | M8: =L8/E8 -> 0.5340986
A9: 4 | C9: 宁波经营小组 | D9: 沈腾飞 | E9: 0 | F9: {=(SUMPRODUCT((华东区域指挥部主办逾期!$L$3:$L$31>0)*(华东区域指挥部主办逾期!$T$3:$T$31=D9)*华东区域指挥部主办逾期!$L$3:$L$31*华东区域指挥部主办逾期!$Q$3:$Q$31*华东区域指挥部主办逾期!$U$3:$U$31)+SUMPRODUCT((华东区域指挥部主办逾期!$L$3:$L$31>0)*(华东区域指挥部主办逾期!$W$3:$W$31=D9)*华东区域指挥部主办逾期!$L$3:$L$31*华东区域指挥部主办逾期!$Q$3:$Q$31*华东区域指挥部主办逾期!$X$3:$X$31)+SUMPRODUCT((华东区域指挥协办逾期!$L$3:$L$10>0)*(华东区域指挥协办逾期!$T$3:$T$10=D9)*华东区域指挥协办逾期!$L$3:$L$10*华东区域指挥协办逾期!$Q$3:$Q$10*华东区域指挥协办逾期!$U$3:$U$10)+SUMPRODUCT((华东区域指挥协办逾期!$L$3:$L$10>0)*(华东区域指挥协办逾期!$W$3:$W$10=D9)*华东区域指挥协办逾期!$L$3:$L$10*华东区域指挥协办逾期!$Q$3:$Q$10*华东区域指挥协办逾期!$X$3:$X$10))/10000} -> 0 | G9: {=(SUMPRODUCT((华东区域指挥部主办逾期!$M$3:$M$31>0)*(华东区域指挥部主办逾期!$T$3:$T$31=D9)*华东区域指挥部主办逾期!$M$3:$M$31*华东区域指挥部主办逾期!$Q$3:$Q$31*华东区域指挥部主办逾期!$U$3:$U$31)+SUMPRODUCT((华东区域指挥部主办逾期!$M$3:$M$31>0)*(华东区域指挥部主办逾期!$W$3:$W$31=D9)*华东区域指挥部主办逾期!$M$3:$M$31*华东区域指挥部主办逾期!$Q$3:$Q$31*华东区域指挥部主办逾期!$X$3:$X$31)+SUMPRODUCT((华东区域指挥协办逾期!$M$3:$M$10>0)*(华东区域指挥协办逾期!$T$3:$T$10=D9)*华东区域指挥协办逾期!$M$3:$M$10*华东区域指挥协办逾期!$Q$3:$Q$10*华东区域指挥协办逾期!$U$3:$U$10)+SUMPRODUCT((华东区域指挥协办逾期!$M$3:$M$10>0)*(华东区域指挥协办逾期!$W$3:$W$10=D9)*华东区域指挥协办逾期!$M$3:$M$10*华东区域指挥协办逾期!$Q$3:$Q$10*华东区域指挥协办逾期!$X$3:$X$10))/10000} -> 0 | H9: {=(SUMPRODUCT((华东区域指挥部主办逾期!$N$3:$N$31>0)*(华东区域指挥部主办逾期!$T$3:$T$31=D9)*华东区域指挥部主办逾期!$N$3:$N$31*华东区域指挥部主办逾期!$Q$3:$Q$31*华东区域指挥部主办逾期!$U$3:$U$31)+SUMPRODUCT((华东区域指挥部主办逾期!$N$3:$N$31>0)*(华东区域指挥部主办逾期!$W$3:$W$31=D9)*华东区域指挥部主办逾期!$N$3:$N$31*华东区域指挥部主办逾期!$Q$3:$Q$31*华东区域指挥部主办逾期!$X$3:$X$31)+SUMPRODUCT((华东区域指挥协办逾期!$N$3:$N$10>0)*(华东区域指挥协办逾期!$T$3:$T$10=D9)*华东区域指挥协办逾期!$N$3:$N$10*华东区域指挥协办逾期!$Q$3:$Q$10*华东区域指挥协办逾期!$U$3:$U$10)+SUMPRODUCT((华东区域指挥协办逾期!$N$3:$N$10>0)*(华东区域指挥协办逾期!$W$3:$W$10=D9)*华东区域指挥协办逾期!$N$3:$N$10*华东区域指挥协办逾期!$Q$3:$Q$10*华东区域指挥协办逾期!$X$3:$X$10))/10000} -> 0 | I9: {=(SUMPRODUCT((华东区域指挥部主办逾期!$O$3:$O$31>0)*(华东区域指挥部主办逾期!$T$3:$T$31=D9)*华东区域指挥部主办逾期!$O$3:$O$31*华东区域指挥部主办逾期!$Q$3:$Q$31*华东区域指挥部主办逾期!$U$3:$U$31)+SUMPRODUCT((华东区域指挥部主办逾期!$O$3:$O$31>0)*(华东区域指挥部主办逾期!$W$3:$W$31=D9)*华东区域指挥部主办逾期!$O$3:$O$31*华东区域指挥部主办逾期!$Q$3:$Q$31*华东区域指挥部主办逾期!$X$3:$X$31)+SUMPRODUCT((华东区域指挥协办逾期!$O$3:$O$10>0)*(华东区域指挥协办逾期!$T$3:$T$10=D9)*华东区域指挥协办逾期!$O$3:$O$10*华东区域指挥协办逾期!$Q$3:$Q$10*华东区域指挥协办逾期!$U$3:$U$10)+SUMPRODUCT((华东区域指挥协办逾期!$O$3:$O$10>0)*(华东区域指挥协办逾期!$W$3:$W$10=D9)*华东区域指挥协办逾期!$O$3:$O$10*华东区域指挥协办逾期!$Q$3:$Q$10*华东区域指挥协办逾期!$X$3:$X$10))/10000} -> 0 | J9: {=(SUMPRODUCT((华东区域指挥部主办逾期!$P$3:$P$31>0)*(华东区域指挥部主办逾期!$T$3:$T$31=D9)*华东区域指挥部主办逾期!$P$3:$P$31*华东区域指挥部主办逾期!$Q$3:$Q$31*华东区域指挥部主办逾期!$U$3:$U$31)+SUMPRODUCT((华东区域指挥部主办逾期!$P$3:$P$31>0)*(华东区域指挥部主办逾期!$W$3:$W$31=D9)*华东区域指挥部主办逾期!$P$3:$P$31*华东区域指挥部主办逾期!$Q$3:$Q$31*华东区域指挥部主办逾期!$X$3:$X$31)+SUMPRODUCT((华东区域指挥协办逾期!$P$3:$P$10>0)*(华东区域指挥协办逾期!$T$3:$T$10=D9)*华东区域指挥协办逾期!$P$3:$P$10*华东区域指挥协办逾期!$Q$3:$Q$10*华东区域指挥协办逾期!$U$3:$U$10)+SUMPRODUCT((华东区域指挥协办逾期!$P$3:$P$10>0)*(华东区域指挥协办逾期!$W$3:$W$10=D9)*华东区域指挥协办逾期!$P$3:$P$10*华东区域指挥协办逾期!$Q$3:$Q$10*华东区域指挥协办逾期!$X$3:$X$10))/10000} -> 0 | K9: =SUM(F9:J9) -> 0 | L9: =E9-K9 -> 0 | M9: =L9/E9 -> #DIV/0!
A10: 5 | D10: 袁志凌 | E10: 74.3 | F10: {=(SUMPRODUCT((华东区域指挥部主办逾期!$L$3:$L$31>0)*(华东区域指挥部主办逾期!$T$3:$T$31=D10)*华东区域指挥部主办逾期!$L$3:$L$31*华东区域指挥部主办逾期!$Q$3:$Q$31*华东区域指挥部主办逾期!$U$3:$U$31)+SUMPRODUCT((华东区域指挥部主办逾期!$L$3:$L$31>0)*(华东区域指挥部主办逾期!$W$3:$W$31=D10)*华东区域指挥部主办逾期!$L$3:$L$31*华东区域指挥部主办逾期!$Q$3:$Q$31*华东区域指挥部主办逾期!$X$3:$X$31)+SUMPRODUCT((华东区域指挥协办逾期!$L$3:$L$10>0)*(华东区域指挥协办逾期!$T$3:$T$10=D10)*华东区域指挥协办逾期!$L$3:$L$10*华东区域指挥协办逾期!$Q$3:$Q$10*华东区域指挥协办逾期!$U$3:$U$10)+SUMPRODUCT((华东区域指挥协办逾期!$L$3:$L$10>0)*(华东区域指挥协办逾期!$W$3:$W$10=D10)*华东区域指挥协办逾期!$L$3:$L$10*华东区域指挥协办逾期!$Q$3:$Q$10*华东区域指挥协办逾期!$X$3:$X$10))/10000} -> 0 | G10: {=(SUMPRODUCT((华东区域指挥部主办逾期!$M$3:$M$31>0)*(华东区域指挥部主办逾期!$T$3:$T$31=D10)*华东区域指挥部主办逾期!$M$3:$M$31*华东区域指挥部主办逾期!$Q$3:$Q$31*华东区域指挥部主办逾期!$U$3:$U$31)+SUMPRODUCT((华东区域指挥部主办逾期!$M$3:$M$31>0)*(华东区域指挥部主办逾期!$W$3:$W$31=D10)*华东区域指挥部主办逾期!$M$3:$M$31*华东区域指挥部主办逾期!$Q$3:$Q$31*华东区域指挥部主办逾期!$X$3:$X$31)+SUMPRODUCT((华东区域指挥协办逾期!$M$3:$M$10>0)*(华东区域指挥协办逾期!$T$3:$T$10=D10)*华东区域指挥协办逾期!$M$3:$M$10*华东区域指挥协办逾期!$Q$3:$Q$10*华东区域指挥协办逾期!$U$3:$U$10)+SUMPRODUCT((华东区域指挥协办逾期!$M$3:$M$10>0)*(华东区域指挥协办逾期!$W$3:$W$10=D10)*华东区域指挥协办逾期!$M$3:$M$10*华东区域指挥协办逾期!$Q$3:$Q$10*华东区域指挥协办逾期!$X$3:$X$10))/10000} -> 0 | H10: {=(SUMPRODUCT((华东区域指挥部主办逾期!$N$3:$N$31>0)*(华东区域指挥部主办逾期!$T$3:$T$31=D10)*华东区域指挥部主办逾期!$N$3:$N$31*华东区域指挥部主办逾期!$Q$3:$Q$31*华东区域指挥部主办逾期!$U$3:$U$31)+SUMPRODUCT((华东区域指挥部主办逾期!$N$3:$N$31>0)*(华东区域指挥部主办逾期!$W$3:$W$31=D10)*华东区域指挥部主办逾期!$N$3:$N$31*华东区域指挥部主办逾期!$Q$3:$Q$31*华东区域指挥部主办逾期!$X$3:$X$31)+SUMPRODUCT((华东区域指挥协办逾期!$N$3:$N$10>0)*(华东区域指挥协办逾期!$T$3:$T$10=D10)*华东区域指挥协办逾期!$N$3:$N$10*华东区域指挥协办逾期!$Q$3:$Q$10*华东区域指挥协办逾期!$U$3:$U$10)+SUMPRODUCT((华东区域指挥协办逾期!$N$3:$N$10>0)*(华东区域指挥协办逾期!$W$3:$W$10=D10)*华东区域指挥协办逾期!$N$3:$N$10*华东区域指挥协办逾期!$Q$3:$Q$10*华东区域指挥协办逾期!$X$3:$X$10))/10000} -> 0 | I10: {=(SUMPRODUCT((华东区域指挥部主办逾期!$O$3:$O$31>0)*(华东区域指挥部主办逾期!$T$3:$T$31=D10)*华东区域指挥部主办逾期!$O$3:$O$31*华东区域指挥部主办逾期!$Q$3:$Q$31*华东区域指挥部主办逾期!$U$3:$U$31)+SUMPRODUCT((华东区域指挥部主办逾期!$O$3:$O$31>0)*(华东区域指挥部主办逾期!$W$3:$W$31=D10)*华东区域指挥部主办逾期!$O$3:$O$31*华东区域指挥部主办逾期!$Q$3:$Q$31*华东区域指挥部主办逾期!$X$3:$X$31)+SUMPRODUCT((华东区域指挥协办逾期!$O$3:$O$10>0)*(华东区域指挥协办逾期!$T$3:$T$10=D10)*华东区域指挥协办逾期!$O$3:$O$10*华东区域指挥协办逾期!$Q$3:$Q$10*华东区域指挥协办逾期!$U$3:$U$10)+SUMPRODUCT((华东区域指挥协办逾期!$O$3:$O$10>0)*(华东区域指挥协办逾期!$W$3:$W$10=D10)*华东区域指挥协办逾期!$O$3:$O$10*华东区域指挥协办逾期!$Q$3:$Q$10*华东区域指挥协办逾期!$X$3:$X$10))/10000} -> 74.3 | J10: {=(SUMPRODUCT((华东区域指挥部主办逾期!$P$3:$P$31>0)*(华东区域指挥部主办逾期!$T$3:$T$31=D10)*华东区域指挥部主办逾期!$P$3:$P$31*华东区域指挥部主办逾期!$Q$3:$Q$31*华东区域指挥部主办逾期!$U$3:$U$31)+SUMPRODUCT((华东区域指挥部主办逾期!$P$3:$P$31>0)*(华东区域指挥部主办逾期!$W$3:$W$31=D10)*华东区域指挥部主办逾期!$P$3:$P$31*华东区域指挥部主办逾期!$Q$3:$Q$31*华东区域指挥部主办逾期!$X$3:$X$31)+SUMPRODUCT((华东区域指挥协办逾期!$P$3:$P$10>0)*(华东区域指挥协办逾期!$T$3:$T$10=D10)*华东区域指挥协办逾期!$P$3:$P$10*华东区域指挥协办逾期!$Q$3:$Q$10*华东区域指挥协办逾期!$U$3:$U$10)+SUMPRODUCT((华东区域指挥协办逾期!$P$3:$P$10>0)*(华东区域指挥协办逾期!$W$3:$W$10=D10)*华东区域指挥协办逾期!$P$3:$P$10*华东区域指挥协办逾期!$Q$3:$Q$10*华东区域指挥协办逾期!$X$3:$X$10))/10000} -> 0 | K10: =SUM(F10:J10) -> 74.3 | L10: =E10-K10 -> 0 | M10: =L10/E10 -> 0
A11: 6 | D11: 万赛 | E11: 629.2399 | F11: {=(SUMPRODUCT((华东区域指挥部主办逾期!$L$3:$L$31>0)*(华东区域指挥部主办逾期!$T$3:$T$31=D11)*华东区域指挥部主办逾期!$L$3:$L$31*华东区域指挥部主办逾期!$Q$3:$Q$31*华东区域指挥部主办逾期!$U$3:$U$31)+SUMPRODUCT((华东区域指挥部主办逾期!$L$3:$L$31>0)*(华东区域指挥部主办逾期!$W$3:$W$31=D11)*华东区域指挥部主办逾期!$L$3:$L$31*华东区域指挥部主办逾期!$Q$3:$Q$31*华东区域指挥部主办逾期!$X$3:$X$31)+SUMPRODUCT((华东区域指挥协办逾期!$L$3:$L$10>0)*(华东区域指挥协办逾期!$T$3:$T$10=D11)*华东区域指挥协办逾期!$L$3:$L$10*华东区域指挥协办逾期!$Q$3:$Q$10*华东区域指挥协办逾期!$U$3:$U$10)+SUMPRODUCT((华东区域指挥协办逾期!$L$3:$L$10>0)*(华东区域指挥协办逾期!$W$3:$W$10=D11)*华东区域指挥协办逾期!$L$3:$L$10*华东区域指挥协办逾期!$Q$3:$Q$10*华东区域指挥协办逾期!$X$3:$X$10))/10000} -> 0 | G11: {=(SUMPRODUCT((华东区域指挥部主办逾期!$M$3:$M$31>0)*(华东区域指挥部主办逾期!$T$3:$T$31=D11)*华东区域指挥部主办逾期!$M$3:$M$31*华东区域指挥部主办逾期!$Q$3:$Q$31*华东区域指挥部主办逾期!$U$3:$U$31)+SUMPRODUCT((华东区域指挥部主办逾期!$M$3:$M$31>0)*(华东区域指挥部主办逾期!$W$3:$W$31=D11)*华东区域指挥部主办逾期!$M$3:$M$31*华东区域指挥部主办逾期!$Q$3:$Q$31*华东区域指挥部主办逾期!$X$3:$X$31)+SUMPRODUCT((华东区域指挥协办逾期!$M$3:$M$10>0)*(华东区域指挥协办逾期!$T$3:$T$10=D11)*华东区域指挥协办逾期!$M$3:$M$10*华东区域指挥协办逾期!$Q$3:$Q$10*华东区域指挥协办逾期!$U$3:$U$10)+SUMPRODUCT((华东区域指挥协办逾期!$M$3:$M$10>0)*(华东区域指挥协办逾期!$W$3:$W$10=D11)*华东区域指挥协办逾期!$M$3:$M$10*华东区域指挥协办逾期!$Q$3:$Q$10*华东区域指挥协办逾期!$X$3:$X$10))/10000} -> 25.56 | H11: {=(SUMPRODUCT((华东区域指挥部主办逾期!$N$3:$N$31>0)*(华东区域指挥部主办逾期!$T$3:$T$31=D11)*华东区域指挥部主办逾期!$N$3:$N$31*华东区域指挥部主办逾期!$Q$3:$Q$31*华东区域指挥部主办逾期!$U$3:$U$31)+SUMPRODUCT((华东区域指挥部主办逾期!$N$3:$N$31>0)*(华东区域指挥部主办逾期!$W$3:$W$31=D11)*华东区域指挥部主办逾期!$N$3:$N$31*华东区域指挥部主办逾期!$Q$3:$Q$31*华东区域指挥部主办逾期!$X$3:$X$31)+SUMPRODUCT((华东区域指挥协办逾期!$N$3:$N$10>0)*(华东区域指挥协办逾期!$T$3:$T$10=D11)*华东区域指挥协办逾期!$N$3:$N$10*华东区域指挥协办逾期!$Q$3:$Q$10*华东区域指挥协办逾期!$U$3:$U$10)+SUMPRODUCT((华东区域指挥协办逾期!$N$3:$N$10>0)*(华东区域指挥协办逾期!$W$3:$W$10=D11)*华东区域指挥协办逾期!$N$3:$N$10*华东区域指挥协办逾期!$Q$3:$Q$10*华东区域指挥协办逾期!$X$3:$X$10))/10000} -> 269.78 | I11: {=(SUMPRODUCT((华东区域指挥部主办逾期!$O$3:$O$31>0)*(华东区域指挥部主办逾期!$T$3:$T$31=D11)*华东区域指挥部主办逾期!$O$3:$O$31*华东区域指挥部主办逾期!$Q$3:$Q$31*华东区域指挥部主办逾期!$U$3:$U$31)+SUMPRODUCT((华东区域指挥部主办逾期!$O$3:$O$31>0)*(华东区域指挥部主办逾期!$W$3:$W$31=D11)*华东区域指挥部主办逾期!$O$3:$O$31*华东区域指挥部主办逾期!$Q$3:$Q$31*华东区域指挥部主办逾期!$X$3:$X$31)+SUMPRODUCT((华东区域指挥协办逾期!$O$3:$O$10>0)*(华东区域指挥协办逾期!$T$3:$T$10=D11)*华东区域指挥协办逾期!$O$3:$O$10*华东区域指挥协办逾期!$Q$3:$Q$10*华东区域指挥协办逾期!$U$3:$U$10)+SUMPRODUCT((华东区域指挥协办逾期!$O$3:$O$10>0)*(华东区域指挥协办逾期!$W$3:$W$10=D11)*华东区域指挥协办逾期!$O$3:$O$10*华东区域指挥协办逾期!$Q$3:$Q$10*华东区域指挥协办逾期!$X$3:$X$10))/10000} -> 0 | J11: {=(SUMPRODUCT((华东区域指挥部主办逾期!$P$3:$P$31>0)*(华东区域指挥部主办逾期!$T$3:$T$31=D11)*华东区域指挥部主办逾期!$P$3:$P$31*华东区域指挥部主办逾期!$Q$3:$Q$31*华东区域指挥部主办逾期!$U$3:$U$31)+SUMPRODUCT((华东区域指挥部主办逾期!$P$3:$P$31>0)*(华东区域指挥部主办逾期!$W$3:$W$31=D11)*华东区域指挥部主办逾期!$P$3:$P$31*华东区域指挥部主办逾期!$Q$3:$Q$31*华东区域指挥部主办逾期!$X$3:$X$31)+SUMPRODUCT((华东区域指挥协办逾期!$P$3:$P$10>0)*(华东区域指挥协办逾期!$T$3:$T$10=D11)*华东区域指挥协办逾期!$P$3:$P$10*华东区域指挥协办逾期!$Q$3:$Q$10*华东区域指挥协办逾期!$U$3:$U$10)+SUMPRODUCT((华东区域指挥协办逾期!$P$3:$P$10>0)*(华东区域指挥协办逾期!$W$3:$W$10=D11)*华东区域指挥协办逾期!$P$3:$P$10*华东区域指挥协办逾期!$Q$3:$Q$10*华东区域指挥协办逾期!$X$3:$X$10))/10000} -> 193.89989 | K11: =SUM(F11:J11) -> 489.23989 | L11: =E11-K11 -> 140 | M11: \
A12: 7 | D12: 小计 | E12: 703.5399 | F12: =SUM(F9:F11) -> 0 | G12: =SUM(G9:G11) -> 25.56 | H12: =SUM(H9:H11) -> 269.78 | I12: =SUM(I9:I11) -> 74.3 | J12: =SUM(J9:J11) -> 193.89989 | K12: =SUM(K9:K11) -> 563.5399 | L12: =SUM(L9:L11) -> 140 | M12: =L12/E12 -> 0.19899369
A13: 8 | C13: 浙江小计 | E13: 2146.1949 | F13: =SUM(F8,F12) -> 0 | G13: =SUM(G8,G12) -> 578.153 | H13: =SUM(H8,H12) -> 301.85 | I13: =SUM(I8,I12) -> 74.3 | J13: =SUM(J8,J12) -> 281.37189 | K13: =SUM(K8,K12) -> 1235.6749 | L13: =SUM(L8,L12) -> 910.52004 | M13: =L13/E13 -> 0.42424853
A14: 9 | B14: 上海经营部 | C14: 上海经营小组 | D14: 穆华清 | E14: 186.18068 | F14: {=(SUMPRODUCT((华东区域指挥部主办逾期!$L$3:$L$31>0)*(华东区域指挥部主办逾期!$T$3:$T$31=D14)*华东区域指挥部主办逾期!$L$3:$L$31*华东区域指挥部主办逾期!$Q$3:$Q$31*华东区域指挥部主办逾期!$U$3:$U$31)+SUMPRODUCT((华东区域指挥部主办逾期!$L$3:$L$31>0)*(华东区域指挥部主办逾期!$W$3:$W$31=D14)*华东区域指挥部主办逾期!$L$3:$L$31*华东区域指挥部主办逾期!$Q$3:$Q$31*华东区域指挥部主办逾期!$X$3:$X$31)+SUMPRODUCT((华东区域指挥协办逾期!$L$3:$L$10>0)*(华东区域指挥协办逾期!$T$3:$T$10=D14)*华东区域指挥协办逾期!$L$3:$L$10*华东区域指挥协办逾期!$Q$3:$Q$10*华东区域指挥协办逾期!$U$3:$U$10)+SUMPRODUCT((华东区域指挥协办逾期!$L$3:$L$10>0)*(华东区域指挥协办逾期!$W$3:$W$10=D14)*华东区域指挥协办逾期!$L$3:$L$10*华东区域指挥协办逾期!$Q$3:$Q$10*华东区域指挥协办逾期!$X$3:$X$10))/10000} -> 0 | G14: {=(SUMPRODUCT((华东区域指挥部主办逾期!$M$3:$M$31>0)*(华东区域指挥部主办逾期!$T$3:$T$31=D14)*华东区域指挥部主办逾期!$M$3:$M$31*华东区域指挥部主办逾期!$Q$3:$Q$31*华东区域指挥部主办逾期!$U$3:$U$31)+SUMPRODUCT((华东区域指挥部主办逾期!$M$3:$M$31>0)*(华东区域指挥部主办逾期!$W$3:$W$31=D14)*华东区域指挥部主办逾期!$M$3:$M$31*华东区域指挥部主办逾期!$Q$3:$Q$31*华东区域指挥部主办逾期!$X$3:$X$31)+SUMPRODUCT((华东区域指挥协办逾期!$M$3:$M$10>0)*(华东区域指挥协办逾期!$T$3:$T$10=D14)*华东区域指挥协办逾期!$M$3:$M$10*华东区域指挥协办逾期!$Q$3:$Q$10*华东区域指挥协办逾期!$U$3:$U$10)+SUMPRODUCT((华东区域指挥协办逾期!$M$3:$M$10>0)*(华东区域指挥协办逾期!$W$3:$W$10=D14)*华东区域指挥协办逾期!$M$3:$M$10*华东区域指挥协办逾期!$Q$3:$Q$10*华东区域指挥协办逾期!$X$3:$X$10))/10000} -> 65.08061 | H14: {=(SUMPRODUCT((华东区域指挥部主办逾期!$N$3:$N$31>0)*(华东区域指挥部主办逾期!$T$3:$T$31=D14)*华东区域指挥部主办逾期!$N$3:$N$31*华东区域指挥部主办逾期!$Q$3:$Q$31*华东区域指挥部主办逾期!$U$3:$U$31)+SUMPRODUCT((华东区域指挥部主办逾期!$N$3:$N$31>0)*(华东区域指挥部主办逾期!$W$3:$W$31=D14)*华东区域指挥部主办逾期!$N$3:$N$31*华东区域指挥部主办逾期!$Q$3:$Q$31*华东区域指挥部主办逾期!$X$3:$X$31)+SUMPRODUCT((华东区域指挥协办逾期!$N$3:$N$10>0)*(华东区域指挥协办逾期!$T$3:$T$10=D14)*华东区域指挥协办逾期!$N$3:$N$10*华东区域指挥协办逾期!$Q$3:$Q$10*华东区域指挥协办逾期!$U$3:$U$10)+SUMPRODUCT((华东区域指挥协办逾期!$N$3:$N$10>0)*(华东区域指挥协办逾期!$W$3:$W$10=D14)*华东区域指挥协办逾期!$N$3:$N$10*华东区域指挥协办逾期!$Q$3:$Q$10*华东区域指挥协办逾期!$X$3:$X$10))/10000} -> 0 | I14: {=(SUMPRODUCT((华东区域指挥部主办逾期!$O$3:$O$31>0)*(华东区域指挥部主办逾期!$T$3:$T$31=D14)*华东区域指挥部主办逾期!$O$3:$O$31*华东区域指挥部主办逾期!$Q$3:$Q$31*华东区域指挥部主办逾期!$U$3:$U$31)+SUMPRODUCT((华东区域指挥部主办逾期!$O$3:$O$31>0)*(华东区域指挥部主办逾期!$W$3:$W$31=D14)*华东区域指挥部主办逾期!$O$3:$O$31*华东区域指挥部主办逾期!$Q$3:$Q$31*华东区域指挥部主办逾期!$X$3:$X$31)+SUMPRODUCT((华东区域指挥协办逾期!$O$3:$O$10>0)*(华东区域指挥协办逾期!$T$3:$T$10=D14)*华东区域指挥协办逾期!$O$3:$O$10*华东区域指挥协办逾期!$Q$3:$Q$10*华东区域指挥协办逾期!$U$3:$U$10)+SUMPRODUCT((华东区域指挥协办逾期!$O$3:$O$10>0)*(华东区域指挥协办逾期!$W$3:$W$10=D14)*华东区域指挥协办逾期!$O$3:$O$10*华东区域指挥协办逾期!$Q$3:$Q$10*华东区域指挥协办逾期!$X$3:$X$10))/10000} -> 78.71962 | J14: {=(SUMPRODUCT((华东区域指挥部主办逾期!$P$3:$P$31>0)*(华东区域指挥部主办逾期!$T$3:$T$31=D14)*华东区域指挥部主办逾期!$P$3:$P$31*华东区域指挥部主办逾期!$Q$3:$Q$31*华东区域指挥部主办逾期!$U$3:$U$31)+SUMPRODUCT((华东区域指挥部主办逾期!$P$3:$P$31>0)*(华东区域指挥部主办逾期!$W$3:$W$31=D14)*华东区域指挥部主办逾期!$P$3:$P$31*华东区域指挥部主办逾期!$Q$3:$Q$31*华东区域指挥部主办逾期!$X$3:$X$31)+SUMPRODUCT((华东区域指挥协办逾期!$P$3:$P$10>0)*(华东区域指挥协办逾期!$T$3:$T$10=D14)*华东区域指挥协办逾期!$P$3:$P$10*华东区域指挥协办逾期!$Q$3:$Q$10*华东区域指挥协办逾期!$U$3:$U$10)+SUMPRODUCT((华东区域指挥协办逾期!$P$3:$P$10>0)*(华东区域指挥协办逾期!$W$3:$W$10=D14)*华东区域指挥协办逾期!$P$3:$P$10*华东区域指挥协办逾期!$Q$3:$Q$10*华东区域指挥协办逾期!$X$3:$X$10))/10000} -> 0 | K14: =SUM(F14:J14) -> 143.80023 | L14: =E14-K14 -> 42.38045 | M14: =L14/E14 -> 0.22763076
A15: 10 | D15: 赵宇瑄 | E15: 1103.3427 | F15: {=(SUMPRODUCT((华东区域指挥部主办逾期!$L$3:$L$31>0)*(华东区域指挥部主办逾期!$T$3:$T$31=D15)*华东区域指挥部主办逾期!$L$3:$L$31*华东区域指挥部主办逾期!$Q$3:$Q$31*华东区域指挥部主办逾期!$U$3:$U$31)+SUMPRODUCT((华东区域指挥部主办逾期!$L$3:$L$31>0)*(华东区域指挥部主办逾期!$W$3:$W$31=D15)*华东区域指挥部主办逾期!$L$3:$L$31*华东区域指挥部主办逾期!$Q$3:$Q$31*华东区域指挥部主办逾期!$X$3:$X$31)+SUMPRODUCT((华东区域指挥协办逾期!$L$3:$L$10>0)*(华东区域指挥协办逾期!$T$3:$T$10=D15)*华东区域指挥协办逾期!$L$3:$L$10*华东区域指挥协办逾期!$Q$3:$Q$10*华东区域指挥协办逾期!$U$3:$U$10)+SUMPRODUCT((华东区域指挥协办逾期!$L$3:$L$10>0)*(华东区域指挥协办逾期!$W$3:$W$10=D15)*华东区域指挥协办逾期!$L$3:$L$10*华东区域指挥协办逾期!$Q$3:$Q$10*华东区域指挥协办逾期!$X$3:$X$10))/10000} -> 0 | G15: {=(SUMPRODUCT((华东区域指挥部主办逾期!$M$3:$M$31>0)*(华东区域指挥部主办逾期!$T$3:$T$31=D15)*华东区域指挥部主办逾期!$M$3:$M$31*华东区域指挥部主办逾期!$Q$3:$Q$31*华东区域指挥部主办逾期!$U$3:$U$31)+SUMPRODUCT((华东区域指挥部主办逾期!$M$3:$M$31>0)*(华东区域指挥部主办逾期!$W$3:$W$31=D15)*华东区域指挥部主办逾期!$M$3:$M$31*华东区域指挥部主办逾期!$Q$3:$Q$31*华东区域指挥部主办逾期!$X$3:$X$31)+SUMPRODUCT((华东区域指挥协办逾期!$M$3:$M$10>0)*(华东区域指挥协办逾期!$T$3:$T$10=D15)*华东区域指挥协办逾期!$M$3:$M$10*华东区域指挥协办逾期!$Q$3:$Q$10*华东区域指挥协办逾期!$U$3:$U$10)+SUMPRODUCT((华东区域指挥协办逾期!$M$3:$M$10>0)*(华东区域指挥协办逾期!$W$3:$W$10=D15)*华东区域指挥协办逾期!$M$3:$M$10*华东区域指挥协办逾期!$Q$3:$Q$10*华东区域指挥协办逾期!$X$3:$X$10))/10000} -> 486.25734 | H15: {=(SUMPRODUCT((华东区域指挥部主办逾期!$N$3:$N$31>0)*(华东区域指挥部主办逾期!$T$3:$T$31=D15)*华东区域指挥部主办逾期!$N$3:$N$31*华东区域指挥部主办逾期!$Q$3:$Q$31*华东区域指挥部主办逾期!$U$3:$U$31)+SUMPRODUCT((华东区域指挥部主办逾期!$N$3:$N$31>0)*(华东区域指挥部主办逾期!$W$3:$W$31=D15)*华东区域指挥部主办逾期!$N$3:$N$31*华东区域指挥部主办逾期!$Q$3:$Q$31*华东区域指挥部主办逾期!$X$3:$X$31)+SUMPRODUCT((华东区域指挥协办逾期!$N$3:$N$10>0)*(华东区域指挥协办逾期!$T$3:$T$10=D15)*华东区域指挥协办逾期!$N$3:$N$10*华东区域指挥协办逾期!$Q$3:$Q$10*华东区域指挥协办逾期!$U$3:$U$10)+SUMPRODUCT((华东区域指挥协办逾期!$N$3:$N$10>0)*(华东区域指挥协办逾期!$W$3:$W$10=D15)*华东区域指挥协办逾期!$N$3:$N$10*华东区域指挥协办逾期!$Q$3:$Q$10*华东区域指挥协办逾期!$X$3:$X$10))/10000} -> 231.40317 | I15: {=(SUMPRODUCT((华东区域指挥部主办逾期!$O$3:$O$31>0)*(华东区域指挥部主办逾期!$T$3:$T$31=D15)*华东区域指挥部主办逾期!$O$3:$O$31*华东区域指挥部主办逾期!$Q$3:$Q$31*华东区域指挥部主办逾期!$U$3:$U$31)+SUMPRODUCT((华东区域指挥部主办逾期!$O$3:$O$31>0)*(华东区域指挥部主办逾期!$W$3:$W$31=D15)*华东区域指挥部主办逾期!$O$3:$O$31*华东区域指挥部主办逾期!$Q$3:$Q$31*华东区域指挥部主办逾期!$X$3:$X$31)+SUMPRODUCT((华东区域指挥协办逾期!$O$3:$O$10>0)*(华东区域指挥协办逾期!$T$3:$T$10=D15)*华东区域指挥协办逾期!$O$3:$O$10*华东区域指挥协办逾期!$Q$3:$Q$10*华东区域指挥协办逾期!$U$3:$U$10)+SUMPRODUCT((华东区域指挥协办逾期!$O$3:$O$10>0)*(华东区域指挥协办逾期!$W$3:$W$10=D15)*华东区域指挥协办逾期!$O$3:$O$10*华东区域指挥协办逾期!$Q$3:$Q$10*华东区域指挥协办逾期!$X$3:$X$10))/10000} -> 89.73698 | J15: {=(SUMPRODUCT((华东区域指挥部主办逾期!$P$3:$P$31>0)*(华东区域指挥部主办逾期!$T$3:$T$31=D15)*华东区域指挥部主办逾期!$P$3:$P$31*华东区域指挥部主办逾期!$Q$3:$Q$31*华东区域指挥部主办逾期!$U$3:$U$31)+SUMPRODUCT((华东区域指挥部主办逾期!$P$3:$P$31>0)*(华东区域指挥部主办逾期!$W$3:$W$31=D15)*华东区域指挥部主办逾期!$P$3:$P$31*华东区域指挥部主办逾期!$Q$3:$Q$31*华东区域指挥部主办逾期!$X$3:$X$31)+SUMPRODUCT((华东区域指挥协办逾期!$P$3:$P$10>0)*(华东区域指挥协办逾期!$T$3:$T$10=D15)*华东区域指挥协办逾期!$P$3:$P$10*华东区域指挥协办逾期!$Q$3:$Q$10*华东区域指挥协办逾期!$U$3:$U$10)+SUMPRODUCT((华东区域指挥协办逾期!$P$3:$P$10>0)*(华东区域指挥协办逾期!$W$3:$W$10=D15)*华东区域指挥协办逾期!$P$3:$P$10*华东区域指挥协办逾期!$Q$3:$Q$10*华东区域指挥协办逾期!$X$3:$X$10))/10000} -> 0 | K15: =SUM(F15:J15) -> 807.39749 | L15: =E15-K15 -> 295.94518 | M15: =L15/E15 -> 0.26822599
A16: 11 | C16: 上海小计 | E16: 1289.5234 | F16: =SUM(F14:F15) -> 0 | G16: =SUM(G14:G15) -> 551.33795 | H16: =SUM(H14:H15) -> 231.40317 | I16: =SUM(I14:I15) -> 168.4566 | J16: =SUM(J14:J15) -> 0 | K16: =SUM(K14:K15) -> 951.19772 | L16: =SUM(L14:L15) -> 338.32563 | M16: =L16/E16 -> 0.26236487
A17: 12 | B17: 闽赣经营部 | C17: 铁道经营小组 | D17: 陈浩 | E17: 721.57749 | F17: {=(SUMPRODUCT((华东区域指挥部主办逾期!$L$3:$L$31>0)*(华东区域指挥部主办逾期!$T$3:$T$31=D17)*华东区域指挥部主办逾期!$L$3:$L$31*华东区域指挥部主办逾期!$Q$3:$Q$31*华东区域指挥部主办逾期!$U$3:$U$31)+SUMPRODUCT((华东区域指挥部主办逾期!$L$3:$L$31>0)*(华东区域指挥部主办逾期!$W$3:$W$31=D17)*华东区域指挥部主办逾期!$L$3:$L$31*华东区域指挥部主办逾期!$Q$3:$Q$31*华东区域指挥部主办逾期!$X$3:$X$31)+SUMPRODUCT((华东区域指挥协办逾期!$L$3:$L$10>0)*(华东区域指挥协办逾期!$T$3:$T$10=D17)*华东区域指挥协办逾期!$L$3:$L$10*华东区域指挥协办逾期!$Q$3:$Q$10*华东区域指挥协办逾期!$U$3:$U$10)+SUMPRODUCT((华东区域指挥协办逾期!$L$3:$L$10>0)*(华东区域指挥协办逾期!$W$3:$W$10=D17)*华东区域指挥协办逾期!$L$3:$L$10*华东区域指挥协办逾期!$Q$3:$Q$10*华东区域指挥协办逾期!$X$3:$X$10))/10000} -> 0 | G17: {=(SUMPRODUCT((华东区域指挥部主办逾期!$M$3:$M$31>0)*(华东区域指挥部主办逾期!$T$3:$T$31=D17)*华东区域指挥部主办逾期!$M$3:$M$31*华东区域指挥部主办逾期!$Q$3:$Q$31*华东区域指挥部主办逾期!$U$3:$U$31)+SUMPRODUCT((华东区域指挥部主办逾期!$M$3:$M$31>0)*(华东区域指挥部主办逾期!$W$3:$W$31=D17)*华东区域指挥部主办逾期!$M$3:$M$31*华东区域指挥部主办逾期!$Q$3:$Q$31*华东区域指挥部主办逾期!$X$3:$X$31)+SUMPRODUCT((华东区域指挥协办逾期!$M$3:$M$10>0)*(华东区域指挥协办逾期!$T$3:$T$10=D17)*华东区域指挥协办逾期!$M$3:$M$10*华东区域指挥协办逾期!$Q$3:$Q$10*华东区域指挥协办逾期!$U$3:$U$10)+SUMPRODUCT((华东区域指挥协办逾期!$M$3:$M$10>0)*(华东区域指挥协办逾期!$W$3:$W$10=D17)*华东区域指挥协办逾期!$M$3:$M$10*华东区域指挥协办逾期!$Q$3:$Q$10*华东区域指挥协办逾期!$X$3:$X$10))/10000} -> 0 | H17: {=(SUMPRODUCT((华东区域指挥部主办逾期!$N$3:$N$31>0)*(华东区域指挥部主办逾期!$T$3:$T$31=D17)*华东区域指挥部主办逾期!$N$3:$N$31*华东区域指挥部主办逾期!$Q$3:$Q$31*华东区域指挥部主办逾期!$U$3:$U$31)+SUMPRODUCT((华东区域指挥部主办逾期!$N$3:$N$31>0)*(华东区域指挥部主办逾期!$W$3:$W$31=D17)*华东区域指挥部主办逾期!$N$3:$N$31*华东区域指挥部主办逾期!$Q$3:$Q$31*华东区域指挥部主办逾期!$X$3:$X$31)+SUMPRODUCT((华东区域指挥协办逾期!$N$3:$N$10>0)*(华东区域指挥协办逾期!$T$3:$T$10=D17)*华东区域指挥协办逾期!$N$3:$N$10*华东区域指挥协办逾期!$Q$3:$Q$10*华东区域指挥协办逾期!$U$3:$U$10)+SUMPRODUCT((华东区域指挥协办逾期!$N$3:$N$10>0)*(华东区域指挥协办逾期!$W$3:$W$10=D17)*华东区域指挥协办逾期!$N$3:$N$10*华东区域指挥协办逾期!$Q$3:$Q$10*华东区域指挥协办逾期!$X$3:$X$10))/10000} -> 721.57749 | I17: {=(SUMPRODUCT((华东区域指挥部主办逾期!$O$3:$O$31>0)*(华东区域指挥部主办逾期!$T$3:$T$31=D17)*华东区域指挥部主办逾期!$O$3:$O$31*华东区域指挥部主办逾期!$Q$3:$Q$31*华东区域指挥部主办逾期!$U$3:$U$31)+SUMPRODUCT((华东区域指挥部主办逾期!$O$3:$O$31>0)*(华东区域指挥部主办逾期!$W$3:$W$31=D17)*华东区域指挥部主办逾期!$O$3:$O$31*华东区域指挥部主办逾期!$Q$3:$Q$31*华东区域指挥部主办逾期!$X$3:$X$31)+SUMPRODUCT((华东区域指挥协办逾期!$O$3:$O$10>0)*(华东区域指挥协办逾期!$T$3:$T$10=D17)*华东区域指挥协办逾期!$O$3:$O$10*华东区域指挥协办逾期!$Q$3:$Q$10*华东区域指挥协办逾期!$U$3:$U$10)+SUMPRODUCT((华东区域指挥协办逾期!$O$3:$O$10>0)*(华东区域指挥协办逾期!$W$3:$W$10=D17)*华东区域指挥协办逾期!$O$3:$O$10*华东区域指挥协办逾期!$Q$3:$Q$10*华东区域指挥协办逾期!$X$3:$X$10))/10000} -> 0 | J17: {=(SUMPRODUCT((华东区域指挥部主办逾期!$P$3:$P$31>0)*(华东区域指挥部主办逾期!$T$3:$T$31=D17)*华东区域指挥部主办逾期!$P$3:$P$31*华东区域指挥部主办逾期!$Q$3:$Q$31*华东区域指挥部主办逾期!$U$3:$U$31)+SUMPRODUCT((华东区域指挥部主办逾期!$P$3:$P$31>0)*(华东区域指挥部主办逾期!$W$3:$W$31=D17)*华东区域指挥部主办逾期!$P$3:$P$31*华东区域指挥部主办逾期!$Q$3:$Q$31*华东区域指挥部主办逾期!$X$3:$X$31)+SUMPRODUCT((华东区域指挥协办逾期!$P$3:$P$10>0)*(华东区域指挥协办逾期!$T$3:$T$10=D17)*华东区域指挥协办逾期!$P$3:$P$10*华东区域指挥协办逾期!$Q$3:$Q$10*华东区域指挥协办逾期!$U$3:$U$10)+SUMPRODUCT((华东区域指挥协办逾期!$P$3:$P$10>0)*(华东区域指挥协办逾期!$W$3:$W$10=D17)*华东区域指挥协办逾期!$P$3:$P$10*华东区域指挥协办逾期!$Q$3:$Q$10*华东区域指挥协办逾期!$X$3:$X$10))/10000} -> 0 | K17: =SUM(F17:J17) -> 721.57749 | L17: =E17-K17 -> 0 | M17: =L17/E17 -> 0
A18: 13 | D18: 周斌 | E18: 1650.0742 | F18: {=(SUMPRODUCT((华东区域指挥部主办逾期!$L$3:$L$31>0)*(华东区域指挥部主办逾期!$T$3:$T$31=D18)*华东区域指挥部主办逾期!$L$3:$L$31*华东区域指挥部主办逾期!$Q$3:$Q$31*华东区域指挥部主办逾期!$U$3:$U$31)+SUMPRODUCT((华东区域指挥部主办逾期!$L$3:$L$31>0)*(华东区域指挥部主办逾期!$W$3:$W$31=D18)*华东区域指挥部主办逾期!$L$3:$L$31*华东区域指挥部主办逾期!$Q$3:$Q$31*华东区域指挥部主办逾期!$X$3:$X$31)+SUMPRODUCT((华东区域指挥协办逾期!$L$3:$L$10>0)*(华东区域指挥协办逾期!$T$3:$T$10=D18)*华东区域指挥协办逾期!$L$3:$L$10*华东区域指挥协办逾期!$Q$3:$Q$10*华东区域指挥协办逾期!$U$3:$U$10)+SUMPRODUCT((华东区域指挥协办逾期!$L$3:$L$10>0)*(华东区域指挥协办逾期!$W$3:$W$10=D18)*华东区域指挥协办逾期!$L$3:$L$10*华东区域指挥协办逾期!$Q$3:$Q$10*华东区域指挥协办逾期!$X$3:$X$10))/10000} -> 0 | G18: {=(SUMPRODUCT((华东区域指挥部主办逾期!$M$3:$M$31>0)*(华东区域指挥部主办逾期!$T$3:$T$31=D18)*华东区域指挥部主办逾期!$M$3:$M$31*华东区域指挥部主办逾期!$Q$3:$Q$31*华东区域指挥部主办逾期!$U$3:$U$31)+SUMPRODUCT((华东区域指挥部主办逾期!$M$3:$M$31>0)*(华东区域指挥部主办逾期!$W$3:$W$31=D18)*华东区域指挥部主办逾期!$M$3:$M$31*华东区域指挥部主办逾期!$Q$3:$Q$31*华东区域指挥部主办逾期!$X$3:$X$31)+SUMPRODUCT((华东区域指挥协办逾期!$M$3:$M$10>0)*(华东区域指挥协办逾期!$T$3:$T$10=D18)*华东区域指挥协办逾期!$M$3:$M$10*华东区域指挥协办逾期!$Q$3:$Q$10*华东区域指挥协办逾期!$U$3:$U$10)+SUMPRODUCT((华东区域指挥协办逾期!$M$3:$M$10>0)*(华东区域指挥协办逾期!$W$3:$W$10=D18)*华东区域指挥协办逾期!$M$3:$M$10*华东区域指挥协办逾期!$Q$3:$Q$10*华东区域指挥协办逾期!$X$3:$X$10))/10000} -> 1146.0751 | H18: {=(SUMPRODUCT((华东区域指挥部主办逾期!$N$3:$N$31>0)*(华东区域指挥部主办逾期!$T$3:$T$31=D18)*华东区域指挥部主办逾期!$N$3:$N$31*华东区域指挥部主办逾期!$Q$3:$Q$31*华东区域指挥部主办逾期!$U$3:$U$31)+SUMPRODUCT((华东区域指挥部主办逾期!$N$3:$N$31>0)*(华东区域指挥部主办逾期!$W$3:$W$31=D18)*华东区域指挥部主办逾期!$N$3:$N$31*华东区域指挥部主办逾期!$Q$3:$Q$31*华东区域指挥部主办逾期!$X$3:$X$31)+SUMPRODUCT((华东区域指挥协办逾期!$N$3:$N$10>0)*(华东区域指挥协办逾期!$T$3:$T$10=D18)*华东区域指挥协办逾期!$N$3:$N$10*华东区域指挥协办逾期!$Q$3:$Q$10*华东区域指挥协办逾期!$U$3:$U$10)+SUMPRODUCT((华东区域指挥协办逾期!$N$3:$N$10>0)*(华东区域指挥协办逾期!$W$3:$W$10=D18)*华东区域指挥协办逾期!$N$3:$N$10*华东区域指挥协办逾期!$Q$3:$Q$10*华东区域指挥协办逾期!$X$3:$X$10))/10000} -> 132.43916 | I18: {=(SUMPRODUCT((华东区域指挥部主办逾期!$O$3:$O$31>0)*(华东区域指挥部主办逾期!$T$3:$T$31=D18)*华东区域指挥部主办逾期!$O$3:$O$31*华东区域指挥部主办逾期!$Q$3:$Q$31*华东区域指挥部主办逾期!$U$3:$U$31)+SUMPRODUCT((华东区域指挥部主办逾期!$O$3:$O$31>0)*(华东区域指挥部主办逾期!$W$3:$W$31=D18)*华东区域指挥部主办逾期!$O$3:$O$31*华东区域指挥部主办逾期!$Q$3:$Q$31*华东区域指挥部主办逾期!$X$3:$X$31)+SUMPRODUCT((华东区域指挥协办逾期!$O$3:$O$10>0)*(华东区域指挥协办逾期!$T$3:$T$10=D18)*华东区域指挥协办逾期!$O$3:$O$10*华东区域指挥协办逾期!$Q$3:$Q$10*华东区域指挥协办逾期!$U$3:$U$10)+SUMPRODUCT((华东区域指挥协办逾期!$O$3:$O$10>0)*(华东区域指挥协办逾期!$W$3:$W$10=D18)*华东区域指挥协办逾期!$O$3:$O$10*华东区域指挥协办逾期!$Q$3:$Q$10*华东区域指挥协办逾期!$X$3:$X$10))/10000} -> 6.12408 | J18: {=(SUMPRODUCT((华东区域指挥部主办逾期!$P$3:$P$31>0)*(华东区域指挥部主办逾期!$T$3:$T$31=D18)*华东区域指挥部主办逾期!$P$3:$P$31*华东区域指挥部主办逾期!$Q$3:$Q$31*华东区域指挥部主办逾期!$U$3:$U$31)+SUMPRODUCT((华东区域指挥部主办逾期!$P$3:$P$31>0)*(华东区域指挥部主办逾期!$W$3:$W$31=D18)*华东区域指挥部主办逾期!$P$3:$P$31*华东区域指挥部主办逾期!$Q$3:$Q$31*华东区域指挥部主办逾期!$X$3:$X$31)+SUMPRODUCT((华东区域指挥协办逾期!$P$3:$P$10>0)*(华东区域指挥协办逾期!$T$3:$T$10=D18)*华东区域指挥协办逾期!$P$3:$P$10*华东区域指挥协办逾期!$Q$3:$Q$10*华东区域指挥协办逾期!$U$3:$U$10)+SUMPRODUCT((华东区域指挥协办逾期!$P$3:$P$10>0)*(华东区域指挥协办逾期!$W$3:$W$10=D18)*华东区域指挥协办逾期!$P$3:$P$10*华东区域指挥协办逾期!$Q$3:$Q$10*华东区域指挥协办逾期!$X$3:$X$10))/10000} -> 275.19589 | K18: =SUM(F18:J18) -> 1559.8342 | L18: =E18-K18 -> 90.24 | M18: =L18/E18 -> 0.054688449
A19: 14 | D19: 小计 | E19: 2371.6517 | F19: =SUM(F17:F18) -> 0 | G19: =SUM(G17:G18) -> 1146.0751 | H19: =SUM(H17:H18) -> 854.01665 | I19: =SUM(I17:I18) -> 6.12408 | J19: =SUM(J17:J18) -> 275.19589 | K19: =SUM(K17:K18) -> 2281.4117 | L19: =SUM(L17:L18) -> 90.24 | M19: =L19/E19 -> 0.038049432
A20: 15 | C20: 建筑经营小组 | D20: 杨志胜 | E20: 2328.15 | F20: {=(SUMPRODUCT((华东区域指挥部主办逾期!$L$3:$L$31>0)*(华东区域指挥部主办逾期!$T$3:$T$31=D20)*华东区域指挥部主办逾期!$L$3:$L$31*华东区域指挥部主办逾期!$Q$3:$Q$31*华东区域指挥部主办逾期!$U$3:$U$31)+SUMPRODUCT((华东区域指挥部主办逾期!$L$3:$L$31>0)*(华东区域指挥部主办逾期!$W$3:$W$31=D20)*华东区域指挥部主办逾期!$L$3:$L$31*华东区域指挥部主办逾期!$Q$3:$Q$31*华东区域指挥部主办逾期!$X$3:$X$31)+SUMPRODUCT((华东区域指挥协办逾期!$L$3:$L$10>0)*(华东区域指挥协办逾期!$T$3:$T$10=D20)*华东区域指挥协办逾期!$L$3:$L$10*华东区域指挥协办逾期!$Q$3:$Q$10*华东区域指挥协办逾期!$U$3:$U$10)+SUMPRODUCT((华东区域指挥协办逾期!$L$3:$L$10>0)*(华东区域指挥协办逾期!$W$3:$W$10=D20)*华东区域指挥协办逾期!$L$3:$L$10*华东区域指挥协办逾期!$Q$3:$Q$10*华东区域指挥协办逾期!$X$3:$X$10))/10000} -> 0 | G20: {=(SUMPRODUCT((华东区域指挥部主办逾期!$M$3:$M$31>0)*(华东区域指挥部主办逾期!$T$3:$T$31=D20)*华东区域指挥部主办逾期!$M$3:$M$31*华东区域指挥部主办逾期!$Q$3:$Q$31*华东区域指挥部主办逾期!$U$3:$U$31)+SUMPRODUCT((华东区域指挥部主办逾期!$M$3:$M$31>0)*(华东区域指挥部主办逾期!$W$3:$W$31=D20)*华东区域指挥部主办逾期!$M$3:$M$31*华东区域指挥部主办逾期!$Q$3:$Q$31*华东区域指挥部主办逾期!$X$3:$X$31)+SUMPRODUCT((华东区域指挥协办逾期!$M$3:$M$10>0)*(华东区域指挥协办逾期!$T$3:$T$10=D20)*华东区域指挥协办逾期!$M$3:$M$10*华东区域指挥协办逾期!$Q$3:$Q$10*华东区域指挥协办逾期!$U$3:$U$10)+SUMPRODUCT((华东区域指挥协办逾期!$M$3:$M$10>0)*(华东区域指挥协办逾期!$W$3:$W$10=D20)*华东区域指挥协办逾期!$M$3:$M$10*华东区域指挥协办逾期!$Q$3:$Q$10*华东区域指挥协办逾期!$X$3:$X$10))/10000} -> 2064.65 | H20: {=(SUMPRODUCT((华东区域指挥部主办逾期!$N$3:$N$31>0)*(华东区域指挥部主办逾期!$T$3:$T$31=D20)*华东区域指挥部主办逾期!$N$3:$N$31*华东区域指挥部主办逾期!$Q$3:$Q$31*华东区域指挥部主办逾期!$U$3:$U$31)+SUMPRODUCT((华东区域指挥部主办逾期!$N$3:$N$31>0)*(华东区域指挥部主办逾期!$W$3:$W$31=D20)*华东区域指挥部主办逾期!$N$3:$N$31*华东区域指挥部主办逾期!$Q$3:$Q$31*华东区域指挥部主办逾期!$X$3:$X$31)+SUMPRODUCT((华东区域指挥协办逾期!$N$3:$N$10>0)*(华东区域指挥协办逾期!$T$3:$T$10=D20)*华东区域指挥协办逾期!$N$3:$N$10*华东区域指挥协办逾期!$Q$3:$Q$10*华东区域指挥协办逾期!$U$3:$U$10)+SUMPRODUCT((华东区域指挥协办逾期!$N$3:$N$10>0)*(华东区域指挥协办逾期!$W$3:$W$10=D20)*华东区域指挥协办逾期!$N$3:$N$10*华东区域指挥协办逾期!$Q$3:$Q$10*华东区域指挥协办逾期!$X$3:$X$10))/10000} -> 9 | I20: {=(SUMPRODUCT((华东区域指挥部主办逾期!$O$3:$O$31>0)*(华东区域指挥部主办逾期!$T$3:$T$31=D20)*华东区域指挥部主办逾期!$O$3:$O$31*华东区域指挥部主办逾期!$Q$3:$Q$31*华东区域指挥部主办逾期!$U$3:$U$31)+SUMPRODUCT((华东区域指挥部主办逾期!$O$3:$O$31>0)*(华东区域指挥部主办逾期!$W$3:$W$31=D20)*华东区域指挥部主办逾期!$O$3:$O$31*华东区域指挥部主办逾期!$Q$3:$Q$31*华东区域指挥部主办逾期!$X$3:$X$31)+SUMPRODUCT((华东区域指挥协办逾期!$O$3:$O$10>0)*(华东区域指挥协办逾期!$T$3:$T$10=D20)*华东区域指挥协办逾期!$O$3:$O$10*华东区域指挥协办逾期!$Q$3:$Q$10*华东区域指挥协办逾期!$U$3:$U$10)+SUMPRODUCT((华东区域指挥协办逾期!$O$3:$O$10>0)*(华东区域指挥协办逾期!$W$3:$W$10=D20)*华东区域指挥协办逾期!$O$3:$O$10*华东区域指挥协办逾期!$Q$3:$Q$10*华东区域指挥协办逾期!$X$3:$X$10))/10000} -> 0 | J20: {=(SUMPRODUCT((华东区域指挥部主办逾期!$P$3:$P$31>0)*(华东区域指挥部主办逾期!$T$3:$T$31=D20)*华东区域指挥部主办逾期!$P$3:$P$31*华东区域指挥部主办逾期!$Q$3:$Q$31*华东区域指挥部主办逾期!$U$3:$U$31)+SUMPRODUCT((华东区域指挥部主办逾期!$P$3:$P$31>0)*(华东区域指挥部主办逾期!$W$3:$W$31=D20)*华东区域指挥部主办逾期!$P$3:$P$31*华东区域指挥部主办逾期!$Q$3:$Q$31*华东区域指挥部主办逾期!$X$3:$X$31)+SUMPRODUCT((华东区域指挥协办逾期!$P$3:$P$10>0)*(华东区域指挥协办逾期!$T$3:$T$10=D20)*华东区域指挥协办逾期!$P$3:$P$10*华东区域指挥协办逾期!$Q$3:$Q$10*华东区域指挥协办逾期!$U$3:$U$10)+SUMPRODUCT((华东区域指挥协办逾期!$P$3:$P$10>0)*(华东区域指挥协办逾期!$W$3:$W$10=D20)*华东区域指挥协办逾期!$P$3:$P$10*华东区域指挥协办逾期!$Q$3:$Q$10*华东区域指挥协办逾期!$X$3:$X$10))/10000} -> 4.5 | K20: =SUM(F20:J20) -> 2078.15 | L20: =E20-K20 -> 250 | M20: =L20/E20 -> 0.1073814
A21: 16 | C21: 闽赣小计 | E21: 4699.8017 | F21: =SUM(F19,F20) -> 0 | G21: =SUM(G19,G20) -> 3210.7251 | H21: =SUM(H19,H20) -> 863.01665 | I21: =SUM(I19,I20) -> 6.12408 | J21: =SUM(J19,J20) -> 279.69589 | K21: =SUM(K19,K20) -> 4359.5617 | L21: =SUM(L19,L20) -> 340.24 | M21: =L21/E21 -> 0.072394544
A22: 17 | B22: 华东区域指挥部合计 | E22: 8135.52 | F22: =SUM(F13,F16,F21) -> 0 | G22: =SUM(G13,G16,G21) -> 4340.2161 | H22: =SUM(H13,H16,H21) -> 1396.2698 | I22: =SUM(I13,I16,I21) -> 248.88068 | J22: =SUM(J13,J16,J21) -> 561.06778 | K22: =SUM(K13,K16,K21) -> 6546.4343 | L22: =SUM(L13,L16,L21) -> 1589.0857 | M22: =L22/E22 -> 0.19532687
K23: 17210.434
K25: =K22+K23 -> 23756.869
K26: =E22-K25 -> -15621.349
K27: =K26/E22 -> -1.9201414

Sheet 华东区域指挥部主办逾期
A1: 序号 | B1: 系统内/外 | C1: 客户名称 | D1: 项目名称 | E1: 合同编号 | F1: 设备工号 | G1: 期初逾期 | H1: 3月回款 | I1: 累计回款 | J1: 剩余逾期 | K1: 考核备注 | L1: 逾期账龄 | Q1: 拆分比例 | S1: 责任领导 | T1: 责任人1 | W1: 责任人2 | Z1: 责任人3 | AC1: 责任人4
L2: 3个月以内 | M2: 3-6个月 | N2: 6-12个月 | O2: 1-3年 | P2: 3年以上 | Q2: 主办比例 | R2: 归属华东金额 | S2: 姓名 | T2: 姓名 | U2: 比例 | V2: 金额 | W2: 姓名 | X2: 比例 | Y2: 金额 | Z2: 姓名 | AA2: 比例 | AB2: 金额 | AC2: 姓名 | AD2: 比例 | AE2: 金额
A3: 1 | B3: 系统外 | C3: 福州地铁实业有限公司 | D3: 福州市轨道交通2号线项目 | E3: SY-ZY-2022-097 | G3: 10376551 | I3: 0 | J3: =G3-I3 -> 10376551 | K3: =J3-SUM(L3:P3) -> 0 | M3: 10376551 | Q3: 1 | R3: =J3*Q3 -> 10376551 | S3: 张仕民 | T3: 周斌 | U3: 1 | V3: =R3*U3 -> 10376551
A4: 2 | B4: 系统外 | C4: 中国葛洲坝集团第二工程有限公司 | D4: 江西奉新抽水蓄能电站 | E4: CGGC2GS-SB-TBMYYZX-2024-001 | G4: 1402143 | I4: 0 | J4: =G4-I4 -> 1402143 | K4: =J4-SUM(L4:P4) -> 0 | M4: 0 | N4: 1402143 | O4: 0 | Q4: 0.7 | R4: =J4*Q4 -> 981500.1 | S4: 张仕民 | T4: 陈浩 | U4: 1 | V4: =R4*U4 -> 981500.1
A5: 3 | B5: 系统外 | C5: 中建海峡建设发展有限公司 | D5: 福州地铁 | E5: 107003021【2017】55SZ83-07 | G5: 5070000 | I5: 490000 | J5: =3241958.85200001-I5 -> 2751958.9 | K5: =J5-SUM(L5:P5) -> 0 | O5: 0 | P5: 2751958.9 | Q5: 1 | R5: =J5*Q5 -> 2751958.9 | S5: 张仕民 | T5: 周斌 | U5: 1 | V5: =R5*U5 -> 2751958.9
A6: 4 | B6: 系统外 | C6: 上海地铁盾构设备工程有限公司 | D6: 上海地铁 | E6: CRCHI-XS-2021-028 | G6: 280000 | I6: 71196 | J6: =G6-I6 -> 208804 | K6: =J6-SUM(L6:P6) -> 0 | O6: 208804 | Q6: 1 | R6: =J6*Q6 -> 208804 | S6: 穆华清 | T6: 穆华清 | U6: 0.7 | V6: =R6*U6 -> 146162.8 | W6: 赵宇瑄 | X6: 0.3 | Y6: =R6*X6 -> 62641.2
A7: 5 | B7: 系统内 | C7: 中铁十六局轨道公司 | D7: 嘉闵线 | E7: CRCC-16J-JMWZ-2024-008 | F7: DL1558 | G7: 2486114 | I7: 2486114 | J7: =G7-I7 -> 0 | K7: =J7-SUM(L7:P7) -> 0 | L7: 0 | Q7: 0.7 | R7: =J7*Q7 -> 0 | S7: 穆华清 | T7: 赵宇瑄 | U7: 1 | V7: =R7*U7 -> 0
A8: 6 | B8: 系统内 | C8: 中铁十六局轨道公司 | D8: 嘉闵线 | E8: CRCC-16J-JMWZ-2024-008 | F8: DL1559 | G8: 1936062 | I8: 1043886 | J8: =G8-I8 -> 892176 | K8: =J8-SUM(L8:P8) -> 0 | L8: 0 | M8: 892176 | Q8: 0.7 | R8: =J8*Q8 -> 624523.2 | S8: 穆华清 | T8: 赵宇瑄 | U8: 1 | V8: =R8*U8 -> 624523.2
A9: 7 | B9: 系统内 | C9: 中铁十八局四公司 | D9: 嘉善铁路 | E9: 0-SHB-2025-嘉善至西塘市域铁路-0-001 | G9: 1242000 | I9: 0 | J9: =G9-I9 -> 1242000 | K9: =J9-SUM(L9:P9) -> 0 | M9: 828000 | N9: 414000 | Q9: 0.7 | R9: =J9*Q9 -> 869400 | S9: 丁艳林 | T9: 唐作栋 | U9: 1 | V9: =R9*U9 -> 869400
A10: 8 | B10: 系统内 | C10: 中铁十一局集团第四工程有限公司 | D10: 甬舟铁路凿岩台车、多功能钻机 | E10: C2000010001100004011002025006 | G10: 5854000 | I10: 2000000 | J10: =G10-I10 -> 3854000 | K10: =J10-SUM(L10:P10) -> 0 | N10: 3854000 | Q10: 0.7 | R10: =J10*Q10 -> 2697800 | S10: 丁艳林 | T10: 万赛 | U10: 1 | V10: =R10*U10 -> 2697800
A11: 9 | B11: 系统内 | C11: 中国铁建港航局集团有限公司第二工程分公司 | D11: 320国道项目 | E11: GH-02-SBHT-202501-03 | G11: 1020000 | H11: 492100 | I11: 492100 | J11: =G11-I11 -> 527900 | K11: =J11-SUM(L11:P11) -> 0 | M11: 527900 | Q11: 1 | R11: =J11*Q11 -> 527900 | S11: 丁艳林 | T11: 唐作栋 | U11: 1 | V11: =R11*U11 -> 527900
A12: 10 | B12: 系统外 | C12: 上海地铁盾构设备工程有限公司 | D12: 4台管片外径Φ9000mm盾构机嘉闵线适应性改造项目合同 | E12: D23-137F-S00-087 | G12: 2379724 | I12: 0 | J12: 1845485 | K12: =J12-SUM(L12:P12) -> 0 | M12: 929723 | N12: 0 | O12: 915762 | Q12: 1 | R12: =J12*Q12 -> 1845485 | S12: 穆华清 | T12: 穆华清 | U12: 0.7 | V12: =R12*U12 -> 1291839.5 | W12: 赵宇瑄 | X12: 0.3 | Y12: =R12*X12 -> 553645.5
A13: 11 | B13: 系统内 | C13: 北京中铁天瑞机械设备有限公司 | D13: 杭州18号线盾构设备租赁合同 | E13: CR22TR-SBZLCG-HW-2025-001 | G13: 2000000 | I13: 2000000 | J13: =G13-I13 -> 0 | K13: =J13-SUM(L13:P13) -> 0 | M13: 0 | Q13: 0.7 | R13: =J13*Q13 -> 0 | S13: 丁艳林 | T13: 刘新峥 | U13: 1 | V13: =R13*U13 -> 0
A14: 12 | B14: 系统内 | C14: 中国铁建港航局集团有限公司第二工程分公司 | D14: 320国道杭州博陆至仁和段工程（余杭段）第TJ02标段 | E14: GH-02-SBHT-202505-008 | G14: 30900 | I14: 0 | J14: =G14-I14 -> 30900 | K14: =J14-SUM(L14:P14) -> 0 | N14: 30900 | Q14: 1 | R14: =J14*Q14 -> 30900 | S14: 丁艳林 | T14: 唐作栋 | U14: 1 | V14: =R14*U14 -> 30900
A15: 13 | B15: 系统内 | C15: 中铁十二局集团第二工程有限公司 | D15: 漳汕铁路漳汕铁路项目1台MT141-FLB3采购 | E15: CR122-SBB-2025-006-MM006 | G15: 930000 | I15: 0 | J15: =G15-I15 -> 930000 | K15: =J15-SUM(L15:P15) -> 0 | M15: 930000 | Q15: 0.6 | R15: =J15*Q15 -> 558000 | S15: 张仕民 | T15: 杨志胜 | U15: 1 | V15: =R15*U15 -> 558000
A16: 14 | B16: 系统内 | C16: 中铁十五局集团第二工程有限公司 | D16: 西渝高铁 | E16: CR15G2C-SBCG-2024-11 | G16: 800000 | I16: 0 | J16: =G16-I16 -> 800000 | K16: =J16-SUM(L16:P16) -> 0 | O16: 800000 | Q16: 0.7 | R16: =J16*Q16 -> 560000 | S16: 穆华清 | T16: 赵宇瑄 | U16: 1 | V16: =R16*U16 -> 560000
A17: 15 | B17: 系统内 | C17: 中铁二十局集团第三工程有限公司 | D17: 长赣铁路 | E17: ZT2003CGWS20250004 | G17: 588000 | I17: 0 | J17: =G17-I17 -> 588000 | K17: =J17-SUM(L17:P17) -> 0 | N17: 588000 | Q17: 0.6 | R17: =J17*Q17 -> 352800 | S17: 张仕民 | T17: 陈浩 | U17: 1 | V17: =R17*U17 -> 352800
A18: 16 | B18: 系统外 | C18: 浙江物产工程技术服务有限公司 | D18: 浙江物产工服4台ZTE6410盾构机维修改造项目 | E18: WCGF-DZ620-04-WXLT | G18: 199800 | I18: 199800 | J18: =G18-I18 -> 0 | K18: =J18-SUM(L18:P18) -> 0 | L18: 0 | Q18: 0.7 | R18: =J18*Q18 -> 0 | S18: 丁艳林 | T18: 唐作栋 | U18: 0.6 | V18: =R18*U18 -> 0 | W18: 刘新峥 | X18: 0.4 | Y18: =R18*X18 -> 0
A19: 17 | B19: 系统内 | C19: 中铁十二局集团第四工程有限公司 | D19: 杭州地铁12号线DZ038、DZ039盾构机维修 | E19: ZT12-4HZDT12-01 | G19: 8160000 | I19: 3000000 | J19: =G19-I19 -> 5160000 | K19: =J19-SUM(L19:P19) -> 0 | M19: 5160000 | Q19: 0.7 | R19: =J19*Q19 -> 3612000 | S19: 丁艳林 | T19: 唐作栋 | U19: 0.6 | V19: =R19*U19 -> 2167200 | W19: 刘新峥 | X19: 0.4 | Y19: =R19*X19 -> 1444800
A20: 18 | B20: 系统内 | C20: 中铁十八局集团市政工程有限公司 | D20: 杭州地铁10号线盾构设备租赁 | E20: 12-SHBZ-2024-杭州地铁1032-12-002 | G20: 4715760.6 | I20: 4715760.6 | J20: =G20-I20 -> 0 | K20: =J20-SUM(L20:P20) -> 0 | L20: 0 | Q20: 0.7 | R20: =J20*Q20 -> 0 | S20: 丁艳林 | T20: 唐作栋 | U20: 0.6 | V20: =R20*U20 -> 0 | W20: 刘新峥 | X20: 0.4 | Y20: =R20*X20 -> 0
A21: 19 | B21: 系统内 | C21: 中铁十五局集团第三工程有限公司 | D21: 瑞梅铁路 | E21: 局合专6（2024）-052号 | G21: 90000 | I21: 0 | J21: =G21-I21 -> 90000 | K21: =J21-SUM(L21:P21) -> 0 | N21: 90000 | Q21: 1 | R21: =J21*Q21 -> 90000 | S21: 张仕民 | T21: 杨志胜 | U21: 1 | V21: =R21*U21 -> 90000
A22: 20 | B22: 系统外 | C22: 中交第三公路工程局有限公司 | D22: 滨海快线（福州至长乐机场城际铁路工程）第3标段54工区项目 | E22: ZCB-BHKX3-04-JX-03-2021 | G22: 8028 | I22: 0 | J22: =G22-I22 -> 8028 | K22: =J22-SUM(L22:P22) -> 0 | O22: 8028 | Q22: 0.8 | R22: =J22*Q22 -> 6422.4 | S22: 张仕民 | T22: 周斌 | U22: 1 | V22: =R22*U22 -> 6422.4
A23: 21 | B23: 系统外 | C23: 中交第三公路工程局有限公司 | D23: 滨海快线（福州至长乐机场城际铁路工程）第3标段54工区项目 | E23: ZCB-BHKX3-04-JX-03-2021 | G23: 318523 | H23: 200000 | I23: 250000 | J23: =G23-I23 -> 68523 | K23: =J23-SUM(L23:P23) -> 0 | O23: 68523 | Q23: 0.8 | R23: =J23*Q23 -> 54818.4 | S23: 张仕民 | T23: 周斌 | U23: 1 | V23: =R23*U23 -> 54818.4
A24: 22 | B24: 系统内 | C24: 中铁十五局集团城市轨道交通工程有限公司 | D24: 杭州机场高铁搅拌站采购 | E24: CR15-HZJCGT4-JD-202301-(1F) | G24: 453680 | I24: 453680 | J24: =G24-I24 -> 0 | K24: =J24-SUM(L24:P24) -> 0 | N24: 0 | Q24: 0.6 | R24: =J24*Q24 -> 0 | S24: 丁艳林 | T24: 唐作栋 | U24: 1 | V24: =R24*U24 -> 0
A25: 23 | B25: 系统内 | C25: 中铁十五局集团第二工程有限公司 | D25: 义龙庆高速 | E25: CR15G2C-SBCG-2024-16 | G25: 743000 | I25: 0 | J25: =G25-I25 -> 743000 | K25: =J25-SUM(L25:P25) -> 0 | O25: 743000 | Q25: 1 | R25: =J25*Q25 -> 743000 | S25: 丁艳林 | T25: 袁志凌 | U25: 0.6 | V25: =R25*U25 -> 445800 | W25: 袁志凌 | X25: 0.4 | Y25: =R25*X25 -> 297200
A26: 24 | B26: 系统内 | C26: 中铁十九局轨道公司 | D26: 杭州轨道快线土建施工SGJC-4标 | E26: SBHT-09-HZ08-2019-016 | F26: DL263G2 | G26: 1249600 | I26: 0 | J26: =G26-I26 -> 1249600 | K26: =J26-SUM(L26:P26) -> 0 | P26: 1249600 | Q26: 0.7 | R26: =J26*Q26 -> 874720 | S26: 丁艳林 | T26: 唐作栋 | U26: 0.8 | V26: =R26*U26 -> 699776 | W26: 刘新峥 | X26: 0.2 | Y26: =R26*X26 -> 174944
A27: 25 | B27: 系统内 | C27: 中铁二十二局集团第四工程有限公司 | D27: 金义东市域铁路15标项目 | E27: CRCHI-TD-2020-003 | F27: DL242/271 | G27: 2769998.5 | I27: 0 | J27: =G27-I27 -> 2769998.5 | K27: =J27-SUM(L27:P27) -> 0 | P27: 2769998.5 | Q27: 0.7 | R27: =J27*Q27 -> 1938998.9 | S27: 丁艳林 | T27: 万赛 | U27: 1 | V27: =R27*U27 -> 1938998.9
A28: 26 | B28: 系统内 | C28: 中铁十二局集团第四工程有限公司 | D28: 中铁十二局四公司长赣特装设备采购项目 | E28: ZT12-CGJXZQ8-004、005、009 | G28: 2142000 | I28: 0 | J28: =G28-I28 -> 2142000 | K28: =J28-SUM(L28:P28) -> 0 | L28: 0 | M28: 2142000 | Q28: 0.5 | R28: =J28*Q28 -> 1071000 | S28: 杨志胜 | T28: 杨志胜 | U28: 1 | V28: =R28*U28 -> 1071000
A29: 27 | B29: 系统内 | C29: 中铁十二局集团第四工程有限公司 | D29: 中铁十二局四公司长赣特装设备采购项目 | E29: ZT12-CGJXZQ8-001、002、003、006、007、008 | G29: 43035000 | I29: 5000000 | J29: =G29-I29 -> 38035000 | K29: =J29-SUM(L29:P29) -> 0 | L29: 0 | M29: 38035000 | Q29: 0.5 | R29: =J29*Q29 -> 19017500 | S29: 杨志胜 | T29: 杨志胜 | U29: 1 | V29: =R29*U29 -> 19017500
A30: 28 | B30: 系统内 | C30: 中铁二十局集团有限公司 | D30: 中铁20局福州港后铁路机制砂项目 | E30: CR2006-港后-SC-25-010 | G30: 212400 | I30: 212400 | J30: =G30-I30 -> 0 | K30: =J30-SUM(L30:P30) -> 0 | L30: 0 | Q30: 1 | R30: =J30*Q30 -> 0 | S30: 张仕民 | T30: 周斌 | U30: 1 | V30: =R30*U30 -> 0
A31: 29 | B31: 系统外 | C31: 上海地铁盾构设备工程有限公司 | D31: 崇明线105标 | E31: D24-022F-T00-005 | F31: DL749G2 | G31: 2682000 | I31: 306735 | J31: 2375265 | K31: =J31-SUM(L31:P31) -> 0 | M31: 61233.33 | N31: =J31-M31 -> 2314031.7 | Q31: 1 | R31: =J31*Q31 -> 2375265 | S31: 穆华清 | T31: 赵宇瑄 | U31: 1 | V31: =R31*U31 -> 2375265
J32: =SUBTOTAL(9,J3:J31) -> 78091332 | L32: =SUBTOTAL(9,L3:L31) -> 0 | M32: =SUBTOTAL(9,M3:M31) -> 59882583 | N32: =SUBTOTAL(9,N3:N31) -> 8693074.7 | O32: =SUBTOTAL(9,O3:O31) -> 2744117 | P32: =SUBTOTAL(9,P3:P31) -> 6771557.4 | R32: =SUM(R3:R31) -> 52169347

Sheet 华东区域指挥部主办逾期 (含2021年已回完的项目)
A1: 序号 | B1: 合同主体 | C1: 系统内/外 | D1: 客户名称 | E1: 单位名称 | F1: 项目名称 | G1: 合同编号 | H1: 合同金额 | I1: 合同签订时间 | J1: 设备工号 | K1: 期初逾期 | L1: 2月回款 | M1: 累计回款 | N1: 剩余逾期 | O1: 风险等级 | P1: 主办比例 | Q1: 归属华东金额 | R1: 责任领导 | S1: 责任人1 | V1: 责任人2
R3: 姓名 | S3: 姓名 | T3: 比例 | U3: 金额 | V3: 姓名 | W3: 比例 | X3: 金额
A4: 1 | B4: 工程 | C4: 系统内 | D4: 中铁十一局五公司台州市域铁路项目部 | E4: 十一局五公司 | G4: CRCC11-TJZG-2019-01 | H4: 25086006 | I4: 43511 | J4: DL280G2 | K4: 0 | M4: =K4-N4 -> 0 | N4: 0 | O4: 一般3级 | P4: 0.7 | Q4: =N4*P4 -> 0 | R4: 丁艳林 | S4: 段靖宗 | T4: 0.7 | U4: =Q4*T4 -> 0 | V4: 唐作栋 | W4: 0.3 | X4: =Q4*W4 -> 0
A5: 2 | B5: 工程 | C5: 系统内 | D5: 中铁十六局集团有限公司杭州地铁8号线一期工程施工总承包土建工区一项目部 | E5: 十六局集团 | G5: ZT16J-HZDT8YY-DGZL-001 | H5: 11787600 | I5: 43678 | J5: DL206-G1 | K5: 5656408.7 | M5: =K5-N5 -> 4000000 | N5: 1656408.7 | O5: 不良2级 | P5: 0.7 | Q5: =N5*P5 -> 1159486.1 | R5: 丁艳林 | S5: 段靖宗 | T5: 0.7 | U5: =Q5*T5 -> 811640.26 | V5: 唐作栋 | W5: 0.3 | X5: =Q5*W5 -> 347845.83
A6: 3 | B6: 工程 | C6: 系统内 | D6: 中铁十六局集团有限公司杭州地铁8号线一期工程施工总承包土建工区一项目部 | E6: 十六局集团 | F6: 杭州地铁8号线 | G6: ZT16J-HZDT8YY-DGZL-001 | H6: 11992800 | I6: 43678 | J6: DL262-G2 | K6: 6863991.3 | M6: =K6-N6 -> 0 | N6: 6863991.3 | O6: 不良1级 | P6: 0.7 | Q6: =N6*P6 -> 4804793.9 | R6: 丁艳林 | S6: 段靖宗 | T6: 0.7 | U6: =Q6*T6 -> 3363355.7 | V6: 唐作栋 | W6: 0.3 | X6: =Q6*W6 -> 1441438.2
A7: 4 | B7: 工程 | C7: 系统内 | D7: 中铁十九局集团有限公司杭州地铁8号线一期工程施工总承包土建工区二项目部 | E7: 十九局集团 | G7: SBHT-09-HZ08-2019-016 | H7: 9095400 | I7: 43693 | J7: DL263G2 | K7: 1549600 | M7: =K7-N7 -> 300000 | N7: 1249600 | O7: 一般3级 | P7: 0.7 | Q7: =N7*P7 -> 874720 | R7: 丁艳林 | S7: 段靖宗 | T7: 0.7 | U7: =Q7*T7 -> 612304 | V7: 唐作栋 | W7: 0.3 | X7: =Q7*W7 -> 262416
A8: 5 | B8: 工程 | C8: 系统内 | D8: 中铁十六局集团有限公司绍兴市城市轨道交通1号线工程土建施工10标项目经理部 | E8: 十六局集团 | F8: 绍兴市城市轨道交通1号线工程土建施工10标项目 | G8: SX1-10-DGJZL201911 | H8: 12768762 | I8: 43830 | J8: DL251 | K8: 1565140.1 | M8: =K8-N8 -> 1000000 | N8: 565140.1 | O8: 一般2级 | P8: 0.7 | Q8: =N8*P8 -> 395598.07 | R8: 丁艳林 | S8: 段靖宗 | T8: 0.7 | U8: =Q8*T8 -> 276918.65 | V8: 唐作栋 | W8: 0.3 | X8: =Q8*W8 -> 118679.42
A9: 6 | B9: 工程 | C9: 系统内 | D9: 中铁十六局集团有限公司绍兴市城市轨道交通1号线工程土建施工10标项目经理部 | E9: 十六局集团 | G9: SX1-10-DGJZL201911 | H9: 13517100 | I9: 43830 | J9: DL329 | K9: 743303.8 | M9: =K9-N9 -> 0 | N9: 743303.8 | O9: 一般3级 | P9: 0.7 | Q9: =N9*P9 -> 520312.66 | R9: 丁艳林 | S9: 段靖宗 | T9: 0.7 | U9: =Q9*T9 -> 364218.86 | V9: 唐作栋 | W9: 0.3 | X9: =Q9*W9 -> 156093.8
A10: 7 | B10: 工程 | C10: 系统外 | D10: 宏润建设集团股份有限公司 | E10: 宏润建设 | G10: DGGS-租赁类-(2017)10号-SZ | H10: 9705975 | I10: 42941 | J10: DL506 | K10: 0 | M10: =K10-N10 -> 0 | N10: 0 | O10: 风险1级 | P10: 1 | Q10: =N10*P10 -> 0 | R10: 丁艳林 | S10: 段靖宗 | T10: 1 | U10: =Q10*T10 -> 0
A11: 8 | B11: 工程 | C11: 系统外 | D11: 宏润建设集团股份有限公司 | E11: 宏润建设 | H11: 7940000 | I11: 43045 | J11: DL447 | K11: 3076365.6 | M11: =K11-N11 -> 150000 | N11: 2926365.6 | O11: 风险1级 | P11: 1 | Q11: =N11*P11 -> 2926365.6 | R11: 丁艳林 | S11: 段靖宗 | T11: 1 | U11: =Q11*T11 -> 2926365.6
A12: 9 | B12: 区域 | C12: 系统外 | D12: 浙江物产融资租赁有限公司 | E12: 浙江物产 | F12: 杭州地铁 | G12: WCZD-TJZG-2018-HZ02 | H12: 36500000 | I12: 43445 | J12: DZ630 | K12: 0 | M12: =K12-N12 -> 0 | N12: 0 | O12: 不良3级 | P12: 1 | Q12: =N12*P12 -> 0 | R12: 丁艳林 | S12: 段靖宗 | T12: 0.7 | U12: =Q12*T12 -> 0 | V12: 唐作栋 | W12: 0.3 | X12: =Q12*W12 -> 0
A13: 10 | B13: 区域 | C13: 系统内 | D13: 中铁十五局集团都匀桥梁有限公司 | E13: 中铁十五局集团都匀桥梁公司 | F13: 杭黄铁路 | G13: CRCHI-3-2014-316 | H13: 6400000 | I13: 41935 | J13: G020214048 07#左、G020214054右、G020214053左、G020214057 | K13: 0 | M13: =K13-N13 -> 0 | N13: 0 | P13: 1 | Q13: =N13*P13 -> 0 | R13: 高琳 | S13: 陈浩 | T13: 1 | U13: =Q13*T13 -> 0
A14: 11 | B14: 区域 | C14: 系统内 | D14: 中铁十五局集团都匀桥梁公司杭黄铁路站前VIII标项目经理部 | E14: 中铁十五局集团都匀桥梁公司 | F14: 杭黄铁路 | G14: CRCHI-TZ-2015-009 | H14: 2460000 | I14: 42082 | J14: G020114004 01#、G020114004 02# | K14: 1710000 | M14: =K14-N14 -> 0 | N14: 1710000 | O14: 风险2级 | P14: 1 | Q14: =N14*P14 -> 1710000 | R14: 高琳 | S14: 陈浩 | T14: 1 | U14: =Q14*T14 -> 1710000
A15: 12 | B15: 区域 | C15: 系统内 | D15: 中铁十五局集团第二工程有限公司 | E15: 十五局二公司 | F15: 杭黄铁路 | G15: SBCG-02-2016-014 | H15: 3730000 | I15: 42535 | J15: G070115067、、G070115061 | K15: 0 | M15: =K15-N15 -> 0 | N15: 0 | O15: 不良3级 | P15: 1 | Q15: =N15*P15 -> 0 | R15: 高琳 | S15: 陈浩 | T15: 1 | U15: =Q15*T15 -> 0
A16: 13 | B16: 区域 | C16: 系统内 | D16: 中铁十五局集团第一工程有限公司 | E16: 十五局一公司 | F16: 蒙华铁路 | G16: CRCHI-TZ-2016-1-022 | H16: 1720000 | I16: 42542 | J16: G070116056 | K16: 0 | M16: =K16-N16 -> 0 | N16: 0 | P16: 1 | Q16: =N16*P16 -> 0 | R16: 张仕民 | S16: 杨志胜 | T16: 1 | U16: =Q16*T16 -> 0
A17: 14 | B17: 区域 | C17: 系统内 | D17: 中铁十五局集团第四工程有限公司 | E17: 十五局四公司 | F17: 杭黄铁路 | G17: HH-SBCG-2016-019 | H17: 5500000 | I17: 42592 | J17: G070115054、G070115076、 G070115069 | K17: 0 | M17: =K17-N17 -> 0 | N17: 0 | P17: 1 | Q17: =N17*P17 -> 0 | R17: 张仕民 | S17: 杨志胜 | T17: 1 | U17: =Q17*T17 -> 0
A18: 15 | B18: 区域 | C18: 系统内 | D18: 中铁十五局集团第一工程有限公司 | E18: 十五局一公司 | F18: 玉墨铁路 | G18: CRCHI-TZ-2016-1-027 | H18: 1720000 | I18: 42604 | J18: G070116059 | K18: 0 | M18: =K18-N18 -> 0 | N18: 0 | O18: 风险1级 | P18: 1 | Q18: =N18*P18 -> 0 | R18: 张仕民 | S18: 杨志胜 | T18: 1 | U18: =Q18*T18 -> 0
A19: 16 | B19: 区域 | C19: 系统内 | D19: 中铁十五局集团第四工程有限公司 | E19: 十五局四公司 | F19: 渝黔铁路 | G19: YQ-SBCG-2016-009 | H19: 1760000 | I19: 42591 | J19: G070115060 | K19: 0 | M19: =K19-N19 -> 0 | N19: 0 | O19: 风险1级 | P19: 1 | Q19: =N19*P19 -> 0 | R19: 张仕民 | S19: 杨志胜 | T19: 1 | U19: =Q19*T19 -> 0
A20: 17 | B20: 区域 | C20: 系统外 | D20: 福建省冠畅建筑工程有限公司 | E20: 福建省冠畅建筑工程有限公司 | F20: 黔张常铁路 | G20: 16jqzc-2fb-01 | H20: 1980000 | I20: 42518 | J20: G070115100 | K20: 150000 | M20: =K20-N20 -> 0 | N20: 150000 | O20: 风险3级 | P20: 1 | Q20: =N20*P20 -> 150000 | R20: 张仕民 | S20: 杨志胜 | T20: 1 | U20: =Q20*T20 -> 150000
A21: 18 | B21: 区域 | C21: 系统内 | D21: 中铁十七局集团第六工程有限公司 | E21: 十七局六公司 | F21: 云平高速 | G21: CRCHI-TZ-2017-1-009 | H21: 1586000 | I21: 42802 | J21: G020216150 | K21: 0 | M21: =K21-N21 -> 0 | N21: 0 | O21: 风险1级 | P21: 1 | Q21: =N21*P21 -> 0 | R21: 张仕民 | S21: 杨志胜/邓华富 | T21: 0.5 | U21: =Q21*T21 -> 0 | V21: 周斌/申星 | W21: 0.5 | X21: =Q21*W21 -> 0
A22: 19 | B22: 区域 | C22: 系统内 | D22: 中铁十七局集团第六工程有限公司 | E22: 十七局六公司 | F22: 太焦铁路 | G22: CRCHI-TZ-2017-1-010 | H22: 4125000 | I22: 42809 | J22: G070116074、G070116076、G070116077 | K22: 0 | M22: =K22-N22 -> 0 | N22: 0 | O22: 不良3级 | P22: 1 | Q22: =N22*P22 -> 0 | R22: 张仕民 | S22: 杨志胜/邓华富 | T22: 0.5 | U22: =Q22*T22 -> 0 | V22: 周斌/申星 | W22: 0.5 | X22: =Q22*W22 -> 0
A23: 20 | B23: 区域 | C23: 系统内 | D23: 中铁十七局集团第六工程有限公司 | E23: 十七局六公司 | F23: 莆炎高速 | G23: CRCHI-TZ-2017-1-011 | H23: 1706000 | I23: 42803 | J23: G020216173 | K23: 0 | M23: =K23-N23 -> 0 | N23: 0 | O23: 风险1级 | P23: 1 | Q23: =N23*P23 -> 0 | R23: 张仕民 | S23: 杨志胜/邓华富 | T23: 0.5 | U23: =Q23*T23 -> 0 | V23: 周斌/申星 | W23: 0.5 | X23: =Q23*W23 -> 0
A24: 21 | B24: 区域 | C24: 系统内 | D24: 中铁十七局集团第六工程有限公司 | E24: 十七局六公司 | F24: 长福高速A2,A3标项目部 | G24: CRCHI-TZ-2017-1-012 | H24: 5136000 | I24: 42801 | J24: G020316081 | K24: 0 | M24: =K24-N24 -> 0 | N24: 0 | O24: 风险1级 | P24: 1 | Q24: =N24*P24 -> 0 | R24: 张仕民 | S24: 杨志胜/邓华富 | T24: 0.5 | U24: =Q24*T24 -> 0 | V24: 周斌/申星 | W24: 0.5 | X24: =Q24*W24 -> 0
A25: 22 | B25: 区域 | C25: 系统内 | D25: 中铁十七局集团第六工程有限公司 | E25: 十七局六公司 | F25: 福厦铁路 | G25: CRCC17(6)/GN/SBCG/2017010 | H25: 5170000 | I25: 42877 | J25: G020316092 | K25: 4970000 | M25: =K25-N25 -> 2795000 | N25: 2175000 | O25: 不良3级 | P25: 1 | Q25: =N25*P25 -> 2175000 | R25: 张仕民 | S25: 杨志胜/邓华富 | T25: 0.5 | U25: =Q25*T25 -> 1087500 | V25: 周斌/申星 | W25: 0.5 | X25: =Q25*W25 -> 1087500
A26: 23 | B26: 区域 | C26: 系统内 | D26: 中铁十七局集团第六工程有限公司 | E26: 十七局六公司 | F26: 沙埕湾跨海大桥 | G26: CRCC17(6)/GN/SBCG/2017021 | H26: 5040000 | I26: 42926 | J26: G020217067、G020217068、G020217069 | K26: 0 | M26: =K26-N26 -> 0 | N26: 0 | O26: 风险1级 | P26: 1 | Q26: =N26*P26 -> 0 | R26: 张仕民 | S26: 杨志胜/邓华富 | T26: 0.5 | U26: =Q26*T26 -> 0 | V26: 周斌/申星 | W26: 0.5 | X26: =Q26*W26 -> 0
A27: 24 | B27: 区域 | C27: 系统内 | D27: 中铁十七局集团第六工程有限公司 | E27: 十七局六公司 | F27: 蒲梅铁路 | G27: CRCHI-TZ-2017-1-013 | H27: 14772000 | I27: 42803 | J27: G02021633、34、35、36、52、53、54、55 | K27: 6440000 | M27: =K27-N27 -> 0 | N27: 6440000 | O27: 不良3级 | P27: 1 | Q27: =N27*P27 -> 6440000 | R27: 张仕民 | S27: 杨志胜/邓华富 | T27: 0.5 | U27: =Q27*T27 -> 3220000 | V27: 周斌/申星 | W27: 0.5 | X27: =Q27*W27 -> 3220000
A28: 25 | B28: 区域 | C28: 系统内 | D28: 中铁十七局集团第六工程有限公司 | E28: 十七局六公司 | F28: 大田公路 | G28: CRCC17(6)/GN/SBCG/2017033 | H28: 1610000 | I28: 42971 | J28: G020217055 | K28: 0 | M28: =K28-N28 -> 0 | N28: 0 | P28: 1 | Q28: =N28*P28 -> 0 | R28: 张仕民 | S28: 杨志胜/邓华富 | T28: 0.5 | U28: =Q28*T28 -> 0 | V28: 周斌/申星 | W28: 0.5 | X28: =Q28*W28 -> 0
A29: 26 | B29: 区域 | C29: 系统内 | D29: 中铁十七局集团第六工程有限公司 | E29: 十七局六公司 | F29: 莆炎高速项目 | G29: CRCC17(6)/GN/SBCG/2017034，CRCC17(6)/GN/SBCG/2017034补1(补充合同资料未找到) | H29: 4050000 | I29: 42971 | J29: G020217082、G020217083 | K29: 0 | M29: =K29-N29 -> 0 | N29: 0 | O29: 风险1级 | P29: 1 | Q29: =N29*P29 -> 0 | R29: 张仕民 | S29: 杨志胜/邓华富 | T29: 0.5 | U29: =Q29*T29 -> 0 | V29: 周斌/申星 | W29: 0.5 | X29: =Q29*W29 -> 0
A30: 27 | B30: 区域 | C30: 系统内 | D30: 中铁十七局集团第六工程有限公司 | E30: 十七局六公司 | F30: 靖永高速 | G30: CRCC17(6)/GN/SBCG/2018008 | H30: 3920000 | I30: 43256 | J30: G020218049、G020218050 | K30: 205000 | M30: =K30-N30 -> 0 | N30: 205000 | O30: 不良3级 | P30: 1 | Q30: =N30*P30 -> 205000 | R30: 张仕民 | S30: 杨志胜/邓华富 | T30: 0.5 | U30: =Q30*T30 -> 102500 | V30: 周斌/申星 | W30: 0.5 | X30: =Q30*W30 -> 102500
A31: 28 | B31: 区域 | C31: 系统内 | D31: 中铁二十三局集团轨道交通工程有限公司 | E31: 二十三局轨道公司 | F31: 佛山管片基地 | G31: CR235-FSGS-2017-SC01 | H31: 3108000 | I31: 42866 | J31: G020217035 | K31: 1625600 | M31: =K31-N31 -> 0 | N31: 1625600 | O31: 不良2级 | P31: 0.6 | Q31: =N31*P31 -> 975360 | R31: 张仕民 | S31: 杨志胜 | T31: 1 | U31: =Q31*T31 -> 975360
A32: 29 | B32: 区域 | C32: 系统内 | D32: 中铁十五局集团第一工程有限公司 | E32: 十五局一公司 | F32: 福宜高速 | G32: CRCHI-TZ-2017-1-015 | H32: 2540000 | I32: 42859 | J32: G020317007 | K32: 0 | M32: =K32-N32 -> 0 | N32: 0 | O32: 不良2级 | P32: 1 | Q32: =N32*P32 -> 0 | R32: 张仕民 | S32: 杨志胜 | T32: 1 | U32: =Q32*T32 -> 0
A33: 30 | B33: 区域 | C33: 系统内 | D33: 中铁十五局集团杭绍台高速绍兴金华段HST-TJ05合同段项目经理部 | E33: 十五局集团 | F33: 杭绍台铁路 | G33: SBCG-02-2017-009 | H33: 9980000 | I33: 43000 | J33: G100116026 | K33: 7879998 | M33: =K33-N33 -> 3500000 | N33: 4379998 | O33: 风险2级 | P33: 1 | Q33: =N33*P33 -> 4379998 | R33: 高琳 | S33: 陈浩 | T33: 1 | U33: =Q33*T33 -> 4379998
A34: 31 | B34: 区域 | C34: 系统内 | D34: 中铁二十三局集团轨道交通工程有限公司 | E34: 二十三局轨道公司 | F34: 清远磁浮项目 | G34: CR235-QYCF-2018-SC01 | H34: 1556581.2 | I34: 43441 | J34: G020218028 | K34: 748581.19 | M34: =K34-N34 -> 0 | N34: 748581.19 | O34: 不良2级 | P34: 0.6 | Q34: =N34*P34 -> 449148.71 | R34: 张仕民 | S34: 杨志胜 | T34: 1 | U34: =Q34*T34 -> 449148.71
A35: 32 | B35: 区域 | C35: 系统内 | D35: 中铁十五局集团第二工程有限公司 | E35: 十五局二公司 | F35: 兴赣高速 | G35: SBCG-02-2018-006 | H35: 1840000 | I35: 43236 | J35: G020117057 | K35: 0 | M35: =K35-N35 -> 0 | N35: 0 | O35: 不良1级 | P35: 1 | Q35: =N35*P35 -> 0 | R35: 高琳 | S35: 陈浩 | T35: 1 | U35: =Q35*T35 -> 0
A36: 33 | B36: 区域 | C36: 系统内 | D36: 中铁十五局集团第二工程有限公司 | E36: 十五局二公司 | F36: 临双高速 | G36: SBCG-02-2018-007 | H36: SBCG-02-2017-009 | I36: 43273 | J36: G020218080、G020218081 | K36: 482000 | M36: =K36-N36 -> 0 | N36: 482000 | O36: 不良2级 | P36: 1 | Q36: =N36*P36 -> 482000 | R36: 高琳 | S36: 陈浩 | T36: 1 | U36: =Q36*T36 -> 482000
A37: 34 | B37: 区域 | C37: 系统内 | D37: 中铁十五局集团第二工程有限公司 | E37: 十五局二公司 | F37: 安吉公路 | G37: SBCG-02-2018-009 | H37: 1800000 | I37: 43326 | J37: G020118005、06 | K37: 0 | M37: =K37-N37 -> 0 | N37: 0 | O37: 不良2级 | P37: 1 | Q37: =N37*P37 -> 0 | R37: 高琳 | S37: 陈浩 | T37: 1 | U37: =Q37*T37 -> 0
A38: 35 | B38: 区域 | C38: 系统内 | D38: 中铁十五局集团第一工程有限公司玉磨铁路项目经理部 | E38: 十五局一公司 | F38: 玉磨项目搅拌站电器系统改造 | G38: CRCHI-TZ-2016-1-018-补 | H38: 75000 | I38: 42534 | J38: G020216035、 G020216036 | K38: 75000 | M38: =K38-N38 -> 75000 | N38: 0 | O38: 风险2级 | P38: 1 | Q38: =N38*P38 -> 0 | R38: 张仕民 | S38: 杨志胜 | T38: 1 | U38: =Q38*T38 -> 0
A39: 36 | B39: 区域 | C39: 系统内 | D39: 中铁十五局集团第四工程有限公司 | E39: 十五局四公司 | F39: 渝怀铁路项目 | G39: YHTL-WZCG-2018-018 | H39: 52000 | I39: 43490 | K39: 0 | M39: =K39-N39 -> 0 | N39: 0 | O39: 不良2级 | P39: 1 | Q39: =N39*P39 -> 0 | R39: 张仕民 | S39: 杨志胜 | T39: 1 | U39: =Q39*T39 -> 0
A40: 37 | B40: 区域 | C40: 系统内 | D40: 中铁二十二局集团第三工程有限公司 | E40: 二十二局三公司 | F40: 南沿江项目 | G40: CR2203-GS-SBCG-2019-001 | H40: 10450000 | I40: 43244 | J40: G020319027、28、29、G020219001、02 | K40: 0 | M40: =K40-N40 -> 0 | N40: 0 | O40: 不良2级 | P40: 0.6 | Q40: =N40*P40 -> 0 | R40: 张仕民 | S40: 杨志胜 | T40: 0.7 | U40: =Q40*T40 -> 0 | V40: 邓华富 | W40: 0.3 | X40: =Q40*W40 -> 0
A41: 38 | B41: 区域 | C41: 系统内 | D41: 中铁十五局集团第一工程有限公司 | E41: 十五局一公司 | F41: 临大高速 | G41: CRCHI-LG-2019-002 | H41: 1059700 | I41: 43677 | J41: G020219018 | K41: 859700 | M41: =K41-N41 -> 0 | N41: 859700 | O41: 不良1级 | P41: 1 | Q41: =N41*P41 -> 859700 | R41: 张仕民 | S41: 杨志胜 | T41: 1 | U41: =Q41*T41 -> 859700
...

Sheet 华东区域指挥协办逾期
A1: 序号 | B1: 系统内/外 | C1: 客户名称 | D1: 项目名称 | E1: 合同编号 | F1: 设备工号 | G1: 期初逾期 | H1: 1月回款 | I1: 累计回款 | J1: 剩余逾期 | K1: 考核备注 | L1: 逾期账龄 | Q1: 拆分比例 | S1: 责任领导 | T1: 责任人1 | W1: 责任人2
L2: 3个月以内 | M2: 3-6个月 | N2: 6-12个月 | O2: 1-3年 | P2: 3年以上 | Q2: 协办比例 | R2: 归属华东金额 | S2: 姓名 | T2: 姓名 | U2: 比例 | V2: 金额 | W2: 姓名 | X2: 比例 | Y2: 金额
A3: 1 | B3: 系统外 | C3: 浙江物产工程技术服务有限公司 | D3: 长春地铁9号线2台ZTE7150租赁合同 | E3: CRCHI-GZ-2023-013 | G3: 2688100 | J3: =G3-I3 -> 2688100 | K3: =J3-SUM(L3:P3) -> 0 | M3: 2688100 | Q3: 0.3 | R3: =J3*Q3 -> 806430 | S3: 丁艳林 | T3: 唐作栋 | U3: 0.7 | V3: =R3*U3 -> 564501 | W3: 刘新峥 | X3: 0.3 | Y3: =R3*X3 -> 241929
A4: 2 | B4: 系统内 | C4: 中铁十四局大盾构公司 | D4: 昌九铁路ZTS14810泥水平衡盾构机改造合同”的审批申请 | E4: ZT14J-TJZG-GZ-2023001 | G4: 14703687 | J4: =G4-I4 -> 14703687 | K4: =J4-SUM(L4:P4) -> 0 | N4: 14703687 | Q4: 0.4 | R4: =J4*Q4 -> 5881474.8 | S4: 张仕民 | T4: 陈浩 | U4: 1 | V4: =R4*U4 -> 5881474.8
A5: 3 | B5: 系统内 | C5: 中铁十五局集团第二工程有限公司 | D5: 宜涪项目4台HZS180X采购合同 | E5: CR15G2C-SBCG-2025-07 | G5: 2172000 | J5: =G5-I5 -> 2172000 | K5: =J5-SUM(L5:P5) -> 0 | L5: 0 | M5: 2172000 | Q5: 0.3 | R5: =J5*Q5 -> 651600 | S5: 穆华清 | T5: 赵宇瑄 | U5: 1 | V5: =R5*U5 -> 651600
A6: 4 | B6: 系统内 | C6: 中铁十五局集团第二工程有限公司 | D6: 盐宜铁路搅拌站采购项目 | E6: CR15G2C-SBCG-2025-18 | G6: 2286000 | J6: =G6-I6 -> 2286000 | K6: =J6-SUM(L6:P6) -> 0 | L6: 0 | M6: 2286000 | Q6: 0.3 | R6: =J6*Q6 -> 685800 | S6: 穆华清 | T6: 赵宇瑄 | U6: 1 | V6: =R6*U6 -> 685800
A7: 5 | B7: 系统内 | C7: 中铁十九局集团华东工程有限公司 | D7: 宜昌至涪陵高速铁路（湖北段）项目 | E7: CRCHI-XS-2025-014 | G7: 852000 | J7: =G7-I7 -> 852000 | K7: =J7-SUM(L7:P7) -> 0 | L7: 0 | M7: 852000 | Q7: 0.3 | R7: =J7*Q7 -> 255600 | S7: 丁艳林 | T7: 万赛 | U7: 1 | V7: =R7*U7 -> 255600
A8: 6 | B8: 系统外 | C8: 江苏筑世国际贸易有限公司 | D8: 江苏筑世国际贸易有限公司沙特阿拉伯交通隧道项目1批隧道装备产品采购合同 | E8: CSCEC-ZSIT-PC-2024001 | G8: 12042958 | J8: =G8-I8 -> 12042958 | K8: =J8-SUM(L8:P8) -> 0 | M8: 5421000 | N8: 6621958 | Q8: 0.2 | R8: =J8*Q8 -> 2408591.6 | S8: 张仕民 | T8: 周斌 | U8: 1 | V8: =R8*U8 -> 2408591.6
A9: 7 | B9: 系统外 | C9: 福建省冠畅建筑工程有限公司 | D9: 黔张常铁路 | E9: 16jqzc-2fb-01 | G9: 150000 | J9: =G9-I9 -> 150000 | K9: =J9-SUM(L9:P9) -> 0 | P9: 150000 | Q9: 0.3 | R9: =J9*Q9 -> 45000 | S9: 张仕民 | T9: 杨志胜 | U9: 1 | V9: =R9*U9 -> 45000
A10: 8 | B10: 系统内 | C10: 中铁十五局集团第二工程有限公司 | D10: 中吉乌铁路1批特种装备采购合同 | E10: CR15G2C-SBCG-2025-17 | G10: 5121000 | J10: =G10-I10 -> 5121000 | K10: =J10-SUM(L10:P10) -> 0 | L10: 0 | M10: 5121000 | Q10: 0.5 | R10: =J10*Q10 -> 2560500 | S10: 穆华清 | T10: 赵宇瑄 | U10: 1 | V10: =R10*U10 -> 2560500

Sheet 按客户划分
A1: 客户类别 | B1: 客户 | C1: 存量逾期 | D1: 新增逾期 | E1: 合计 | F1: 逾期排名
A2: 系统内 | B2: 中铁二十四局福建公司 | C2: =(SUMIF(华东区域指挥部主办逾期!$C$3:$C$31,B2,华东区域指挥部主办逾期!$R$3:$R$31)+SUMIF(华东区域指挥协办逾期!$C$3:$C$10,B2,华东区域指挥协办逾期!$R$3:$R$10))/10000 -> 0 | D2: =(SUMIF([1]华东区域指挥部主办逾期!$C$3:$C$30,B2,[1]华东区域指挥部主办逾期!$R$3:$R$30)+SUMIF([1]华东区域指挥协办逾期!$C$3:$C$10,B2,[1]华东区域指挥协办逾期!$R$3:$R$10))/10000 -> 4426 | E2: =SUM(C2:D2) -> 4426 | F2: =_xlfn.RANK.EQ(E2,$E$2:$E$40) -> 1
A3: 系统内 | B3: 中铁十二局集团第四工程有限公司 | C3: =(SUMIF(华东区域指挥部主办逾期!$C$3:$C$31,B3,华东区域指挥部主办逾期!$R$3:$R$31)+SUMIF(华东区域指挥协办逾期!$C$3:$C$10,B3,华东区域指挥协办逾期!$R$3:$R$10))/10000 -> 2370.05 | D3: =(SUMIF([1]华东区域指挥部主办逾期!$C$3:$C$30,B3,[1]华东区域指挥部主办逾期!$R$3:$R$30)+SUMIF([1]华东区域指挥协办逾期!$C$3:$C$10,B3,[1]华东区域指挥协办逾期!$R$3:$R$10))/10000 -> 1013.45 | E3: =SUM(C3:D3) -> 3383.5 | F3: =_xlfn.RANK.EQ(E3,$E$2:$E$40) -> 2
A4: 系统内 | B4: 中铁十四局集团第二工程有限公司 | C4: =(SUMIF(华东区域指挥部主办逾期!$C$3:$C$31,B4,华东区域指挥部主办逾期!$R$3:$R$31)+SUMIF(华东区域指挥协办逾期!$C$3:$C$10,B4,华东区域指挥协办逾期!$R$3:$R$10))/10000 -> 0 | D4: =(SUMIF([1]华东区域指挥部主办逾期!$C$3:$C$30,B4,[1]华东区域指挥部主办逾期!$R$3:$R$30)+SUMIF([1]华东区域指挥协办逾期!$C$3:$C$10,B4,[1]华东区域指挥协办逾期!$R$3:$R$10))/10000 -> 2989 | E4: =SUM(C4:D4) -> 2989 | F4: =_xlfn.RANK.EQ(E4,$E$2:$E$40) -> 3
A5: 系统内 | B5: 中铁十四局隧道公司 | C5: =(SUMIF(华东区域指挥部主办逾期!$C$3:$C$31,B5,华东区域指挥部主办逾期!$R$3:$R$31)+SUMIF(华东区域指挥协办逾期!$C$3:$C$10,B5,华东区域指挥协办逾期!$R$3:$R$10))/10000 -> 0 | D5: =(SUMIF([1]华东区域指挥部主办逾期!$C$3:$C$30,B5,[1]华东区域指挥部主办逾期!$R$3:$R$30)+SUMIF([1]华东区域指挥协办逾期!$C$3:$C$10,B5,[1]华东区域指挥协办逾期!$R$3:$R$10))/10000 -> 2559.2 | E5: =SUM(C5:D5) -> 2559.2 | F5: =_xlfn.RANK.EQ(E5,$E$2:$E$40) -> 4
A6: 系统内 | B6: 中铁十二局集团第三工程有限公司 | C6: =(SUMIF(华东区域指挥部主办逾期!$C$3:$C$31,B6,华东区域指挥部主办逾期!$R$3:$R$31)+SUMIF(华东区域指挥协办逾期!$C$3:$C$10,B6,华东区域指挥协办逾期!$R$3:$R$10))/10000 -> 0 | D6: =(SUMIF([1]华东区域指挥部主办逾期!$C$3:$C$30,B6,[1]华东区域指挥部主办逾期!$R$3:$R$30)+SUMIF([1]华东区域指挥协办逾期!$C$3:$C$10,B6,[1]华东区域指挥协办逾期!$R$3:$R$10))/10000 -> 1191.68 | E6: =SUM(C6:D6) -> 1191.68 | F6: =_xlfn.RANK.EQ(E6,$E$2:$E$40) -> 5
A7: 系统内 | B7: 中铁十八局集团隧道工程有限公司 | C7: =(SUMIF(华东区域指挥部主办逾期!$C$3:$C$31,B7,华东区域指挥部主办逾期!$R$3:$R$31)+SUMIF(华东区域指挥协办逾期!$C$3:$C$10,B7,华东区域指挥协办逾期!$R$3:$R$10))/10000 -> 0 | D7: =(SUMIF([1]华东区域指挥部主办逾期!$C$3:$C$30,B7,[1]华东区域指挥部主办逾期!$R$3:$R$30)+SUMIF([1]华东区域指挥协办逾期!$C$3:$C$10,B7,[1]华东区域指挥协办逾期!$R$3:$R$10))/10000 -> 925.643 | E7: =SUM(C7:D7) -> 925.643 | F7: =_xlfn.RANK.EQ(E7,$E$2:$E$40) -> 8
A8: 系统外 | B8: 福州地铁实业有限公司 | C8: =(SUMIF(华东区域指挥部主办逾期!$C$3:$C$31,B8,华东区域指挥部主办逾期!$R$3:$R$31)+SUMIF(华东区域指挥协办逾期!$C$3:$C$10,B8,华东区域指挥协办逾期!$R$3:$R$10))/10000 -> 1037.6551 | D8: =(SUMIF([1]华东区域指挥部主办逾期!$C$3:$C$30,B8,[1]华东区域指挥部主办逾期!$R$3:$R$30)+SUMIF([1]华东区域指挥协办逾期!$C$3:$C$10,B8,[1]华东区域指挥协办逾期!$R$3:$R$10))/10000 -> 0 | E8: =SUM(C8:D8) -> 1037.6551 | F8: =_xlfn.RANK.EQ(E8,$E$2:$E$40) -> 6
A9: 系统外 | B9: 上海地铁盾构设备工程有限公司 | C9: =(SUMIF(华东区域指挥部主办逾期!$C$3:$C$31,B9,华东区域指挥部主办逾期!$R$3:$R$31)+SUMIF(华东区域指挥协办逾期!$C$3:$C$10,B9,华东区域指挥协办逾期!$R$3:$R$10))/10000 -> 442.9554 | D9: =(SUMIF([1]华东区域指挥部主办逾期!$C$3:$C$30,B9,[1]华东区域指挥部主办逾期!$R$3:$R$30)+SUMIF([1]华东区域指挥协办逾期!$C$3:$C$10,B9,[1]华东区域指挥协办逾期!$R$3:$R$10))/10000 -> 543.1155 | E9: =SUM(C9:D9) -> 986.0709 | F9: =_xlfn.RANK.EQ(E9,$E$2:$E$40) -> 7
A10: 系统内 | B10: 中铁十一局集团第一工程有限公司 | C10: =(SUMIF(华东区域指挥部主办逾期!$C$3:$C$31,B10,华东区域指挥部主办逾期!$R$3:$R$31)+SUMIF(华东区域指挥协办逾期!$C$3:$C$10,B10,华东区域指挥协办逾期!$R$3:$R$10))/10000 -> 0 | D10: =(SUMIF([1]华东区域指挥部主办逾期!$C$3:$C$30,B10,[1]华东区域指挥部主办逾期!$R$3:$R$30)+SUMIF([1]华东区域指挥协办逾期!$C$3:$C$10,B10,[1]华东区域指挥协办逾期!$R$3:$R$10))/10000 -> 858.9978 | E10: =SUM(C10:D10) -> 858.9978 | F10: =_xlfn.RANK.EQ(E10,$E$2:$E$40) -> 9
A11: 系统内 | B11: 中铁十九局集团华东工程有限公司 | C11: =(SUMIF(华东区域指挥部主办逾期!$C$3:$C$31,B11,华东区域指挥部主办逾期!$R$3:$R$31)+SUMIF(华东区域指挥协办逾期!$C$3:$C$10,B11,华东区域指挥协办逾期!$R$3:$R$10))/10000 -> 25.56 | D11: =(SUMIF([1]华东区域指挥部主办逾期!$C$3:$C$30,B11,[1]华东区域指挥部主办逾期!$R$3:$R$30)+SUMIF([1]华东区域指挥协办逾期!$C$3:$C$10,B11,[1]华东区域指挥协办逾期!$R$3:$R$10))/10000 -> 710.76 | E11: =SUM(C11:D11) -> 736.32 | F11: =_xlfn.RANK.EQ(E11,$E$2:$E$40) -> 10
