Workbook

Sheet 新签
A1: 序号 | B1: 产品线类型 | C1: 项目名称 | D1: 合同编号 | E1: 客户名称 | F1: 客户类别 | G1: 产品名称 | H1: 行业 | I1: 三新类别 | J1: 风险等级 | K1: 产品数量 | L1: 合同金额 | M1: 产品名称和数量 | N1: 合同签订日期 | O1: 生产工号 | P1: 承揽主办方 | Q1: 承揽协办方 | R1: 执行协办方2 | S1: 执行主办方指标分割比例 | T1: 执行协办方1指标分割比例 | U1: 执行协办方2指标分割比例 | V1: 执行主办方指标分割金额 | W1: 执行协办方1指标分割金额 | X1: 执行协办方2指标分割金额 | Y1: 归属华东金额 | Z1: 部门业绩分配
Z2: 责任人 | AA2: 比例 | AB2: 金额 | AC2: 责任人 | AD2: 比例 | AE2: 金额 | AF2: 责任人 | AG2: 比例 | AH2: 金额
A3: 1 | B3: 特装 | C3: 十一局四公司温福铁路搅拌站采购合同 | D3: C2000010001100004011002025019 | E3: 中铁十一局集团第四工程有限公司 | F3: 系统内 | L3: 3500000 | N3: 46038 | P3: 华中区域 | Q3: 华东区域 | S3: 0.7 | T3: 0.3 | V3: =L3*S3 -> 2450000 | W3: =L3*T3 -> 1050000 | Y3: 1050000 | Z3: 袁志凌 | AA3: 1 | AB3: =Y3*AA3 -> 1050000
A4: 2 | B4: 掘进机 | C4: 中铁二十四局DZ609维修改造合同 | D4: GDGSDG-QT-2025-001（DZ609） | E4: 中铁二十四局集团有限公司 | F4: 系统内 | L4: 7325000 | N4: 46038 | P4: 华东区域 | S4: 1 | V4: =L4*S4 -> 7325000 | Y4: 7325000 | Z4: 赵宇瑄 | AA4: 0.7 | AB4: =Y4*AA4 -> 5127500 | AC4: 穆华清 | AD4: 0.3 | AE4: =Y4*AD4 -> 2197500
A5: 3 | B5: 掘进机 | C5: 中铁二十四局常州地铁5号线DZ213盾构机再制造合同 | D5: GDGSDG-QT-2025-001（DZ213） | E5: 中铁二十四局集团有限公司 | F5: 系统内 | L5: 6495000 | N5: 46038 | P5: 华东区域 | Q5: 华中区域 | S5: 0.7 | T5: 0.3 | V5: =L5*S5 -> 4546500 | W5: =L5*T5 -> 1948500 | Y5: 4546500 | Z5: 赵宇瑄 | AA5: 0.7 | AB5: =Y5*AA5 -> 3182550 | AC5: 穆华清 | AD5: 0.3 | AE5: =Y5*AD5 -> 1363950
A6: 4 | B6: 特装 | C6: 十一局一公司温福铁路凿岩、锚杆台车等采购合同 | D6: 十一局一公司温福铁路凿岩、锚杆台车等采购合同 | E6: 中铁十一局集团第一工程有限公司 | F6: 系统内 | L6: 30560000 | N6: 46038 | P6: 华中区域 | Q6: 华东区域 | S6: 0.7 | T6: 0.3 | V6: =L6*S6 -> 21392000 | W6: =L6*T6 -> 9168000 | Y6: 9168000 | Z6: 杨志胜 | AA6: 1 | AB6: =Y6*AA6 -> 9168000
A7: 5 | B7: 掘进机 | C7: 上海市机械施工集团上海市轨道交通19号线2台ZTE6760采购合同 | D7: 25082075 | E7: 上海市机械施工集团有限公司 | F7: 系统外 | L7: 61600000 | N7: 46038 | P7: 华东区域 | S7: 1 | T7: 0 | V7: =L7*S7 -> 61600000 | Y7: 61600000 | Z7: 赵宇瑄 | AA7: 0.7 | AB7: =Y7*AA7 -> 43120000 | AC7: 穆华清 | AD7: 0.3 | AE7: =Y7*AD7 -> 18480000
A8: 6 | B8: 特装 | C8: 中铁二十四局福建公司温福铁路1批特种装备采购合同 | D8: CR24FJ-SBCG-2026-01、CR24FJ-SBCG-2026-02 | E8: 中铁二十四局集团福建铁路建设有限公司 | F8: 系统内 | L8: 44260000 | N8: 46038 | P8: 华东区域 | S8: 1 | T8: 0 | V8: =L8*S8 -> 44260000 | Y8: 44260000 | Z8: 周斌 | AA8: 0.6 | AB8: =Y8*AA8 -> 26556000 | AC8: 陈浩 | AD8: 0.4 | AE8: =Y8*AD8 -> 17704000
A9: 7 | B9: 特装 | C9: 十一局一公司温福铁路搅拌站采购合同 | D9: 十一局一公司温福铁路搅拌站采购合同 | E9: 中铁十一局集团第一工程有限公司 | F9: 系统内 | L9: 6255000 | N9: 46038 | P9: 华中区域 | Q9: 华东区域 | S9: 0.7 | T9: 0.3 | V9: =L9*S9 -> 4378500 | W9: =L9*T9 -> 1876500 | Y9: 1876500 | Z9: 杨志胜 | AA9: 1 | AB9: =Y9*AA9 -> 1876500
A10: 8 | B10: 特装 | C10: 中铁十九局华东公司宜常高铁项目2台HZS180采购合同 | D10: CRCHI-XS-2026-001 | E10: 中铁十九局集团华东工程有限公司 | F10: 系统内 | L10: 3000000 | N10: 46053 | P10: 华东区域 | Q10: 华中区域 | S10: 0.7 | T10: 0.3 | V10: =L10*S10 -> 2100000 | W10: =L10*T10 -> 900000 | Y10: 2100000 | Z10: 万赛 | AA10: 1 | AB10: =Y10*AA10 -> 2100000
A11: 9 | B11: 掘进机 | C11: 十八局隧道工程扩大杭嘉湖南排连续皮带机设备采购合同 | D11: 11-QT-2026-装备中心-11-001、11-SHB-2026-装备中心-11-002 | E11: 中铁十八局集团隧道工程有限公司 | F11: 系统内 | L11: 18725956 | N11: 46053 | P11: 西南区域 | Q11: 华东区域 | S11: 0.7 | T11: 0.3 | V11: =L11*S11 -> 13108170 | W11: =L11*T11 -> 5617787 | Y11: 5617787 | Z11: 刘新峥 | AA11: 0.6 | AB11: =Y11*AA11 -> 3370672.2 | AC11: 唐作栋 | AD11: 0.4 | AE11: =Y11*AD11 -> 2247114.8
A12: 10 | B12: 掘进机 | C12: 十六局集团杭州轨道15号线DZ151&DZ153维修改造合同 | D12: ZT16J-HZDTSG15-13-DGJWXGZ-02 | E12: 中铁十六局集团有限公司 | F12: 系统内 | L12: 3000000 | N12: 46053 | P12: 华北区域 | Q12: 华东区域 | S12: 0.7 | T12: 0.3 | V12: =L12*S12 -> 2100000 | W12: =L12*T12 -> 900000 | Y12: 900000 | Z12: 唐作栋 | AA12: 0.6 | AB12: =Y12*AA12 -> 540000 | AC12: 刘新峥 | AD12: 0.4 | AE12: =Y12*AD12 -> 360000
A13: 11 | B13: 特装 | C13: 二十局集团长赣铁路湿喷台车设备采购合同 | D13: CR2005-长赣物设-SC-25-007 | E13: 中铁二十局集团第五工程有限公司 | F13: 系统内 | L13: 980000 | N13: 46053 | P13: 西南区域 | Q13: 华东区域 | S13: 0.7 | T13: 0.3 | V13: =L13*S13 -> 686000 | W13: =L13*T13 -> 294000 | Y13: 294000 | Z13: 陈浩 | AA13: 1 | AB13: =Y13*AA13 -> 294000
A14: 14 | B14: 掘进机 | C14: DN5200mm盾构机备品备件材料采购合同 | D14: DN5200mm盾构机备品备件材料采购合同 | E14: 配件 | F14: 系统外 | L14: 1152 | N14: 46053 | P14: 华东区域 | S14: 1 | V14: =L14*S14 -> 1152 | Y14: 1152 | Z14: 赵宇瑄 | AA14: 1 | AB14: =Y14*AA14 -> 1152
A15: 19 | B15: 掘进机 | C15: DN5200mm盾构机备品备件材料采购合同 | D15: DN5200mm盾构机备品备件材料采购合同 | E15: 配件 | F15: 系统外 | L15: 116988 | N15: 46053 | P15: 华东区域 | S15: 1 | V15: =L15*S15 -> 116988 | Y15: 116988 | Z15: 赵宇瑄 | AA15: 1 | AB15: =Y15*AA15 -> 116988
A16: 20 | B16: 掘进机 | C16: 中铁十一局青浦分公司DZ852有偿服务合同 | D16: 中铁十一局青浦分公司DZ852有偿服务合同 | E16: 配件 | F16: 系统内 | L16: 6688 | N16: 46053 | P16: 华东区域 | S16: 1 | V16: =L16*S16 -> 6688 | Y16: 6688 | Z16: 赵宇瑄 | AA16: 1 | AB16: =Y16*AA16 -> 6688
A17: 21 | B17: 掘进机 | C17: 宏润建设集团股份有限公司采购合同 | D17: 宏润建设集团股份有限公司采购合同 | E17: 配件 | F17: 系统外 | L17: 5547 | N17: 46053 | P17: 华东区域 | S17: 1 | V17: =L17*S17 -> 5547 | Y17: 5547 | Z17: 穆华清 | AA17: 1 | AB17: =Y17*AA17 -> 5547
A18: 22 | B18: 掘进机 | C18: 上海通盛山水能源有限责任公司有偿服务合同 | D18: 上海通盛山水能源有限责任公司有偿服务合同 | E18: 配件 | F18: 系统外 | L18: 20000 | N18: 46053 | P18: 华东区域 | S18: 1 | V18: =L18*S18 -> 20000 | Y18: 20000 | Z18: 赵宇瑄 | AA18: 1 | AB18: =Y18*AA18 -> 20000
A19: 23 | B19: 掘进机 | C19: 上海通盛山水能源有限责任公司有偿服务合同 | D19: 上海通盛山水能源有限责任公司有偿服务合同 | E19: 配件 | F19: 系统外 | L19: 5000 | N19: 46053 | P19: 华东区域 | S19: 1 | V19: =L19*S19 -> 5000 | Y19: 5000 | Z19: 赵宇瑄 | AA19: 1 | AB19: =Y19*AA19 -> 5000
A20: 24 | B20: 掘进机 | C20: 中铁十一局甬舟铁路项目DZ1396盾构机技术服务合同 | D20: T11-2024-JSFW-YZTL3GQ-001 | E20: 配件 | F20: 系统内 | L20: 40000 | N20: 46053 | P20: 华东区域 | S20: 1 | V20: =L20*S20 -> 40000 | Y20: 40000 | Z20: 万赛 | AA20: 1 | AB20: =Y20*AA20 -> 40000
A21: 25 | B21: 掘进机 | C21: 上海地铁盾构设备工程有限公司年度合同 | D21: D25-137F-S00-065 | E21: 配件 | F21: 系统外 | L21: 920 | N21: 46081 | P21: 华东区域 | S21: 1 | V21: =L21*S21 -> 920 | Y21: 920 | Z21: 赵宇瑄 | AA21: 1 | AB21: =Y21*AA21 -> 920
A22: 26 | B22: 掘进机 | C22: 中铁十二局浙江区域盾构机配件采购（虚拟）合同 | E22: 配件 | F22: 系统内 | L22: 18712 | N22: 46081 | P22: 华东区域 | S22: 1 | V22: =L22*S22 -> 18712 | Y22: 18712 | Z22: 万赛 | AA22: 1 | AB22: =Y22*AA22 -> 18712
A23: 27 | B23: 掘进机 | C23: 中铁十六局城西南排项目配件采购（虚拟）合同 | E23: 配件 | F23: 系统内 | L23: 852 | N23: 46081 | P23: 华东区域 | S23: 1 | V23: =L23*S23 -> 852 | Y23: 852 | Z23: 唐作栋 | AA23: 1 | AB23: =Y23*AA23 -> 852
A24: 28 | B24: 掘进机 | C24: DN5200mm盾构机备品备件材料采购合同 | D24: DN5200mm盾构机备品备件材料采购合同 | E24: 配件 | F24: 系统外 | L24: 3804 | N24: 46081 | P24: 华东区域 | S24: 1 | V24: =L24*S24 -> 3804 | Y24: 3804 | Z24: 赵宇瑄 | AA24: 1 | AB24: =Y24*AA24 -> 3804
A25: 30 | B25: 掘进机 | C25: 上海渠顺贸易有限公司配件合同 | D25: 上海渠顺贸易有限公司配件合同 | E25: 配件 | F25: 系统外 | L25: 7785 | N25: 46081 | P25: 华东区域 | S25: 1 | V25: =L25*S25 -> 7785 | Y25: 7785 | Z25: 赵宇瑄 | AA25: 1 | AB25: =Y25*AA25 -> 7785
A26: 31 | B26: 掘进机 | C26: 中铁十六局集团杭州至德清市域铁路土建施工I标段三工区项目有偿技术服务合同 | D26: ZT16J-HDSYTL-DGJSFW-01 | E26: 配件 | F26: 系统内 | L26: 92400 | N26: 46081 | P26: 华东区域 | S26: 1 | V26: =L26*S26 -> 92400 | Y26: 92400 | Z26: 唐作栋 | AA26: 1 | AB26: =Y26*AA26 -> 92400
A27: 32 | B27: 掘进机 | C27: DN5200mm盾构机备品备件材料采购合同 | D27: DN5200mm盾构机备品备件材料采购合同 | E27: 配件 | F27: 系统外 | L27: 4860 | N27: 46081 | P27: 华东区域 | S27: 1 | V27: =L27*S27 -> 4860 | Y27: 4860 | Z27: 赵宇瑄 | AA27: 1 | AB27: =Y27*AA27 -> 4860
A28: 33 | B28: 掘进机 | C28: 上海城建市政工程（集团）有限公司备品备件采购合同 | D28: CRCHI-PJCG-1204 | E28: 配件 | F28: 系统外 | L28: 115331 | N28: 46081 | P28: 华东区域 | S28: 1 | V28: =L28*S28 -> 115331 | Y28: 115331 | Z28: 赵宇瑄 | AA28: 1 | AB28: =Y28*AA28 -> 115331
A29: 34 | B29: 特装 | C29: 中国铁建港航局集团温福高铁3台HZS180K采购合同 | D29: GH-温福高铁-SBCG-20251217-001 | E29: 中国铁建港航局集团有限公司 | F29: 系统内 | L29: 7851000 | M29: 搅拌站-3 | N29: 46109 | P29: 华东区域 | S29: 1 | V29: =L29*S29 -> 7851000 | Y29: 7851000 | Z29: 袁志凌 | AA29: 1 | AB29: =Y29*AA29 -> 7851000
A30: 35 | B30: 特装 | C30: 中铁建大桥局五公司长赣铁路项目钻锚注一体机采购合同 | D30: CGJX10-2-JXSBCG-2026-07 | E30: 中铁建大桥局五公司 | F30: 系统内 | L30: 3000000 | M30: 钻锚注一体机-1 | N30: 46109 | P30: 西南区域 | Q30: 华东区域 | R30: 华北区域 | S30: 0.5 | T30: 0.3 | U30: 0.2 | V30: =L30*S30 -> 1500000 | W30: =L30*T30 -> 900000 | X30: =L30*U30 -> 600000 | Y30: 900000 | Z30: 杨志胜 | AA30: 1 | AB30: =Y30*AA30 -> 900000
A31: 36 | B31: 特装 | C31: 中铁十四局隧道公司长赣铁路隧道施工大机设备采购合同补充协议 | D31: ZTSSJ-SDGS-SB-2025-1211-补1 | E31: 中铁十四局集团隧道工程有限公司 | F31: 系统内 | L31: 11180000 | M31: 特种装备 | N31: 46109 | P31: 中原区域 | Q31: 华东区域 | S31: 0.6 | T31: 0.4 | V31: =L31*S31 -> 6708000 | W31: =L31*T31 -> 4472000 | Y31: 4472000 | Z31: 周斌 | AA31: 1 | AB31: =Y31*AA31 -> 4472000
A32: 37 | B32: 掘进机 | C32: 上海市基础工程集团有限公司DZ851维修改造合同 | D32: SFEG(2025)五工-F029 | E32: 上海市基础工程集团有限公司 | F32: 系统外 | L32: 19280000 | M32: 盾构机-1 | N32: 46109 | P32: 华东区域 | Q32: 华中区域 | S32: 0.7 | T32: 0.3 | V32: =L32*S32 -> 13496000 | W32: =L32*T32 -> 5784000 | Y32: 13496000 | Z32: 赵宇瑄 | AA32: 0.7 | AB32: =Y32*AA32 -> 9447200 | AC32: 穆华清 | AD32: 0.3 | AE32: =Y32*AD32 -> 4048800
A33: 38 | B33: 掘进机 | C33: 上海市基础工程集团有限公司DZ851主驱动维修合同 | D33: SFEG(2025)五工-F027 | E33: 上海市基础工程集团有限公司 | F33: 系统外 | L33: 1300000 | M33: 盾构机-1 | N33: 46109 | P33: 华东区域 | S33: 1 | V33: =L33*S33 -> 1300000 | Y33: 1300000 | Z33: 赵宇瑄 | AA33: 0.7 | AB33: =Y33*AA33 -> 910000 | AC33: 穆华清 | AD33: 0.3 | AE33: =Y33*AD33 -> 390000
A34: 39 | B34: 特装 | C34: 中铁十九局华东公司宜涪铁路1台MT141&3台SCD133A采购合同 | D34: CRCHI-XS-2025-055、CRCHI-XS-2025-056 | E34: 中铁十九局集团华东工程有限公司 | F34: 系统内 | L34: 9800000 | M34: 特种装备 | N34: 46109 | P34: 华东区域 | Q34: 华中区域 | S34: 0.7 | T34: 0.3 | V34: =L34*S34 -> 6860000 | W34: =L34*T34 -> 2940000 | Y34: 6860000 | Z34: 万赛 | AA34: 1 | AB34: =Y34*AA34 -> 6860000
A35: 40 | B35: 掘进机 | C35: 中铁十一局集团有限公司上海青浦分公司设备配件购销合同 | D35: 2025-SHSFQX16B-PJCG-022 | E35: 配件 | F35: 系统内 | L35: 54597.4 | M35: 配件 | N35: 46109 | P35: 华东区域 | S35: 1 | V35: =L35*S35 -> 54597.4 | Y35: 54597.4 | Z35: 赵宇瑄 | AA35: 1 | AB35: =Y35*AA35 -> 54597.4
A36: 41 | B36: 掘进机 | C36: 上海渠顺贸易有限公司配件合同 | D36: 上海渠顺贸易有限公司配件合同 | E36: 配件 | F36: 系统外 | L36: 25398 | M36: 配件 | N36: 46109 | P36: 华东区域 | S36: 1 | V36: =L36*S36 -> 25398 | Y36: 25398 | Z36: 赵宇瑄 | AA36: 1 | AB36: =Y36*AA36 -> 25398
A37: 42 | B37: 特装 | C37: 国能e购商城内蒙古公司2024年度集团级铁建重工掘锚机配件单一来源铺货采购协议 | D37: CRCHI-KSPJ-2025-021301 | E37: 配件 | F37: 系统外 | L37: 430.2 | M37: 配件 | N37: 46109 | P37: 华东区域 | S37: 1 | V37: =L37*S37 -> 430.2 | Y37: 430.2 | Z37: 赵宇瑄 | AA37: 1 | AB37: =Y37*AA37 -> 430.2
A38: 43 | B38: 特装 | C38: 十一局一公司温福铁路凿岩、锚杆台车等采购合同（合并重签） | D38: C2000010001100001011002026008（合并2） | E38: 中铁十一局集团第一工程有限公司 | F38: 系统内 | L38: -2100000 | M38: 特种装备 | N38: 46109 | P38: 华中区域 | Q38: 华东区域 | S38: 0.7 | T38: 0.3 | V38: =L38*S38 -> -1470000 | W38: =L38*T38 -> -630000 | Y38: -630000 | Z38: 杨志胜 | AA38: 1 | AB38: =Y38*AA38 -> -630000
A39: 44 | B39: 掘进机 | C39: 甬舟公路复线二期 | D39: CRCC1417-DGJZZZ-DZ666-2026-01 | E39: 中铁十四局集团装备有限公司 | F39: 系统内 | L39: 125500000 | M39: 盾构机-1 | N39: 46109 | P39: 华中区域 | Q39: 华东区域 | S39: 0.7 | T39: 0.3 | V39: =L39*S39 -> 87850000 | W39: =L39*T39 -> 37650000 | Y39: 37650000 | Z39: 沈腾飞 | AA39: 1 | AB39: =Y39*AA39 -> 37650000
A40: 45 | B40: 特装 | C40: 中铁十一局一公司温福铁路凿岩台车、拱架安装台车、湿喷机械手采购合同(第二批) | D40: C2000010001100001011002026013 | E40: 中铁十一局集团第一工程有限公司 | F40: 系统内 | L40: 20640000 | M40: 特装装备 | N40: 46112 | P40: 华中区域 | Q40: 华东区域 | S40: 0.7 | T40: 0.3 | V40: =L40*S40 -> 14448000 | W40: =L40*T40 -> 6192000 | Y40: 6192000 | Z40: 杨志胜 | AA40: 1 | AB40: =Y40*AA40 -> 6192000
...

Sheet 收入
A1: 2026年华东区域指挥部收入明细表
A2: 序号 | B2: 确认收入月日 | C2: 客户名称 | D2: 项目名称 | E2: 合同编号 | F2: 销售收入金额（不含税） | G2: 产品名称和数量 | H2: 执行主办方 | I2: 执行协办方 | J2: 执行协办方2 | K2: 执行主办方指标分割比例 | L2: 执行协办方1指标分割比例 | M2: 执行协办方2指标分割比例 | N2: 执行主办方指标分割金额 | O2: 执行协办方1指标分割金额 | P2: 执行协办方2指标分割金额 | Q2: 归属华东金额 | R2: 部门业绩分配
R3: 责任人 | S3: 比例 | T3: 金额 | U3: 责任人 | V3: 比例 | W3: 金额
A4: 1 | B4: 46038 | C4: 上海地铁盾构设备工程有限公司 | D4: 上海地铁盾构设备工程公司上海市轨道交通崇明线一期工程2台盾构机租赁合同 | E4: D24-022F-T00-005 | F4: 1142808.9 | H4: 华东区域 | K4: 1 | N4: =F4*K4 -> 1142808.9 | Q4: 1142808.9 | R4: 赵宇瑄 | S4: 1 | T4: =Q4*S4 -> 1142808.9
A5: 2 | B5: 46038 | C5: 上海地铁盾构设备工程有限公司 | D5: 上海地铁盾构设备工程公司上海市轨道交通崇明线一期工程2台盾构机租赁合同 | E5: D24-022F-T00-005 | F5: 1258634.1 | H5: 华东区域 | K5: 1 | N5: =F5*K5 -> 1258634.1 | Q5: 1258634.1 | R5: 赵宇瑄 | S5: 1 | T5: =Q5*S5 -> 1258634.1
A6: 3 | B6: 46038 | C6: 中铁二十四局集团有限公司 | D6: 中铁二十四局上海东站项目2台ZTE6830租赁合同 | E6: SHDZ-2025-DZ-001 | F6: 1183070.1 | H6: 华东区域 | K6: 1 | N6: =F6*K6 -> 1183070.1 | Q6: 1183070.1 | R6: 赵宇瑄 | S6: 1 | T6: =Q6*S6 -> 1183070.1
A7: 4 | B7: 46038 | C7: 中铁二十四局集团有限公司 | D7: 中铁二十四局上海东站项目2台ZTE6830租赁合同 | E7: SHDZ-2025-DZ-001 | F7: 793871.9 | H7: 华东区域 | K7: 1 | N7: =F7*K7 -> 793871.9 | Q7: 793871.9 | R7: 赵宇瑄 | S7: 1 | T7: =Q7*S7 -> 793871.9
A8: 5 | B8: 46038 | C8: 上海地铁盾构设备工程有限公司 | D8: 上海地铁盾构设备工程有限公司年度合同 | E8: 上海地铁盾构设备工程有限公司年度合同 | F8: 61065.5 | H8: 华东区域 | K8: 1 | N8: =F8*K8 -> 61065.5 | Q8: 61065.5 | R8: 赵宇瑄 | S8: 1 | T8: =Q8*S8 -> 61065.5
A9: 6 | B9: 46038 | C9: 中铁二十局集团有限公司 | D9: 二十局集团长赣高铁湿喷台车购销合同 | E9: ZT2003CGWS20250004 | F9: 867256.64 | H9: 华东区域 | I9: 西南区域 | K9: 0.7 | L9: 0.3 | N9: =F9*K9 -> 607079.65 | O9: =F9*L9 -> 260176.99 | Q9: 607079.65 | R9: 陈浩 | S9: 1 | T9: =Q9*S9 -> 607079.65
A10: 7 | B10: 46038 | C10: 中铁二十局集团有限公司 | D10: 二十局集团长赣高铁湿喷台车购销合同 | E10: ZT2003CGWS20250004 | F10: 867256.64 | H10: 华东区域 | I10: 西南区域 | K10: 0.7 | L10: 0.3 | N10: =F10*K10 -> 607079.65 | O10: =F10*L10 -> 260176.99 | Q10: 607079.65 | R10: 陈浩 | S10: 1 | T10: =Q10*S10 -> 607079.65
A11: 8 | B11: 46038 | C11: 浙江物产工程技术服务有限公司 | D11: 浙江物产工程技术服务有限公司DZ620维修、整机联调合同 | E11: WCGF-DZ620-04-WXLT | F11: 2211504.4 | H11: 华东区域 | I11: 华南区域 | K11: 0.7 | L11: 0.3 | N11: =F11*K11 -> 1548053.1 | O11: =F11*L11 -> 663451.33 | Q11: 1548053.1 | R11: 唐作栋 | S11: 0.6 | T11: =Q11*S11 -> 928831.86 | U11: 刘新峥 | V11: 0.4 | W11: =Q11*V11 -> 619221.24
A12: 9 | B12: 46038 | C12: 上海市基础工程集团有限公司上海机场联络线 | D12: 上海市基础工程集团有限公司泥水平衡隧道掘进机销售合同 | E12: SFEG（2024）设材-C004【SFEG（2023）五工092-D001（0613-224023070012）】 | F12: 481853.54 | H12: 华东区域 | K12: 1 | N12: =F12*K12 -> 481853.54 | Q12: 481853.54 | R12: 赵宇瑄 | S12: 1 | T12: =Q12*S12 -> 481853.54
A13: 10 | B13: 46038 | C13: 中铁十一局集团有限公司城市建设分公司甬舟铁路YZSG-3工区一分部项目经理部 | D13: 中铁十一局甬舟铁路项目DZ1396盾构机技术服务合同 | E13: T11-2024-JSFW-YZTL3GQ-001 | F13: 37735.85 | H13: 华东区域 | K13: 1 | N13: =F13*K13 -> 37735.85 | Q13: 37735.85 | R13: 万赛 | S13: 1 | T13: =Q13*S13 -> 37735.85
A14: 11 | B14: 46038 | C14: 浙江物产工程技术服务有限公司 | D14: 浙江物产工程技术服务有限公司长春地铁9号线2台ZTE7150租赁合同 | E14: CRCHI-GZ-2023-013 | F14: 469115.04 | H14: 东北区域 | I14: 华东区域 | K14: 0.7 | L14: 0.3 | N14: =F14*K14 -> 328380.53 | O14: =F14*L14 -> 140734.51 | Q14: 140734.51 | R14: 唐作栋 | S14: 0.6 | T14: =Q14*S14 -> 84440.707 | U14: 刘新峥 | V14: 0.4 | W14: =Q14*V14 -> 56293.805
A15: 12 | B15: 46038 | C15: 上海市基础工程集团有限公司上海机场联络线 | D15: 上海市基础工程集团有限公司泥水平衡隧道掘进机销售合同 | E15: SFEG（2024）设材-C004【SFEG（2023）五工092-D001（0613-224023070012）】 | F15: 481853.54 | H15: 华东区域 | K15: 1 | N15: =F15*K15 -> 481853.54 | Q15: 481853.54 | R15: 赵宇瑄 | S15: 1 | T15: =Q15*S15 -> 481853.54
A16: 13 | B16: 46038 | C16: 中铁十六局集团有限公司 | D16: 关于“中铁十六局集团上海嘉闵线土压平衡盾构机租赁合同”的审批申请 | E16: CRCC-16J-JMWZ-2024-008 | F16: 2581486.7 | H16: 华东区域 | I16: 华北区域 | K16: 0.7 | L16: 0.3 | N16: =F16*K16 -> 1807040.7 | O16: =F16*L16 -> 774446.02 | Q16: 1807040.7 | R16: 赵宇瑄 | S16: 1 | T16: =Q16*S16 -> 1807040.7
A17: 14 | B17: 46038 | C17: 中铁十六局集团有限公司 | D17: 关于“中铁十六局集团上海嘉闵线土压平衡盾构机租赁合同”的审批申请 | E17: CRCC-16J-JMWZ-2024-008 | F17: 2404672.6 | H17: 华东区域 | I17: 华北区域 | K17: 0.7 | L17: 0.3 | N17: =F17*K17 -> 1683270.8 | O17: =F17*L17 -> 721401.77 | Q17: 1683270.8 | R17: 赵宇瑄 | S17: 1 | T17: =Q17*S17 -> 1683270.8
A18: 15 | B18: 46038 | C18: 中铁十一局集团有限公司城市建设分公司甬舟铁路YZSG-3工区一分部项目经理部 | D18: 11局甬舟铁路项目DZ1396盾构机配件第八批采购合同 | E18: T11-2025-PJ-YZTL3GQ-087 | F18: 950001.74 | H18: 华东区域 | K18: 1 | N18: =F18*K18 -> 950001.74 | Q18: 950001.74 | R18: 万赛 | S18: 1 | T18: =Q18*S18 -> 950001.74
A19: 16 | B19: 46053 | C19: 中铁十六局集团有限公司 | D19: 关于“中铁十六局集团上海嘉闵线土压平衡盾构机租赁合同”的审批申请 | E19: CRCC-16J-JMWZ-2024-008 | F19: 2457716.8 | H19: 华东区域 | I19: 华北区域 | K19: 0.7 | L19: 0.3 | N19: =F19*K19 -> 1720401.8 | O19: =F19*L19 -> 737315.04 | Q19: 1720401.8 | R19: 赵宇瑄 | S19: 1 | T19: =Q19*S19 -> 1720401.8 | Y19: =SUM(T19:T20,T24:T27) -> 5023936.1
A20: 17 | B20: 46053 | C20: 中铁十六局集团有限公司 | D20: 关于“中铁十六局集团上海嘉闵线土压平衡盾构机租赁合同”的审批申请 | E20: CRCC-16J-JMWZ-2024-008 | F20: 990159.29 | H20: 华东区域 | I20: 华北区域 | K20: 0.7 | L20: 0.3 | N20: =F20*K20 -> 693111.5 | O20: =F20*L20 -> 297047.79 | Q20: 693111.5 | R20: 赵宇瑄 | S20: 1 | T20: =Q20*S20 -> 693111.5
A21: 18 | B21: 46053 | C21: 中铁十一局集团城市轨道工程有限公司 | D21: 中铁十一局杭州城轨交通SG18-8标2台ZTE7150租赁合同 | E21: CRCHI-GZ-2025-002（客户编号T11CG-HZ1808-2025-ZL-11） | F21: 1153008.9 | H21: 华东区域 | I21: 华中区域 | K21: 0.7 | L21: 0.3 | N21: =F21*K21 -> 807106.19 | O21: =F21*L21 -> 345902.66 | Q21: 807106.19 | R21: 唐作栋 | S21: 0.6 | T21: =Q21*S21 -> 484263.72 | U21: 刘新峥 | V21: 0.4 | W21: =Q21*V21 -> 322842.48
A22: 19 | B22: 46053 | C22: 中铁十一局集团城市轨道工程有限公司 | D22: 中铁十一局杭州城轨交通SG18-8标2台ZTE7150租赁合同 | E22: CRCHI-GZ-2025-002（客户编号T11CG-HZ1808-2025-ZL-11） | F22: 1944026.6 | H22: 华东区域 | I22: 华中区域 | K22: 0.7 | L22: 0.3 | N22: =F22*K22 -> 1360818.6 | O22: =F22*L22 -> 583207.96 | Q22: 1360818.6 | R22: 唐作栋 | S22: 0.6 | T22: =Q22*S22 -> 816491.15 | U22: 刘新峥 | V22: 0.4 | W22: =Q22*V22 -> 544327.43 | Y22: =SUM(T21:T23,T28) -> 1930375.1 | Z22: =SUM(W21:W22,W28) -> 1228803.5
A23: 20 | B23: 46053 | C23: 中铁十六局集团有限公司杭州至德清市域铁路土建施工I标段三工区项目部 | D23: 中铁十六局集团杭州至德清市域铁路土建施工I标段三工区项目有偿技术服务合同 | E23: ZT16J-HDSYTL-DGJSFW-01 | F23: 87169.81 | H23: 华东区域 | K23: 1 | N23: =F23*K23 -> 87169.81 | Q23: 87169.81 | R23: 唐作栋 | S23: 1 | T23: =Q23*S23 -> 87169.81
A24: 21 | B24: 46053 | C24: 中铁二十四局集团有限公司 | D24: 中铁二十四局上海东站项目2台ZTE6830租赁合同 | E24: SHDZ-2025-DZ-001 | F24: 1409925.7 | H24: 华东区域 | K24: 1 | N24: =F24*K24 -> 1409925.7 | Q24: 1409925.7 | R24: 赵宇瑄 | S24: 1 | T24: =Q24*S24 -> 1409925.7
A25: 22 | B25: 46053 | C25: 中铁二十四局集团有限公司 | D25: 中铁二十四局上海东站项目2台ZTE6830租赁合同 | E25: SHDZ-2025-DZ-001 | F25: 879275.91 | H25: 华东区域 | K25: 1 | N25: =F25*K25 -> 879275.91 | Q25: 879275.91 | R25: 赵宇瑄 | S25: 1 | T25: =Q25*S25 -> 879275.91
A26: 23 | B26: 46053 | C26: 上海市基础工程集团有限公司上海机场联络线 | D26: 上海市基础工程集团有限公司机场联络线DZ851/852第2批备品备件购销合同 | E26: SFEG（2022）五工088-C001 | F26: 316312.39 | H26: 华东区域 | K26: 1 | N26: =F26*K26 -> 316312.39 | Q26: 316312.39 | R26: 赵宇瑄 | S26: 1 | T26: =Q26*S26 -> 316312.39
A27: 24 | B27: 46053 | C27: 宏润建设集团股份有限公司 | D27: 宏润建设集团股份有限公司采购合同 | E27: 宏润建设集团股份有限公司采购合同 | F27: 4908.85 | H27: 华东区域 | K27: 1 | N27: =F27*K27 -> 4908.85 | Q27: 4908.85 | R27: 赵宇瑄 | S27: 1 | T27: =Q27*S27 -> 4908.85
A28: 25 | B28: 46053 | C28: 中铁十一局集团有限公司 | D28: 中铁十一局杭州市城市轨道交通18号线1台ZTE7150租赁合同 | E28: T11CG-HZ18HX13-2025-ZL-001 | F28: 1291548.7 | H28: 华东区域 | I28: 华中区域 | K28: 0.7 | L28: 0.3 | N28: =F28*K28 -> 904084.07 | O28: =F28*L28 -> 387464.6 | Q28: 904084.07 | R28: 唐作栋 | S28: 0.6 | T28: =Q28*S28 -> 542450.44 | U28: 刘新峥 | V28: 0.4 | W28: =Q28*V28 -> 361633.63
A29: 26 | B29: 46053 | C29: 上海基础赊销物料发货合同 | D29: 上海基础赊销物料发货合同 | E29: PJXS20220806 | F29: 707.96 | H29: 华东区域 | K29: 1 | N29: =F29*K29 -> 707.96 | Q29: 707.96 | R29: 赵宇瑄 | S29: 1 | T29: =Q29*S29 -> 707.96
A30: 27 | B30: 46053 | C30: 中铁十五局集团有限公司杭州机场高铁站前4标项目经理部盾尾油脂采购合同 | D30: 中铁十五局集团有限公司杭州机场高铁站前4标项目经理部盾尾油脂采购合同 | F30: 190265.49 | H30: 华东区域 | K30: 1 | N30: =F30*K30 -> 190265.49 | Q30: 190265.49 | R30: 唐作栋 | S30: 1 | T30: =Q30*S30 -> 190265.49
A31: 28 | B31: 46053 | C31: 上海通盛山水能源有限责任公司有偿服务合同 | D31: 上海通盛山水能源有限责任公司有偿服务合同 | E31: 上海通盛山水能源有限责任公司有偿服务合同 | F31: 25896.23 | H31: 华东区域 | K31: 1 | N31: =F31*K31 -> 25896.23 | Q31: 25896.23 | R31: 赵宇瑄 | S31: 1 | T31: =Q31*S31 -> 25896.23
A32: 29 | B32: 46053 | C32: 上海基础减速机销售合同 | D32: 上海基础减速机销售合同 | E32: CRCHI-2024-PJXS1 | F32: 7079.65 | H32: 华东区域 | K32: 1 | N32: =F32*K32 -> 7079.65 | Q32: 7079.65 | R32: 赵宇瑄 | S32: 1 | T32: =Q32*S32 -> 7079.65
A33: 30 | B33: 46053 | C33: 上海渠顺贸易有限公司配件合同 | D33: 上海渠顺贸易有限公司配件合同 | E33: 上海渠顺贸易有限公司配件合同 | F33: 4130.97 | H33: 华东区域 | K33: 1 | N33: =F33*K33 -> 4130.97 | Q33: 4130.97 | R33: 赵宇瑄 | S33: 1 | T33: =Q33*S33 -> 4130.97
A34: 31 | B34: 46053 | C34: 上海渠顺贸易有限公司配件合同 | D34: 上海渠顺贸易有限公司配件合同 | E34: 上海渠顺贸易有限公司配件合同 | F34: 6889.38 | H34: 华东区域 | K34: 1 | N34: =F34*K34 -> 6889.38 | Q34: 6889.38 | R34: 赵宇瑄 | S34: 1 | T34: =Q34*S34 -> 6889.38
A35: 32 | B35: 46053 | C35: 中铁十一局青浦分公司DZ852有偿服务合同 | D35: 中铁十一局青浦分公司DZ852有偿服务合同 | E35: 中铁十一局青浦分公司DZ852有偿服务合同 | F35: 6309.43 | H35: 华东区域 | K35: 1 | N35: =F35*K35 -> 6309.43 | Q35: 6309.43 | R35: 赵宇瑄 | S35: 1 | T35: =Q35*S35 -> 6309.43
A36: 33 | B36: 46053 | C36: 上海基础赊销物料发货合同 | D36: 上海基础赊销物料发货合同 | E36: PJXS20220806 | F36: 2727.43 | H36: 华东区域 | K36: 1 | N36: =F36*K36 -> 2727.43 | Q36: 2727.43 | R36: 赵宇瑄 | S36: 1 | T36: =Q36*S36 -> 2727.43
A37: 34 | B37: 46053 | C37: 上海基础赊销物料发货合同 | D37: 上海基础赊销物料发货合同 | E37: PJXS20220806 | F37: 4424.78 | H37: 华东区域 | K37: 1 | N37: =F37*K37 -> 4424.78 | Q37: 4424.78 | R37: 赵宇瑄 | S37: 1 | T37: =Q37*S37 -> 4424.78
A38: 35 | B38: 46053 | C38: 中铁十五局集团有限公司杭州机场高铁站前4标项目经理部盾尾油脂采购合同 | D38: 中铁十五局集团有限公司杭州机场高铁站前4标项目经理部盾尾油脂采购合同 | F38: 154867.26 | H38: 华东区域 | K38: 1 | N38: =F38*K38 -> 154867.26 | Q38: 154867.26 | R38: 唐作栋 | S38: 1 | T38: =Q38*S38 -> 154867.26
A39: 36 | B39: 46053 | C39: 上海通盛山水能源有限责任公司有偿服务合同 | D39: 上海通盛山水能源有限责任公司有偿服务合同 | E39: 上海通盛山水能源有限责任公司有偿服务合同 | F39: 16132.08 | H39: 华东区域 | K39: 1 | N39: =F39*K39 -> 16132.08 | Q39: 16132.08 | R39: 赵宇瑄 | S39: 1 | T39: =Q39*S39 -> 16132.08
A40: 37 | B40: 46081 | C40: 中铁十四局集团第四工程有限公司温玉项目390元销售配件 | D40: 中铁十四局集团第四工程有限公司温玉项目390元销售配件 | F40: 345.13 | H40: 华东区域 | K40: 1 | N40: =F40*K40 -> 345.13 | Q40: 345.13 | R40: 沈腾飞 | S40: 1 | T40: =Q40*S40 -> 345.13
...

Sheet Sheet1
A3: 确认收入月日 | B3: 求和项:归属华东金额
A4: 2025-01-13 | B4: 2218755.7
A5: 2025-01-15 | B5: 37735.85
A6: 2025-01-18 | B6: 1150442.5
A7: 2025-01-19 | B7: 0
A8: 45667 | B8: 1284531
A9: 45712 | B9: 2513778.5
A10: 45716 | B10: 16885140
A11: 45723 | B11: 104326.53
A12: 45731 | B12: 165703.54
A13: 45747 | B13: 9409305.3 | C13: =SUM(B8:B13) -> 30362785
A14: (空白)
A15: 总计 | B15: 33769719 | C15: =SUM(B14:B15) -> 33769719
C20: =SUM(B16:B20) -> 0
C25: =SUM(B22:B25) -> 0
C29: =SUM(B26:B29) -> 0
C36: =SUM(B30:B36) -> 0
C40: =SUM(B37:B40) -> 0
C45: =SUM(B41:B45) -> 0
C51: =SUM(B46:B51) -> 0
C52: =SUM(GETPIVOTDATA("归属华东金额",$A$3,"确认收入月日",DATE(2021,10,15)),B4:B7) -> #REF!
C54: =SUM(B53:B54) -> 0

Sheet 回款
A1: 2026年华东区域指挥部回款明细表
A2: 序号 | B2: 回款月日 | C2: 客户名称 | D2: 项目名称 | E2: 是否是逾期回款 | F2: 合同编号 | G2: 回款金额 | H2: 产品名称和数量 | I2: 执行主办方 | J2: 执行协办方 | K2: 执行协办方2 | L2: 执行主办方指标分割比例 | M2: 执行协办方1指标分割比例 | N2: 执行协办方2指标分割比例 | O2: 执行主办方指标分割金额 | P2: 执行协办方1指标分割金额 | Q2: 执行协办方2指标分割金额 | R2: 归属华东金额 | S2: 部门业绩分配
S3: 责任人1 | T3: 比例 | U3: 金额 | V3: 责任人2 | W3: 比例 | X3: 金额 | Y3: 责任人3 | Z3: 比例 | AA3: 金额 | AB3: 责任人4 | AC3: 比例 | AD3: 金额
A4: 1 | B4: 46038 | C4: 中铁十五局集团有限公司 | D4: 中铁十五局彭泽廊道项目散料运输设备购销合同 | F4: CR15G2C-TL（房建、市政）彭泽廊道项目-SBCG-2025-001 | G4: 10000000 | I4: 华东区域 | L4: 1 | O4: =G4*L4 -> 10000000 | R4: 10000000 | S4: 陈浩 | T4: 0.75 | U4: =R4*T4 -> 7500000 | V4: 赵宇瑄 | W4: 0.25 | X4: =R4*W4 -> 2500000
A5: 2 | B5: 46038 | C5: 中铁十五局集团城市轨道交通工程有限公司 | D5: 关于“中铁十五局城市轨道交通工程公司杭州机场高铁搅拌站采购合同”的审批申请 | E5: 是 | F5: CR15-HZJCGT4-JD-202301-(1F) | G5: 453680 | I5: 华东区域 | J5: 华中区域 | L5: 0.6 | M5: 0.4 | O5: =G5*L5 -> 272208 | P5: =G5*M5 -> 181472 | R5: 272208 | S5: 唐作栋 | T5: 1 | U5: =R5*T5 -> 272208
A6: 3 | B6: 46038 | C6: 中铁十九局集团华东工程有限公司 | D6: 中铁十九局华东公司宜涪铁路1批特种装备采购合同 | F6: CRCHI-XS-2025-045、046、047、048 | G6: 2382000 | I6: 华中区域 | J6: 华东区域 | L6: 0.7 | M6: 0.3 | O6: =G6*L6 -> 1667400 | P6: =G6*M6 -> 714600 | R6: 714600 | S6: 万赛 | T6: 1 | U6: =R6*T6 -> 714600
A7: 4 | B7: 46053 | C7: 上海市基础工程集团有限公司上海浦东机场三期项目 | D7: 上海城建市政工程（集团）有限公司泰和污水处理厂扩建工程1台ZTJ13000租赁合同 | F7: CRCHI-GZ-2023-001、2024-ZLPS-000088 | G7: 4000000 | I7: 华东区域 | L7: 1 | O7: =G7*L7 -> 4000000 | R7: 4000000 | S7: 赵宇瑄 | T7: 1 | U7: =R7*T7 -> 4000000
A8: 5 | B8: 46053 | C8: 上海市基础工程集团有限公司桃浦污水处理厂初期雨水调蓄工程TP1.2标 | D8: DN5200盾构机备品备件材料采购 | F8: SFEG(2024)二工154-C009 | G8: 184968 | I8: 华东区域 | L8: 1 | O8: =G8*L8 -> 184968 | R8: 184968 | S8: 赵宇瑄 | T8: 1 | U8: =R8*T8 -> 184968
A9: 6 | B9: 46053 | C9: 中铁十四局集团有限公司 | D9: 关于“中铁十四局萧山机场铁路搅拌站采购合同”的审批申请 | F9: SBCGHT-HZXSJC-00008、ZZCLCGHT-HZXSJC-00002 | G9: 78800 | I9: 华东区域 | J9: 华北区域 | L9: 0.7 | M9: 0.3 | O9: =G9*L9 -> 55160 | P9: =G9*M9 -> 23640 | R9: 55160 | S9: 唐作栋 | T9: 0.6 | U9: =R9*T9 -> 33096 | V9: 刘新峥 | W9: 0.4 | X9: =R9*W9 -> 22064
A10: 7 | B10: 46053 | C10: 中铁二十二局集团有限公司轨道交通工程分公司台州市域铁路S2线土建施工2标段项目部 | D10: 二十二局轨道交通台州S2线盾构机维修改造合同 | F10: CR22GD-GD-TZSYTL-SBWX-2025-002 | G10: 5355000 | I10: 华东区域 | J10: 华北区域 | L10: 0.7 | M10: 0.3 | O10: =G10*L10 -> 3748500 | P10: =G10*M10 -> 1606500 | R10: 3748500 | S10: 沈腾飞 | T10: 1 | U10: =R10*T10 -> 3748500
A11: 8 | B11: 46053 | C11: 浙江物产工程技术服务有限公司 | D11: 浙江物产工程技术服务有限公司深圳地铁15号线DZ619/621维修改造合同 | F11: WCGF-DZ619/DZ621-04-WXLTGZ | G11: 2000000 | I11: 华东区域 | J11: 华南区域 | L11: 0.7 | M11: 0.3 | O11: =G11*L11 -> 1400000 | P11: =G11*M11 -> 600000 | R11: 1400000 | S11: 唐作栋 | T11: 0.6 | U11: =R11*T11 -> 840000 | V11: 刘新峥 | W11: 0.4 | X11: =R11*W11 -> 560000
A12: 9 | B12: 46053 | C12: 中铁十八局集团隧道工程有限公司 | D12: 十八局隧道镜岭水库皮带机采购合同 | F12: 11-SHB-2025-隧道公司-11-010 | G12: 1000000 | I12: 华东区域 | J12: 西南区域 | L12: 0.7 | M12: 0.3 | O12: =G12*L12 -> 700000 | P12: =G12*M12 -> 300000 | R12: 700000 | S12: 刘新峥 | T12: 0.6 | U12: =R12*T12 -> 420000 | V12: 唐作栋 | W12: 0.4 | X12: =R12*W12 -> 280000
A13: 10 | B13: 46053 | C13: 上海市机械施工集团有限公司 | D13: 上海市机械施工集团上海市轨道交通19号线2台ZTE6760采购合同 | F13: 25082075 | G13: 6160000 | I13: 华东区域 | L13: 1 | O13: =G13*L13 -> 6160000 | R13: 6160000 | S13: 赵宇瑄 | T13: 0.7 | U13: =R13*T13 -> 4312000 | V13: 穆华清 | W13: 0.3 | X13: =R13*W13 -> 1848000
A14: 11 | B14: 46053 | C14: 中交路桥南方工程有限公司 | D14: 中交路桥南方公司长赣铁路凿岩台车改造修理合同 | F14: LJNFNF-PJ2021018413-069925006 | G14: 213753 | I14: 华北区域 | J14: 华东区域 | L14: 0.7 | M14: 0.3 | O14: =G14*L14 -> 149627.1 | P14: =G14*M14 -> 64125.9 | R14: 64125.9 | S14: 陈浩 | T14: 1 | U14: =R14*T14 -> 64125.9
A15: 12 | B15: 46053 | C15: 中铁十一局集团有限公司 | D15: 回款虚拟合同池-华东区域 | F15: 3250* | G15: 54597.4 | I15: 华东区域 | L15: 1 | O15: =G15*L15 -> 54597.4 | R15: 54597.4 | S15: 赵宇瑄 | T15: 1 | U15: =R15*T15 -> 54597.4
A16: 13 | B16: 46053 | C16: 上海市基础工程集团有限公司上海机场联络线 | D16: 上海市基础工程集团有限公司DL1207&DL1208改造合同 | F16: SFEG（2024）设材-F001 | G16: 1730351.6 | I16: 华东区域 | L16: 1 | O16: =G16*L16 -> 1730351.6 | R16: 1730351.6 | S16: 赵宇瑄 | T16: 0.7 | U16: =R16*T16 -> 1211246.1 | V16: 穆华清 | W16: 0.3 | X16: =R16*W16 -> 519105.49
A17: 14 | B17: 46053 | C17: 宏润建设集团股份有限公司 | D17: 宏润建设集团股份有限公司采购合同 | F17: 宏润建设集团股份有限公司采购合同 | G17: 5547 | I17: 华东区域 | L17: 1 | O17: =G17*L17 -> 5547 | R17: 5547 | S17: 赵宇瑄 | T17: 1 | U17: =R17*T17 -> 5547
A18: 15 | B18: 46053 | C18: 中铁十六局集团有限公司 | D18: 关于“中铁十六局集团上海嘉闵线土压平衡盾构机租赁合同”的审批申请 | E18: 是 | F18: CRCC-16J-JMWZ-2024-008 | G18: 3530000 | I18: 华东区域 | J18: 华北区域 | L18: 0.7 | M18: 0.3 | O18: =G18*L18 -> 2471000 | P18: =G18*M18 -> 1059000 | R18: 2471000 | S18: 赵宇瑄 | T18: 1 | U18: =R18*T18 -> 2471000
A19: 16 | B19: 46053 | C19: 浙江物产工程技术服务有限公司 | D19: 浙江物产工程技术服务有限公司DZ620维修、整机联调合同 | E19: 是 | F19: WCGF-DZ620-04-WXLT | G19: 399400 | I19: 华东区域 | J19: 华南区域 | L19: 0.7 | M19: 0.3 | O19: =G19*L19 -> 279580 | P19: =G19*M19 -> 119820 | R19: 279580 | S19: 唐作栋 | T19: 0.6 | U19: =R19*T19 -> 167748 | V19: 刘新峥 | W19: 0.4 | X19: =R19*W19 -> 111832
A20: 17 | B20: 46053 | C20: 中铁十八局集团有限公司 | D20: 关于“中铁十八局集团有限公司杭州地铁10号线盾构设备租赁合同”的审批申请 | E20: 是 | F20: 12-SHBZ-2024-杭州地铁1032-12-002 | G20: 6000000 | I20: 华东区域 | J20: 华北区域 | L20: 0.7 | M20: 0.3 | O20: =G20*L20 -> 4200000 | P20: =G20*M20 -> 1800000 | R20: 4200000 | S20: 唐作栋 | T20: 0.6 | U20: =R20*T20 -> 2520000 | V20: 刘新峥 | W20: 0.4 | X20: =R20*W20 -> 1680000
A21: 18 | B21: 46053 | C21: 中铁十二局集团第四工程有限公司 | D21: 中铁十二局四公司DZ407/DZ408盾构机刀盘改造合同 | F21: ZT12-HZDTDG-SB012 | G21: 56000 | I21: 华东区域 | L21: 1 | O21: =G21*L21 -> 56000 | R21: 56000 | S21: 刘新峥 | T21: 0.6 | U21: =R21*T21 -> 33600 | V21: 唐作栋 | W21: 0.4 | X21: =R21*W21 -> 22400
A22: 19 | B22: 46053 | C22: 上海市机械施工集团有限公司 | D22: 上海市机械施工集团有限公司1台ZTJ18000采购合同 | F22: 25082024 | G22: 10152000 | I22: 华东区域 | L22: 1 | O22: =G22*L22 -> 10152000 | R22: 10152000 | S22: 赵宇瑄 | T22: 0.7 | U22: =R22*T22 -> 7106400 | V22: 穆华清 | W22: 0.3 | X22: =R22*W22 -> 3045600
A23: 20 | B23: 46053 | C23: 上海市基础工程集团有限公司上海机场联络线 | D23: 上海市基础工程集团有限公司9m土压掘进机采购合同 | F23: SFEG（2022）设材-C001 | G23: 5046500 | I23: 华东区域 | L23: 1 | O23: =G23*L23 -> 5046500 | R23: 5046500 | S23: 赵宇瑄 | T23: 0.7 | U23: =R23*T23 -> 3532550 | V23: 穆华清 | W23: 0.3 | X23: =R23*W23 -> 1513950
A24: 21 | B24: 46081 | C24: 中铁二十二局集团轨道工程有限公司 | D24: 中铁天瑞杭州18号线盾构设备租赁合同 | E24: 是 | F24: CR22TR-SBZLCG-HW-2025-001 | G24: 2000000 | I24: 华东区域 | J24: 华北区域 | L24: 0.6 | M24: 0.4 | O24: =G24*L24 -> 1200000 | P24: =G24*M24 -> 800000 | R24: 1200000 | S24: 刘新峥 | T24: 0.6 | U24: =R24*T24 -> 720000 | V24: 唐作栋 | W24: 0.4 | X24: =R24*W24 -> 480000
A25: 22 | B25: 46081 | C25: 中铁十五局集团有限公司杭州机场高铁站前4标项目经理部 | D25: 中铁十五局集团有限公司杭州机场高铁站前4标项目经理部加强型密封刷采购合同 | F25: CR15-HZJCGT4-JD-2024022(1F) | G25: 150000 | I25: 华东区域 | L25: 1 | O25: =G25*L25 -> 150000 | R25: 150000 | S25: 唐作栋 | T25: 1 | U25: =R25*T25 -> 150000
A26: 23 | B26: 46081 | C26: 中铁十一局集团有限公司城市建设分公司甬舟铁路YZSG-3工区一分部项目经理部 | D26: 中铁十一局甬舟铁路项目DZ1396盾构机技术服务合同 | F26: T11-2024-JSFW-YZTL3GQ-001 | G26: 40000 | I26: 华东区域 | L26: 1 | O26: =G26*L26 -> 40000 | R26: 40000 | S26: 万赛 | T26: 1 | U26: =R26*T26 -> 40000
A27: 24 | B27: 46081 | C27: 中铁十一局集团有限公司城市建设分公司甬舟铁路YZSG-3工区一分部项目经理部 | D27: 11局甬舟铁路项目DZ1396盾构机配件第八批采购合同 | F27: T11-2025-PJ-YZTL3GQ-087 | G27: 1073502 | I27: 华东区域 | L27: 1 | O27: =G27*L27 -> 1073502 | R27: 1073502 | S27: 万赛 | T27: 1 | U27: =R27*T27 -> 1073502
A28: 25 | B28: 46081 | C28: 通用个人客户 | D28: 回款虚拟合同池-华东区域 | F28: 3250* | G28: 852 | I28: 华东区域 | L28: 1 | O28: =G28*L28 -> 852 | R28: 852 | S28: 赵宇瑄 | T28: 1 | U28: =R28*T28 -> 852
A29: 26 | B29: 46081 | C29: 中铁二十四局集团有限公司 | D29: 中铁二十四局上海东站项目2台ZTE6830租赁合同 | E29: 是 | F29: SHDZ-2025-DZ-001 | G29: 1000000 | I29: 华东区域 | L29: 1 | O29: =G29*L29 -> 1000000 | R29: 1000000 | S29: 赵宇瑄 | T29: 1 | U29: =R29*T29 -> 1000000
A30: 27 | B30: 46081 | C30: 上海城建市政（集团）有限公司泰和污水调蓄池项目 | D30: 上海城建市政工程（集团）有限公司备品备件采购合同 | F30: CRCHI-PJCG-1204 | G30: 123039 | I30: 华东区域 | L30: 1 | O30: =G30*L30 -> 123039 | R30: 123039 | S30: 赵宇瑄 | T30: 1 | U30: =R30*T30 -> 123039
A31: 28 | B31: 46081 | C31: 中建海峡建设发展有限公司 | D31: 中建海峡建设发展有限公司租赁合同 | E31: 是 | F31: 107003021【2017】55SZ83-07 | G31: 490000 | I31: 华东区域 | L31: 1 | O31: =G31*L31 -> 490000 | R31: 490000 | S31: 周斌 | T31: 1 | U31: =R31*T31 -> 490000
A32: 29 | B32: 46081 | C32: 上海市基础工程集团有限公司上海机场联络线 | D32: 上海市基础工程集团上海市轨道交通项目2台ZTE6760采购合同 | F32: SFEG（2024）设材-C003 | G32: 6560000 | I32: 华东区域 | L32: 1 | O32: =G32*L32 -> 6560000 | R32: 6560000 | S32: 赵宇瑄 | T32: 0.7 | U32: =R32*T32 -> 4592000 | V32: 穆华清 | W32: 0.3 | X32: =R32*W32 -> 1968000
A33: 30 | B33: 46081 | C33: 中铁十六局集团地铁工程有限公司 | D33: 中铁十六局地铁公司厦工中铁243/244号盾构机维修合同 | F33: CRCC-16J-DGJWXHT-202303-8（CRCHI-WXGZ-2022-009） | G33: 82681 | I33: 华东区域 | L33: 1 | O33: =G33*L33 -> 82681 | R33: 82681 | S33: 周斌 | T33: 1 | U33: =R33*T33 -> 82681
A34: 31 | B34: 46081 | C34: 上海地铁盾构设备工程有限公司 | D34: 上海地铁盾构设备工程有限公司盾构机部件购销合同 | F34: CRCHI-XS-2021-028 | G34: 71196 | I34: 华东区域 | L34: 1 | O34: =G34*L34 -> 71196 | R34: 71196 | S34: 赵宇瑄 | T34: 1 | U34: =R34*T34 -> 71196
A35: 32 | B35: 46081 | C35: 中铁十一局集团有限公司第四分公司 | D35: 十一局四公司甬舟铁路凿岩台车、多功能钻机采购合同 | E35: 是 | F35: C2000010001100004011002025006 | G35: 2000000 | I35: 华东区域 | J35: 华中区域 | L35: 0.7 | M35: 0.3 | O35: =G35*L35 -> 1400000 | P35: =G35*M35 -> 600000 | R35: 1400000 | S35: 万赛 | T35: 1 | U35: =R35*T35 -> 1400000
A36: 33 | B36: 46081 | C36: 中铁二十局集团有限公司 | D36: 中铁二十局福州港口后方铁路项目砂石骨料加工设备采购合同 | E36: 是 | F36: CR2006-港后-SC-25-010 | G36: 212400 | I36: 华东区域 | L36: 1 | O36: =G36*L36 -> 212400 | R36: 212400 | S36: 周斌 | T36: 1 | U36: =R36*T36 -> 212400
A37: 34 | B37: 46081 | C37: 中铁十九局集团华东工程有限公司 | D37: 中铁十九局华东公司汉宜高速项目2台HZS180采购合同 | F37: CRCHI-XS-2025-032 | G37: 350000 | I37: 华中区域 | J37: 华东区域 | L37: 0.7 | M37: 0.3 | O37: =G37*L37 -> 245000 | P37: =G37*M37 -> 105000 | R37: 105000 | S37: 万赛 | T37: 1 | U37: =R37*T37 -> 105000
A38: 35 | B38: 46081 | C38: 中铁十五局集团有限公司 | D38: 中铁十五局彭泽廊道项目散料运输设备购销合同 | F38: CR15G2C-TL（房建、市政）彭泽廊道项目-SBCG-2025-001 | G38: 81813570 | I38: 华东区域 | L38: 1 | O38: =G38*L38 -> 81813570 | R38: 81813570 | S38: 陈浩 | T38: 0.75 | U38: =R38*T38 -> 61360177 | V38: 赵宇瑄 | W38: 0.25 | X38: =R38*W38 -> 20453392
A39: 36 | B39: 46081 | C39: 中铁十一局集团城市轨道工程有限公司 | D39: 中铁十一局杭州城轨交通SG18-8标2台ZTE7150租赁合同 | F39: CRCHI-GZ-2025-002（客户编号T11CG-HZ1808-2025-ZL-11） | G39: 2000000 | I39: 华东区域 | J39: 华中区域 | L39: 0.7 | M39: 0.3 | O39: =G39*L39 -> 1400000 | P39: =G39*M39 -> 600000 | R39: 1400000 | S39: 唐作栋 | T39: 0.6 | U39: =R39*T39 -> 840000 | V39: 刘新峥 | W39: 0.4 | X39: =R39*W39 -> 560000
A40: 37 | B40: 46081 | C40: 中铁十八局集团隧道工程有限公司 | D40: 中铁十八局隧道公司江西上栗抽蓄项目DZ534TBM维修改造合同 | F40: 11-QT-2024-流源水库-0-006 | G40: 1500000 | I40: 华东区域 | J40: 西南区域 | L40: 0.7 | M40: 0.3 | O40: =G40*L40 -> 1050000 | P40: =G40*M40 -> 450000 | R40: 1050000 | S40: 杨志胜 | T40: 1 | U40: =R40*T40 -> 1050000
...

Sheet 业绩台账
A1: 华东区域指挥部经营人员指标完成情况
A2: 单位：万元
A3: 排序 | B3: 省市 | C3: 经营小组 | D3: 姓名 | E3: 本周新签 | F3: 近两周新签 | G3: 本月新签 | H3: 累计新签 | I3: 新签目标 | J3: 新签目标完成率 | K3: 2025年同期新签 | L3: 新签同比增长率 | M3: 本周营收 | N3: 近两周营收 | O3: 本月营收 | P3: 累计营收 | Q3: 营收目标 | R3: 营收目标完成率 | S3: 2025年同期营收 | T3: 营收同比增长率 | U3: 本周回款 | V3: 近两周回款 | W3: 本月回款 | X3: 累计回款 | Y3: 回款目标 | Z3: 回款目标完成率 | AA3: 2025年同期回款 | AB3: 回款同比增长率
A4: 1 | B4: 浙江省经营部 | C4: 杭州经营小组 | D4: 刘新峥 | E4: 0 | F4: 0 | G4: 0 | H4: 373.06722 | I4: 4000 | J4: =H4/I4 -> 0.093266804 | K4: 1259.6643 | L4: =(H4-K4)/K4 -> -0.703836 | M4: 0 | N4: 0 | O4: 412.04354 | P4: =190.4318582+O4 -> 602.4754 | Q4: 2000 | R4: =P4/Q4 -> 0.3012377 | S4: 18.522478 | T4: =(P4-S4)/S4 -> 31.526717 | U4: 0 | V4: 0 | W4: 209.704 | X4: =589.07882268+W4 -> 798.78282 | Y4: 2100 | Z4: =X4/Y4 -> 0.38037277 | AA4: 1931.1161 | AB4: =(X4-AA4)/AA4 -> -0.58636209
A5: 2 | D5: 唐作栋 | E5: 0 | F5: 0 | G5: 0 | H5: 288.03668 | I5: 6200 | J5: =H5/I5 -> 0.046457529 | K5: 967.93325 | L5: =(H5-K5)/K5 -> -0.70242093 | M5: 0 | N5: 0 | O5: 618.06531 | P5: =328.8780433+O5 -> 946.94335 | Q5: 7200 | R5: =P5/Q5 -> 0.13151991 | S5: 27.783717 | T5: =(P5-S5)/S5 -> 33.082674 | U5: 0 | V5: 0 | W5: 172.306 | X5: =828.03903402+W5 -> 1000.345 | Y5: 4300 | Z5: =X5/Y5 -> 0.23263838 | AA5: 2843.127 | AB5: =(X5-AA5)/AA5 -> -0.64815323 | AC5: 9.3252 | AD5: =H5-AC5 -> 278.71148
A6: 3 | D6: 小计 | E6: =SUM(E4:E5) -> 0 | F6: =SUM(F4:F5) -> 0 | G6: =SUM(G4:G5) -> 0 | H6: =SUM(H4:H5) -> 661.10389 | I6: =SUM(I4:I5) -> 10200 | J6: =H6/I6 -> 0.064814107 | K6: 2227.5975 | L6: =(H6-K6)/K6 -> -0.70322112 | M6: =SUM(M4:M5) -> 0 | N6: =SUM(N4:N5) -> 0 | O6: =SUM(O4:O5) -> 1030.1088 | P6: =SUM(P4:P5) -> 1549.4188 | Q6: =SUM(Q4:Q5) -> 9200 | R6: =P6/Q6 -> 0.16841508 | S6: 46.306195 | T6: =(P6-S6)/S6 -> 32.460291 | U6: 0 | V6: 0 | W6: =SUM(W4:W5) -> 382.01 | X6: =SUM(X4:X5) -> 1799.1279 | Y6: =SUM(Y4:Y5) -> 6400 | Z6: =X6/Y6 -> 0.28111373 | AA6: 4774.243 | AB6: =(X6-AA6)/AA6 -> -0.62315956
A7: 4 | C7: 宁波经营小组 | D7: 沈腾飞 | E7: 0 | F7: 0 | G7: 3765 | H7: 3765 | I7: 7100 | J7: =H7/I7 -> 0.53028169 | K7: 0.039 | L7: =(H7-K7)/K7 -> 96537.462 | M7: 0 | N7: 0 | O7: 991.15044 | P7: 991.15044 | Q7: 10000 | R7: =P7/Q7 -> 0.099115044 | S7: 0 | T7: =(P7-S7)/S7 -> #DIV/0! | U7: 0 | V7: 0 | W7: 409.15 | X7: =374.85+W7 -> 784 | Y7: 8200 | Z7: =X7/Y7 -> 0.095609756 | AA7: 54.67 | AB7: =(X7-AA7)/AA7 -> 13.340589
A8: 5 | D8: 袁志凌 | E8: 0 | F8: 0 | G8: 785.1 | H8: =105+G8 -> 890.1 | I8: 21700 | J8: =H8/I8 -> 0.041018433 | K8: 87.22907 | L8: =(H8-K8)/K8 -> 9.204167 | M8: 0 | N8: 0 | O8: 984.95575 | P8: =270.637168+O8 -> 1255.5929 | Q8: 800 | R8: =P8/Q8 -> 1.5694912 | S8: 0 | T8: =(P8-S8)/S8 -> #DIV/0! | U8: 0 | V8: 0 | W8: 157.02 | X8: 157.02 | Y8: 8400 | Z8: =X8/Y8 -> 0.018692857 | AA8: 869.234 | AB8: =(X8-AA8)/AA8 -> -0.81935819
A9: 6 | D9: 万赛 | E9: 0 | F9: 0 | G9: 686 | H9: =215.8712+G9 -> 901.8712 | I9: 5000 | J9: =H9/I9 -> 0.18037424 | K9: 776.7889 | L9: =(H9-K9)/K9 -> 0.16102483 | M9: 0 | N9: 0 | O9: 327.61062 | P9: =452.9330509+O9 -> 780.54367 | Q9: 4000 | R9: =P9/Q9 -> 0.19513592 | S9: 687.4238 | T9: =(P9-S9)/S9 -> 0.13546209 | U9: 0 | V9: 0 | W9: 0 | X9: 518.514 | Y9: 4000 | Z9: =X9/Y9 -> 0.1296285 | AA9: 1098.5193 | AB9: =(X9-AA9)/AA9 -> -0.52798827
A10: 7 | D10: 小计 | E10: =SUM(E7:E9) -> 0 | F10: =SUM(F7:F9) -> 0 | G10: =SUM(G7:G9) -> 5236.1 | H10: =SUM(H7:H9) -> 5556.9712 | I10: =SUM(I7:I9) -> 33800 | J10: =H10/I10 -> 0.16440743 | K10: 864.05697 | L10: =(H10-K10)/K10 -> 5.4312556 | M10: =SUM(M7:M9) -> 0 | N10: =SUM(N7:N9) -> 0 | O10: =SUM(O7:O9) -> 2303.7168 | P10: =SUM(P7:P9) -> 3027.287 | Q10: =SUM(Q7:Q9) -> 14800 | R10: =P10/Q10 -> 0.20454642 | S10: 687.4238 | T10: =(P10-S10)/S10 -> 3.4038147 | U10: 0 | V10: 0 | W10: =SUM(W7:W9) -> 566.17 | X10: =SUM(X7:X9) -> 1459.534 | Y10: =SUM(Y7:Y9) -> 20600 | Z10: =X10/Y10 -> 0.070851165 | AA10: 2022.4233 | AB10: =(X10-AA10)/AA10 -> -0.27832418
A11: 8 | C11: 总计 | E11: =SUM(E6,E10) -> 0 | F11: =SUM(F6,F10) -> 0 | G11: =SUM(G6,G10) -> 5236.1 | H11: =SUM(H6,H10) -> 6218.0751 | I11: =SUM(I6,I10) -> 44000 | J11: =H11/I11 -> 0.14131989 | K11: 3091.6545 | L11: =(H11-K11)/K11 -> 1.0112451 | M11: =SUM(M6,M10) -> 0 | N11: =SUM(N6,N10) -> 0 | O11: =SUM(O6,O10) -> 3333.8257 | P11: =SUM(P6,P10) -> 4576.7058 | Q11: =SUM(Q6,Q10) -> 24000 | R11: =P11/Q11 -> 0.19069607 | S11: 733.73 | T11: =(P11-S11)/S11 -> 5.2375885 | U11: =SUM(U6,U10) -> 0 | V11: =SUM(V6,V10) -> 0 | W11: =SUM(W6,W10) -> 948.18 | X11: =SUM(X6,X10) -> 3258.6619 | Y11: =SUM(Y6,Y10) -> 27000 | Z11: =X11/Y11 -> 0.12069118 | AA11: 6796.6663 | AB11: =(X11-AA11)/AA11 -> -0.52054997
A12: 9 | B12: 上海市经营部 | C12: 上海经营小组 | D12: 穆华清 | E12: 0 | F12: 0 | G12: 443.88 | H12: 2648.5797 | I12: 3500 | J12: =H12/I12 -> 0.75673706 | K12: 5.7409 | L12: =(H12-K12)/K12 -> 460.3527 | M12: 0 | N12: 0 | O12: 0 | P12: 0 | Q12: 4500 | R12: =P12/Q12 -> 0 | S12: 6521.1504 | T12: =(P12-S12)/S12 -> -1 | U12: 0 | V12: 0 | W12: 0 | X12: 889.46555 | Y12: 4500 | Z12: =X12/Y12 -> 0.19765901 | AA12: 3628.2367 | AB12: =(X12-AA12)/AA12 -> -0.75484908 | AC12: 11.5331 | AD12: =H12-AC12 -> 2637.0466
A13: 10 | D13: 赵宇瑄 | E13: 0 | F13: 0 | G13: =1044.81516-0.7478-0.3048 -> 1043.7626 | H13: 6215.3252 | I13: 9500 | J13: =H13/I13 -> 0.65424475 | K13: 4.9697 | L13: =(H13-K13)/K13 -> 1249.6439 | M13: 0 | N13: 0 | O13: 280.27736 | P13: =1399.170303+O13 -> 1679.4477 | Q13: 10500 | R13: =P13/Q13 -> 0.1599474 | S13: 3568.67 | T13: =(P13-S13)/S13 -> -0.52939116 | U13: 0 | V13: 0 | W13: 3.1147 | X13: =5161.87880305+W13 -> 5164.9935 | Y13: 10500 | Z13: =X13/Y13 -> 0.49190414 | AA13: 5095.1482 | AB13: =(X13-AA13)/AA13 -> 0.013708198 | AC13: 5.993628 | AD13: =O13+AC13 -> 286.27099
A14: 11 | C14: 总计 | E14: =SUM(E12:E13) -> 0 | F14: =SUM(F12:F13) -> 0 | G14: =SUM(G12:G13) -> 1487.6426 | H14: =SUM(H12:H13) -> 8863.9049 | I14: =SUM(I12:I13) -> 13000 | J14: =H14/I14 -> 0.68183884 | K14: 10.7106 | L14: =(H14-K14)/K14 -> 826.58248 | M14: =SUM(M12:M13) -> 0 | N14: =SUM(N12:N13) -> 0 | O14: =SUM(O12:O13) -> 280.27736 | P14: =SUM(P12:P13) -> 1679.4477 | Q14: =SUM(Q12:Q13) -> 15000 | R14: =P14/Q14 -> 0.11196318 | S14: 10089.82 | T14: =SUM(T12:T13) -> -1.5293912 | U14: =SUM(U12:U13) -> 0 | V14: =SUM(V12:V13) -> 0 | W14: =SUM(W12:W13) -> 3.1147 | X14: =SUM(X12:X13) -> 6054.4591 | Y14: =SUM(Y12:Y13) -> 15000 | Z14: =X14/Y14 -> 0.4036306 | AA14: 8723.3849 | AB14: =(X14-AA14)/AA14 -> -0.30595071
A15: 12 | B15: 闽赣经营营 | C15: 铁道经营小组 | D15: 周斌 | E15: 0 | F15: 0 | G15: 0 | H15: =4426+G15+447.2-1770.4 -> 3102.8 | I15: 6000 | J15: =H15/I15 -> 0.51713333 | K15: 82.824 | L15: =(H15-K15)/K15 -> 36.462571 | M15: 0 | N15: 0 | O15: 1773.4671 | P15: =4916.4601774+O15 -> 6689.9272 | Q15: 10000 | R15: =P15/Q15 -> 0.66899272 | S15: 451.41035 | T15: =(P15-S15)/S15 -> 13.820057 | U15: 0 | V15: 0 | W15: 19.7689 | X15: =82.5081+W15 -> 102.277 | Y15: 9500 | Z15: =X15/Y15 -> 0.010766 | AA15: 387.6 | AB15: =(X15-AA15)/AA15 -> -0.73612745
A16: 13 | D16: 陈浩 | E16: 0 | F16: 0 | G16: 0 | H16: =29.4+1770.4 -> 1799.8 | I16: 3000 | J16: =H16/I16 -> 0.59993333 | K16: 0 | L16: =(H16-K16)/K16 -> #DIV/0! | M16: 0 | N16: 0 | O16: 60.707965 | P16: =121.4159296+O16 -> 182.12389 | Q16: 12000 | R16: =P16/Q16 -> 0.015176991 | S16: 0 | T16: =(P16-S16)/S16 -> #DIV/0! | U16: 0 | V16: 0 | W16: 0 | X16: 6892.4303 | Y16: 15000 | Z16: =X16/Y16 -> 0.45949536 | AA16: 265.1973 | AB16: =(X16-AA16)/AA16 -> 24.989821
A17: 14 | D17: 小计 | E17: =SUM(E15:E16) -> 0 | F17: =SUM(F15:F16) -> 0 | G17: =SUM(G15:G16) -> 0 | H17: =SUM(H15:H16) -> 4902.6 | I17: =SUM(I15:I16) -> 9000 | J17: =H17/I17 -> 0.54473333 | K17: 82.824 | L17: =(H17-K17)/K17 -> 58.192988 | M17: =SUM(M15:M16) -> 0 | N17: =SUM(N15:N16) -> 0 | O17: =SUM(O15:O16) -> 1834.175 | P17: =SUM(P15:P16) -> 6872.0511 | Q17: =SUM(Q15:Q16) -> 22000 | R17: =P17/Q17 -> 0.31236596 | S17: 451.41035 | T17: =(P17-S17)/S17 -> 14.223512 | U17: 0 | V17: 0 | W17: =SUM(W15:W16) -> 19.7689 | X17: =SUM(X15:X16) -> 6994.7073 | Y17: =SUM(Y15:Y16) -> 24500 | Z17: =X17/Y17 -> 0.28549826 | AA17: 652.7973 | AB17: =(X17-AA17)/AA17 -> 9.7149759
A18: 15 | C18: 建筑经营小组 | D18: 杨志胜 | E18: 0 | F18: 0 | G18: =537.2+619.2-63 -> 1093.4 | H18: =1104.45+G18-447.2 -> 1750.65 | I18: 4000 | J18: =H18/I18 -> 0.4376625 | K18: 183.456 | L18: =(H18-K18)/K18 -> 8.5426151 | M18: 0 | N18: 0 | O18: 132.74336 | P18: =2191.9469019+O18 -> 2324.6903 | Q18: 10000 | R18: =P18/Q18 -> 0.23246903 | S18: 93.543363 | T18: =(P18-S18)/S18 -> 23.851472 | U18: 0 | V18: 0 | W18: 0 | X18: 355 | Y18: 7500 | Z18: =X18/Y18 -> 0.047333333 | AA18: 0 | AB18: =(X18-AA18)/AA18 -> #DIV/0!
A19: 16 | C19: 总计 | E19: =SUM(E17,E18) -> 0 | F19: =SUM(F17,F18) -> 0 | G19: =SUM(G17,G18) -> 1093.4 | H19: =SUM(H17,H18) -> 6653.25 | I19: =SUM(I17,I18) -> 13000 | J19: =H19/I19 -> 0.51178846 | K19: 266.28 | L19: =(H19-K19)/K19 -> 23.985917 | M19: =SUM(M17,M18) -> 0 | N19: =SUM(N17,N18) -> 0 | O19: =SUM(O17,O18) -> 1966.9184 | P19: =SUM(P17,P18) -> 9196.7414 | Q19: =SUM(Q17,Q18) -> 32000 | R19: =P19/Q19 -> 0.28739817 | S19: 544.95372 | T19: =(P19-S19)/S19 -> 15.876188 | U19: 0 | V19: 0 | W19: =SUM(W17,W18) -> 19.7689 | X19: =SUM(X17,X18) -> 7349.7073 | Y19: =SUM(Y17,Y18) -> 32000 | Z19: =X19/Y19 -> 0.22967835 | AA19: 652.7973 | AB19: =(X19-AA19)/AA19 -> 10.258789
A20: 华东区域指挥部总计 | E20: =SUM(E11,E14,E19) -> 0 | F20: =SUM(F11,F14,F19) -> 0 | G20: =SUM(G11,G14,G19) -> 7817.1426 | H20: =SUM(H11,H14,H19) -> 21735.23 | I20: =SUM(I11,I14,I19) -> 70000 | J20: =H20/I20 -> 0.31050329 | K20: 3368.6451 | L20: =(H20-K20)/K20 -> 5.4522172 | M20: =SUM(M11,M14,M19) -> 0 | N20: =SUM(N11,N14,N19) -> 0 | O20: =SUM(O11,O14,O19) -> 5581.0214 | P20: =SUM(P11,P14,P19) -> 15452.895 | Q20: =SUM(Q11,Q14,Q19) -> 71000 | R20: =P20/Q20 -> 0.21764641 | S20: 11368.504 | T20: =(P20-S20)/S20 -> 0.35927248 | U20: 0 | V20: 0 | W20: =SUM(W11,W14,W19) -> 971.0636 | X20: =SUM(X11,X14,X19) -> 16662.828 | Y20: =SUM(Y11,Y14,Y19) -> 74000 | Z20: =X20/Y20 -> 0.22517335 | AA20: 16172.848 | AB20: =(X20-AA20)/AA20 -> 0.030296441
M32: 10000

Sheet 新签分类占比
A1: 序号 | B1: 产品线 | C1: 金额 | D1: 占比
A2: 1 | B2: 掘进机 | C2: =(SUMIF(新签!B3:B9,B2,新签!Y3:Y9))/10000 -> 7347.15 | D2: =C2/C4 -> 0.56592285
A3: 2 | B3: 特装 | C3: =(SUMIF(新签!B3:B9,B3,新签!Y3:Y9))/10000 -> 5635.45 | D3: =C3/C4 -> 0.43407715
B4: 合计 | C4: =SUM(C2:C3) -> 12982.6
A8: 序号 | B8: 客户类别 | C8: 金额 | D8: 占比
A9: 1 | B9: 系统内 | C9: =(SUMIF(新签!F3:F9,B9,新签!Y3:Y9))/10000 -> 6822.6 | D9: =C9/C11 -> 0.52551877
A10: 2 | B10: 系统外 | C10: =(SUMIF(新签!F3:F9,B10,新签!Y3:Y9))/10000 -> 6160 | D10: =C10/C11 -> 0.47448123
B11: 合计 | C11: =SUM(C9:C10) -> 12982.6

Sheet Sheet10
A3: 姓名 | B3: 求和项:金额
A4: 陈浩 | B4: 2222202
A5: 刘新峥 | B5: 585000
A6: 陆顺 | B6: 640000
A7: 穆华清 | B7: 658249.84
A8: 沈腾飞 | B8: 723090
A9: 袁志凌 | B9: 320760
A10: 赵宇瑄 | B10: -1749000
A11: 赵宇暄 | B11: 1535916.3
A12: 周斌 | B12: 1500400
A13: (空白)
A14: 总计 | B14: 6436618.1

Sheet Sheet8
A1: 姓名 | B1: 比例 | C1: 金额
A2: 陈浩 | B2: 1 | C2: 80000
A3: 赵宇瑄 | B3: 1 | C3: -1749000
A4: 袁志凌 | B4: 0.6 | C4: 320760
A5: 赵宇暄 | B5: 0.7 | C5: -334896.58
A6: 沈腾飞 | B6: 1 | C6: 509250
A7: 赵宇暄 | B7: 0.7 | C7: 1870812.9
A8: 周斌 | B8: 1 | C8: 1100000
A9: 周斌 | B9: 0.7 | C9: 400400
A10: 陈浩 | B10: 0.5 | C10: 585000
A11: 陈浩 | B11: 1 | C11: 230000
A12: 陈浩 | B12: 1 | C12: 575400
A13: 陆顺 | B13: 1 | C13: 240000
... A22: 刘新峥 | B22: 0.5 | C22: 585000

Sheet Sheet5
A1: 责任人1 | B1: 比例 | C1: 金额
A2: 赵宇暄 | B2: 0.7 | C2: 1870812.9
A3: 周斌 | B3: 1 | C3: 1100000
A4: 周斌 | B4: 0.7 | C4: 400400
A5: 陈浩 | B5: 0.5 | C5: 585000
A6: 陈浩 | B6: 1 | C6: 230000
A7: 陈浩 | B7: 1 | C7: 575400
A8: 陆顺 | B8: 1 | C8: 240000
A9: 陆顺 | B9: 1 | C9: 400000
A10: 穆华清 | B10: 0.3 | C10: 801776.94
A11: 陈浩 | B11: 0.3 | C11: 171600
A12: 刘新峥 | B12: 0.5 | C12: 585000
F28: 责任人1 | G28: 求和项:金额
F29: 陈浩 | G29: 1562000
F30: 刘新峥 | G30: 585000
F31: 陆顺 | G31: 640000
F32: 穆华清 | G32: 801776.94
F33: 赵宇暄 | G33: 1870812.9
F34: 周斌 | G34: 1500400
F35: 总计 | G35: 6959989.8

Sheet Sheet9
A1: 责任人1 | B1: 比例 | C1: 金额
A2: 杨志胜 | B2: 1 | C2: 150000
A3: 段靖宗 | B3: 0.7 | C3: 1470000
A4: 杨志胜 | B4: 1 | C4: 359000
A5: 段靖宗 | B5: 0.7 | C5: 2450000
A6: 段靖宗 | B6: 0.7 | C6: 2205000
A7: 段靖宗 | B7: 0.7 | C7: 2205000
A8: 陈浩 | B8: 1 | C8: 45000
A9: 袁志凌 | B9: 1 | C9: 700000
A10: 陈浩 | B10: 1 | C10: 364000
A11: 段靖宗 | B11: 0.7 | C11: 1372000
A12: 杨志胜 | B12: 1 | C12: 126000
A13: 陈浩 | B13: 1 | C13: 210000
... A380: 申星 | B380: 0.25 | C380: 525000

Sheet 业绩台账 （月报)
A1: 华东区域指挥部经营人员指标完成情况
A2: 单位：万元
A3: 排序 | B3: 经营部 | C3: 经营小组 | D3: 姓名 | E3: 新签目标 | F3: 月度新签目标 | G3: 本月新签 | H3: 月度新签目标完成率 | I3: 累计新签 | J3: 累计新签完成率 | K3: 营收目标 | L3: 月度营收目标 | M3: 本月营收 | N3: 月度营收目标完成率 | O3: 累计营收 | P3: 在手项目营收目标完成率 | Q3: 新签项目本月营收 | R3: 新签项目营收 | S3: 累计营收 | T3: 期初逾期总额 | U3: 本月逾期回款目标 | V3: 本月逾期回款 | W3: 本月逾期回款目标完成率 | X3: 逾期累计回款 | Y3: 逾期回款率 | Z3: 本月到期回款（含新增逾期回款） | AA3: 累计到期回款（含新增逾期回款） | AB3: 累计回款
A4: 1 | B4: 浙江省经营部 | C4: 杭州经营小组 | D4: 段靖宗 | E4: \ | F4: \ | G4: 0 | H4: \ | I4: 0 | K4: \ | L4: \ | M4: 0 | N4: \ | O4: 6592.7644 | P4: \ | Q4: 0 | R4: 0 | S4: 6592.7644 | T4: 5392.3947 | U4: =T4*0.7/12 -> 314.55636 | V4: 0 | W4: =V4/U4 -> 0 | X4: 3494.0601 | Y4: 0.60281708 | Z4: 840 | AA4: =AB4-X4 -> 8647.9199 | AB4: 12141.98
A5: 2 | D5: 刘新峥 | E5: \ | F5: \ | G5: 0 | H5: \ | I5: 623.6 | J5: \ | K5: \ | L5: \ | M5: 0 | N5: \ | O5: 719.11504 | P5: \ | Q5: 93.805309 | R5: 719.11504 | S5: 719.11504 | T5: \ | U5: \ | V5: \ | W5: \ | X5: \ | Y5: \ | Z5: 0 | AA5: 0 | AB5: 469.4
A6: 3 | D6: 唐作栋 | E6: \ | F6: \ | G6: 0 | H6: \ | I6: 556.52988 | J6: \ | K6: \ | L6: \ | M6: 0 | N6: \ | O6: 2825.4705 | P6: \ | Q6: 0 | R6: 0 | S6: 2825.4705 | T6: 2216.8796 | U6: =T6*0.7/12 -> 129.31798 | V6: 0 | W6: =V6/U6 -> 0 | X6: 1452.6402 | Y6: 0.62543656 | Z6: 360 | AA6: =AB6-X6 -> 3950.7927 | AB6: 5403.4329
A7: 4 | D7: 合计 | E7: 22500 | F7: =E7/12 -> 1875 | G7: =SUM(G4:G6) -> 0 | H7: =G7/F7 -> 0 | I7: =SUM(I4:I6) -> 1180.1299 | J7: =I7/E7 -> 0.052450217 | K7: 13000 | L7: =K7/12 -> 1083.3333 | M7: =SUM(M4:M6) -> 0 | N7: =M7/L7 -> 0 | O7: =SUM(O4:O6) -> 10137.35 | P7: =O7/K7 -> 0.77979615 | Q7: =SUM(Q4:Q6) -> 93.805309 | R7: 458.0531 | S7: 10137.35 | T7: 7609.2744 | U7: =T7*0.7/12 -> 443.87434 | V7: =SUM(V4:V6) -> 0 | W7: =V7/U7 -> 0 | X7: 4946.7003 | Y7: =X7/T7 -> 0.6500883 | Z7: 1200 | AA7: 1400.9332 | AB7: 18014.813
A8: 5 | C8: 宁波经营小组 | D8: 沈腾飞 | E8: \ | F8: \ | G8: 1325 | H8: \ | I8: 7153.259 | J8: \ | K8: \ | L8: \ | M8: 0 | N8: \ | O8: 1210.0062 | P8: \ | Q8: 450.6823 | R8: 1210.0062 | S8: 1210.0062 | T8: 621.36884 | U8: =T8*0.7/12 -> 36.246516 | V8: 0 | W8: =V8/U8 -> 0 | X8: 363.13997 | Y8: 0.47424328 | Z8: 0 | AA8: =AB8-X8 -> 6198.0434 | AB8: 6561.1834
A9: 6 | D9: 袁志凌 | E9: \ | F9: \ | G9: 834.3752 | H9: \ | I9: 3965.9752 | J9: \ | K9: \ | L9: \ | M9: 0 | N9: \ | O9: 432.56637 | P9: \ | Q9: 0 | R9: 432.56637 | S9: 432.56637 | T9: 126 | U9: =T9*0.7/12 -> 7.35 | V9: 0 | W9: =V9/U9 -> 0 | X9: 0 | Y9: 0 | Z9: 51.56256 | AA9: =AB9-X9 -> 3739.1781 | AB9: 3739.1781
A10: 7 | D10: 万赛 | E10: \ | F10: \ | G10: 920.3128 | H10: \ | I10: 5140.3128 | J10: \ | K10: \ | L10: \ | M10: 0 | N10: \ | O10: 1438.8282 | P10: \ | Q10: 0 | R10: 107.07965 | S10: 1438.8282 | T10: 85.648864 | U10: =T10*0.7/12 -> 4.9961837 | V10: 0 | W10: =V10/U10 -> 0 | X10: 85.648864 | Y10: 1 | Z10: 46.34384 | AA10: =AB10-X10 -> 3776.635 | AB10: 3862.2838
A11: 9 | D11: 合计 | E11: 22500 | F11: =E11/12 -> 1875 | G11: =SUM(G8:G10) -> 3079.688 | H11: =G11/F11 -> 1.6425003 | I11: =SUM(I8:I10) -> 16259.547 | J11: =I11/E11 -> 0.72264653 | K11: 5000 | L11: =K11/12 -> 416.66667 | M11: =SUM(M8:M10) -> 0 | N11: =M11/L11 -> 0 | O11: =SUM(O8:O10) -> 3081.4008 | P11: =O11/K11 -> 0.61628016 | Q11: =SUM(Q8:Q10) -> 450.6823 | R11: =SUM(R8:R10) -> 1749.6522 | S11: 3081.4008 | T11: 833.01771 | U11: =T11*0.7/12 -> 48.5927 | V11: 0 | W11: =V11/U11 -> 0 | X11: 448.78883 | Y11: =X11/T11 -> 0.53875065 | Z11: 97.9064 | AA11: 534.29114 | AB11: 14162.645
A12: 10 | C12: 小计 | E12: =SUM(E7,E11) -> 45000 | F12: =E12/12 -> 3750 | G12: =SUM(G7,G11) -> 3079.688 | H12: =G12/F12 -> 0.82125013 | I12: =SUM(I7,I11) -> 17439.677 | J12: =I12/E12 -> 0.38754838 | K12: 18000 | L12: =K12/12 -> 1500 | M12: =SUM(M7,M11) -> 0 | N12: =M12/L12 -> 0 | O12: =SUM(O7,O11) -> 13218.751 | P12: =O12/K12 -> 0.73437504 | Q12: =SUM(Q7,Q11) -> 544.48761 | R12: =SUM(R7,R11) -> 2207.7053 | S12: 13218.751 | T12: 8442.2921 | U12: =T12*0.7/12 -> 492.46704 | V12: =SUM(V7,V11) -> 0 | W12: =V12/U12 -> 0 | X12: 5395.4891 | Y12: =X12/T12 -> 0.63910239 | Z12: 1297.9064 | AA12: =AB12-X12 -> 26781.969 | AB12: 32177.458
A13: 11 | B13: 上海市经营部 | C13: 经营一组 | D13: 穆华清 | E13: 18500 | F13: =E13/12 -> 1541.6667 | G13: 0 | H13: \ | I13: 17207.989 | J13: \ | K13: 18400 | L13: =K13/12 -> 1533.3333 | M13: 0 | N13: \ | O13: 16133.393 | P13: 0.78523366 | Q13: 0 | R13: 146.61505 | S13: 16133.393 | T13: 897.33097 | U13: =T13*0.7/12 -> 52.344307 | V13: 0 | W13: =V13/U13 -> 0 | X13: 117.99594 | Y13: 0.40043116 | Z13: 15.309 | AA13: =AB13-X13 -> 8645.5398 | AB13: 8763.5358
A14: 12 | D14: 合计 | E14: 18500 | F14: =E14/12 -> 1541.6667 | G14: 0 | H14: =G14/F14 -> 0 | I14: =SUM(I13) -> 17207.989 | J14: =I14/E14 -> 0.93016159 | K14: 18400 | L14: =K14/12 -> 1533.3333 | M14: =SUM(M13) -> 0 | N14: =M14/L14 -> 0 | O14: 16133.393 | P14: =O14/K14 -> 0.87681485 | Q14: =SUM(Q13) -> 0 | R14: 146.61505 | S14: 16133.393 | T14: 897.33097 | U14: =T14*0.7/12 -> 52.344307 | V14: 0 | W14: =V14/U14 -> 0 | X14: 117.99594 | Y14: =X14/T14 -> 0.13149657 | Z14: 15.309 | AA14: 0 | AB14: 8763.5358
A15: 13 | C15: 经营二组 | D15: 赵宇瑄 | E15: 12500 | F15: =E15/12 -> 1041.6667 | G15: 353.934 | H15: \ | I15: 11742.348 | J15: \ | K15: 3100 | L15: =K15/12 -> 258.33333 | M15: 263.71681 | N15: \ | O15: 2562.7775 | P15: 0.47902256 | Q15: 0 | R15: 195.96903 | S15: 2562.7775 | T15: 249.03153 | U15: =T15*0.7/12 -> 14.526839 | V15: 0 | W15: =V15/U15 -> 0 | X15: 38.555993 | Y15: 0.34945984 | Z15: 35.721 | AA15: =AB15-X15 -> 6619.8189 | AB15: 6658.3749
A16: 14 | D16: 合计 | E16: 12500 | F16: =E16/12 -> 1041.6667 | G16: =SUM(G15) -> 353.934 | H16: =G16/F16 -> 0.33977664 | I16: =SUM(I15) -> 11742.348 | J16: =I16/E16 -> 0.93938785 | K16: 3100 | L16: =K16/12 -> 258.33333 | M16: =SUM(M15) -> 263.71681 | N16: =M16/L16 -> 1.0208393 | O16: 2562.7775 | P16: =O16/K16 -> 0.82670243 | Q16: =SUM(Q15) -> 0 | R16: 195.96903 | S16: 2562.7775 | T16: 249.03153 | U16: =T16*0.7/12 -> 14.526839 | V16: 0 | W16: =V16/U16 -> 0 | X16: 38.555993 | Y16: =X16/T16 -> 0.15482374 | Z16: 35.721 | AA16: 0 | AB16: 6658.3749
A17: 15 | C17: 小计 | E17: =SUM(E14,E16) -> 31000 | F17: =E17/12 -> 2583.3333 | G17: =SUM(G14,G16) -> 353.934 | H17: =G17/F17 -> 0.13700671 | I17: =SUM(I14,I16) -> 28950.338 | J17: =I17/E17 -> 0.93388186 | K17: =SUM(K14,K16) -> 21500 | L17: =K17/12 -> 1791.6667 | M17: =SUM(M14,M16) -> 263.71681 | N17: =M17/L17 -> 0.14719078 | O17: =SUM(O14,O16) -> 18696.171 | P17: =O17/K17 -> 0.86958933 | Q17: =SUM(Q14,Q16) -> 0 | R17: =SUM(R14,R16) -> 342.58407 | S17: 18696.171 | T17: 1146.3625 | U17: =T17*0.7/12 -> 66.871146 | V17: =SUM(V14,V16) -> 0 | W17: =V17/U17 -> 0 | X17: 156.55194 | Y17: =X17/T17 -> 0.13656408 | Z17: 51.03 | AA17: =AB17-X17 -> 15265.359 | AB17: =SUM(AB14,AB16) -> 15421.911
A18: 17 | C18: 福州经营小组 | D18: 申星 | E18: \ | F18: \ | G18: 0 | H18: \ | I18: 1600.2133 | J18: \ | K18: \ | L18: \ | M18: 0 | N18: 14.450973 | O18: 1585.7928 | P18: \ | Q18: 20.141531 | R18: 1585.7928 | S18: 1585.7928 | T18: 657.18179 | U18: =T18*0.7/12 -> 38.335605 | V18: 0 | W18: =V18/U18 -> 0 | X18: 546.84429 | Y18: 0.59244534 | Z18: 73.5 | AA18: =AB18-X18 -> 1504.3496 | AB18: 2051.1939
A19: 18 | D19: 陆顺 | E19: \ | F19: \ | G19: 0 | H19: \ | I19: 854.6088 | J19: \ | K19: \ | L19: \ | M19: 0 | N19: \ | O19: 611.93837 | P19: \ | Q19: 0 | R19: 355.93699 | S19: 611.93837 | T19: 799.286 | U19: =T19*0.7/12 -> 46.625017 | V19: 0 | W19: =V19/U19 -> 0 | X19: 668.9325 | Y19: 0.56222703 | Z19: 0 | AA19: =AB19-X19 -> 343.21175 | AB19: 1012.1442
A20: 19 | D20: 合计 | E20: 5500 | F20: =E20/12 -> 458.33333 | G20: 0 | H20: =G20/F20 -> 0 | I20: =SUM(I18:I19) -> 2454.8221 | J20: =I20/E20 -> 0.44633129 | K20: 4500 | L20: =K20/12 -> 375 | M20: =SUM(M18:M19) -> 0 | N20: =M20/L20 -> 0 | O20: =SUM(O18:O19) -> 2197.7312 | P20: =O20/K20 -> 0.48838471 | Q20: =SUM(Q18:Q19) -> 20.141531 | R20: =SUM(R18:R19) -> 1941.7298 | S20: 2197.7312 | T20: 1456.4678 | U20: =SUM(U18:U19) -> 84.960621 | V20: =SUM(V18:V19) -> 0 | W20: =V20/U20 -> 0 | X20: 1215.7768 | Y20: =X20/T20 -> 0.83474334 | Z20: 73.5 | AA20: =SUM(AA18:AA19) -> 1847.5614 | AB20: 3063.3381
A21: 20 | C21: 厦门经营小组 | D21: 李汝 | E21: \ | F21: \ | G21: 0 | H21: \ | I21: 276.004 | J21: \ | K21: \ | L21: \ | M21: 0 | N21: \ | O21: 1719.0107 | P21: \ | Q21: 110.61947 | R21: =157.7168138+Q21 -> 268.33628 | S21: 1719.0107 | T21: \ | U21: \ | V21: \ | W21: \ | X21: \ | Y21: \ | Z21: 0 | AA21: 0 | AB21: 903.22111
A22: 21 | D22: 周斌 | E22: \ | F22: \ | G22: 0 | H22: \ | I22: 1055.6 | J22: \ | K22: \ | L22: \ | M22: 0 | N22: \ | O22: 478.01778 | P22: \ | Q22: 0 | R22: 0 | S22: 478.01778 | T22: 745.9233 | U22: =T22*0.7/12 -> 43.512192 | V22: 0 | W22: =V22/U22 -> 0 | X22: 635.5858 | Y22: 0.64093158 | Z22: 0 | AA22: =AB22-X22 -> 199.32126 | AB22: 834.90706
A23: 22 | D23: 刘江斌 | E23: \ | F23: \ | G23: 0 | H23: \ | I23: 27.216 | J23: \ | K23: \ | L23: \ | M23: 0 | N23: \ | O23: 0 | P23: \ | Q23: 0 | R23: 0 | S23: 0 | T23: \ | U23: \ | V23: \ | W23: \ | X23: \ | Y23: \ | Z23: 0 | AA23: \ | AB23: 0
A24: 23 | D24: 合计 | E24: 7500 | F24: =E24/12 -> 625 | G24: 0 | H24: =G24/F24 -> 0 | I24: =SUM(I21:I23) -> 1358.82 | J24: =I24/E24 -> 0.181176 | K24: 5000 | L24: =K24/12 -> 416.66667 | M24: =SUM(M21:M23) -> 0 | N24: =M24/L24 -> 0 | O24: =SUM(O21:O23) -> 2197.0285 | P24: =O24/K24 -> 0.43940571 | Q24: =SUM(Q21:Q23) -> 110.61947 | R24: =SUM(R21:R23) -> 268.33628 | S24: =SUM(S21:S23) -> 2197.0285 | T24: 745.9233 | U24: =SUM(U21:U23) -> 43.512192 | V24: 0 | W24: =V24/U24 -> 0 | X24: 635.5858 | Y24: =X24/T24 -> 0.85207929 | Z24: 0 | AA24: =SUM(AA21:AA23) -> 199.32126 | AB24: 1738.1282
A25: 24 | C25: 小计 | E25: =SUM(E20,E24) -> 13000 | F25: =E25/12 -> 1083.3333 | G25: 0 | H25: =G25/F25 -> 0 | I25: =SUM(I20,I24) -> 3813.6421 | J25: =I25/E25 -> 0.29335708 | K25: =SUM(K20,K24) -> 9500 | L25: =K25/12 -> 791.66667 | M25: =SUM(M20,M24) -> 0 | N25: =M25/L25 -> 0 | O25: =SUM(O20,O24) -> 4394.7597 | P25: =O25/K25 -> 0.46260629 | Q25: =SUM(Q20,Q24) -> 130.761 | R25: =SUM(R20,R24) -> 2210.0661 | S25: =SUM(S20,S24) -> 4394.7597 | T25: 2202.3911 | U25: =SUM(U24,U20) -> 128.47281 | V25: 0 | W25: =V25/U25 -> 0 | X25: 1851.3626 | Y25: =X25/T25 -> 0.84061482 | Z25: 73.5 | AA25: =SUM(AA24,AA20) -> 2046.8826 | AB25: 4801.4663
A26: 25 | C26: 南昌经营小组 | D26: 陈浩 | E26: \ | F26: \ | G26: 914.9 | H26: \ | I26: 5854.292 | J26: \ | K26: \ | L26: \ | M26: 0 | N26: \ | O26: 3625.7623 | P26: \ | Q26: 1118.3186 | R26: 3625.7623 | S26: 3625.7623 | T26: 1871.361 | U26: =T26*0.7/12 -> 109.16272 | V26: 0 | W26: =V26/U26 -> 0 | X26: 1121.97 | Y26: 0.4169575 | Z26: 105 | AA26: =AB26-X26 -> 2710.8748 | AB26: 3832.8448
A27: 27 | D27: 合计 | E27: 6500 | F27: =E27/12 -> 541.66667 | G27: 914.9 | H27: =G27/F27 -> 1.6890462 | I27: =SUM(I26:I26) -> 5854.292 | J27: =I27/E27 -> 0.90066031 | K27: 3300 | L27: =K27/12 -> 275 | M27: =SUM(M26:M26) -> 0 | N27: =M27/L27 -> 0 | O27: 3625.7623 | P27: =O27/K27 -> 1.0987158 | Q27: =SUM(Q26:Q26) -> 1118.3186 | R27: 2507.4437 | S27: 3625.7623 | T27: 1871.361 | U27: =SUM(U26:U26) -> 109.16272 | V27: 0 | W27: =V27/U27 -> 0 | X27: 1121.97 | Y27: =SUM(Y26:Y26) -> 0.4169575 | Z27: 105 | AA27: 0 | AB27: 3832.8448
A28: 28 | C28: 九江经营小组 | D28: 杨志胜 | E28: \ | F28: \ | G28: 0 | H28: \ | I28: 54 | J28: \ | K28: \ | L28: \ | M28: 0 | N28: \ | O28: 20.714341 | P28: \ | Q28: 0 | R28: 0 | S28: 20.714341 | T28: 2109.4849 | U28: =T28*0.7/12 -> 123.05328 | V28: 0 | W28: =V28/U28 -> 0 | X28: 1493.3325 | Y28: 0.29527652 | Z28: 26.706 | AA28: =AB28-X28 -> 644.65685 | AB28: 2137.9893
A29: 29 | D29: 合计 | E29: 4500 | F29: =E29/12 -> 375 | G29: 0 | H29: =G29/F29 -> 0 | I29: =SUM(I28) -> 54 | J29: =I29/E29 -> 0.012 | K29: 700 | L29: =K29/12 -> 58.333333 | M29: =SUM(M28) -> 0 | N29: =M29/L29 -> 0 | O29: =S29-R29 -> 20.714341 | P29: =O29/K29 -> 0.029591916 | Q29: =SUM(Q28) -> 0 | R29: 0 | S29: 20.714341 | T29: 2109.4849 | U29: =SUM(U28:U28) -> 123.05328 | V29: 17.748 | W29: =V29/U29 -> 0.1442302 | X29: 1493.3325 | Y29: 0.15926803 | Z29: 26.706 | AA29: =AB29-X29 -> 644.65685 | AB29: 2137.9893
A30: 31 | C30: 小计 | E30: =SUM(E27,E29) -> 11000 | F30: =E30/12 -> 916.66667 | G30: =SUM(G27,G29) -> 914.9 | H30: =G30/F30 -> 0.99807273 | I30: =SUM(I27,I29) -> 5908.292 | J30: =I30/E30 -> 0.53711745 | K30: 4000 | L30: =K30/12 -> 333.33333 | M30: =SUM(M27,M29) -> 0 | N30: =M30/L30 -> 0 | O30: =SUM(O27,O29) -> 3646.4766 | P30: =O30/K30 -> 0.91161916 | Q30: =SUM(Q27,Q29) -> 1118.3186 | R30: =SUM(R27,R29) -> 2507.4437 | S30: 3646.4766 | T30: 3980.8459 | U30: =SUM(U27,U29) -> 232.21601 | V30: =SUM(V27,V29) -> 17.748 | W30: =V30/U30 -> 0.076428839 | X30: 2615.3025 | Y30: =X30/T30 -> 0.65697155 | Z30: 131.706 | AA30: 281.992 | AB30: =SUM(AB27,AB29) -> 5970.8341
A31: 32 | C31: 总计 | E31: =SUM(E12,E17,E25,E30) -> 100000 | F31: =E31/12 -> 8333.3333 | G31: =SUM(G12,G17,G25,G30) -> 4348.522 | H31: =G31/F31 -> 0.52182264 | I31: =SUM(I12,I17,I25,I30) -> 56111.948 | J31: =I31/E31 -> 0.56111948 | K31: 50000 | L31: =K31/12 -> 4166.6667 | M31: =SUM(M12,M17,M25,M30) -> 263.71681 | N31: =M31/L31 -> 0.063292035 | O31: =SUM(O12,O17,O25,O30) -> 39956.158 | P31: =O31/K31 -> 0.79912316 | Q31: =SUM(Q12,Q17,Q25,Q30) -> 1793.5672 | R31: =SUM(R12,R17,R25,R30) -> 7267.7992 | S31: 39956.158 | T31: 15771.892 | U31: =T31*0.7/12 -> 920.02701 | V31: =SUM(V12,V17,V25,V30) -> 17.748 | W31: =V31/U31 -> 0.019290738 | X31: 10018.706 | Y31: =X31/T31 -> 0.6352254 | Z31: 1554.1424 | AA31: =AB31-X31 -> 48352.963 | AB31: =SUM(AB12,AB17,AB25,AB30) -> 58371.669
J35: =I31/80000 -> 0.70139936

Sheet Sheet6
A3: 责任人 | B3: 求和项:金额
A4: 陈浩 | B4: 25074437
A5: 段靖宗 | B5: 65927644
A6: 李汝 | B6: 16083913
A7: 刘新峥 | B7: 6253097.3
A8: 陆顺 | B8: 6119383.7
A9: 穆华清 | B9: 1.6122044e+08
A10: 申星 | B10: 15414543
A11: 沈腾飞 | B11: 7593238.9
A12: 唐作栋 | B12: 28254705
A13: 万赛 | B13: 14388282
A14: 杨志胜 | B14: 207143.41
A15: 袁志凌 | B15: 4325663.7
... A19: 总计 | B19: 3.7836845e+08

Sheet Sheet4
A1: 5000 | B1: 0 | C1: 0 | D1: 0 | E1: 0 | F1: 0 | G1: 0 | H1: 0 | I1: 0 | J1: 0 | K1: 0 | L1: 0 | M1: 0 | N1: 0 | O1: 0 | P1: 0
A2: 3800 | B2: 0 | C2: 2283 | D2: =C2/A2 -> 0.60078947 | E2: 2000 | F2: 0 | G2: 1964 | H2: =G2/E2 -> 0.982 | I2: 1964 | J2: 1964 | K2: 0 | L2: 0 | M2: 0 | N2: 0 | O2: 0 | P2: 1925
A4: =SUM(A1:A2) -> 8800 | B4: =SUM(B1:B2) -> 0 | C4: =SUM(C1:C2) -> 2283 | D4: =C4/A4 -> 0.25943182 | E4: =SUM(E1:E2) -> 2000 | F4: =SUM(F1:F2) -> 0 | G4: =SUM(G1:G2) -> 1964 | H4: =G4/E4 -> 0.982 | I4: =SUM(I1:I2) -> 1964 | J4: =SUM(J1:J2) -> 1964 | K4: =SUM(K1:K2) -> 0 | L4: =SUM(L1:L2) -> 0 | M4: =SUM(M1:M2) -> 0 | N4: =SUM(N1:N2) -> 0 | O4: =SUM(O1:O2) -> 0 | P4: =SUM(P1:P2) -> 1925
A6: 22500 | B6: 0 | C6: 990 | D6: 0.044 | E6: 8700 | F6: 0 | G6: 10044 | H6: 1.154 | I6: 458 | J6: 10044 | K6: 7609 | L6: 0 | M6: 4947 | N6: 0.65 | O6: 0 | P6: 16846
A7: 22500 | B7: 0 | C7: 13180 | D7: 0.586 | E7: 8700 | F7: 0 | G7: 2631 | H7: 0.302 | I7: 974 | J7: 2631 | K7: 833 | L7: 0 | M7: 449 | N7: 0.539 | O7: 0 | P7: 14096
A8: 45000 | B8: 0 | C8: 14170 | D8: 0.315 | E8: 17400 | F8: 0 | G8: 12674 | H8: 0.728 | I8: 1432 | J8: 12674 | K8: 8442 | L8: 0 | M8: 5395 | N8: 0.639 | O8: 0 | P8: 30931
A9: 18500 | B9: 0 | C9: 17208 | D9: 0.93 | E9: 16500 | F9: 11 | G9: 16133 | H9: 0.978 | I9: 147 | J9: 16133 | K9: 897 | L9: 15 | M9: 90 | N9: 0.1 | O9: 0 | P9: 8720
A10: 12500 | B10: 0 | C10: 11388 | D10: 0.911 | E10: 5000 | F10: 26 | G10: 2299 | H10: 0.46 | I10: 196 | J10: 2299 | K10: 249 | L10: 0 | M10: 27 | N10: 0.107 | O10: 0 | P10: 6611
A11: 31000 | B11: 0 | C11: 28596 | D11: 0.922 | E11: 21500 | F11: 38 | G11: 18432 | H11: 0.857 | I11: 343 | J11: 18432 | K11: 1146 | L11: 15 | M11: 117 | N11: 0.102 | O11: 0 | P11: 15331
