Workbook

Sheet exportReport
A1: 最后修改时间 | B1: 创建时间 | C1: 项目编号 | D1: 项目名称 | E1: 扣分原因 | F1: 项目概况 | G1: 隧道情况 | H1: 行业分类 | I1: 产品事业部 | J1: 承揽主办方 | K1: 承揽协办方1 | L1: 项目所在省份 | M1: 投资规模（亿元） | N1: 业主单位 | O1: 设计单位 | P1: 施工单位 | Q1: 设备需求预测（产品类型-数量-预计需求时间） | R1: 预计签约日期 | S1: 预计成交金额（元） | T1: 项目经理 | U1: 项目经理2 | V1: 项目详细阶段 | W1: 跟进具体情况描述 | X1: 下一步工作计划 | Y1: 项目阶段 | Z1: 已完成工作与成效 | AA1: 信息等级 | AB1: 所有人 | AC1: 取消跟进原因 | AD1: 取消跟进说明 | AE1: 创建人 | AF1: 目前状态 | AG1: 最后修改人
A2: 46120 | B2: 2025-09-01 08:32:50 | C2: XM-2025090120213 | D2: 浙江物产DZ622盾构机维修改造项目 | F2: 浙江物产工服DZ622盾构机维修改造，更换主轴承、新制刀盘、二级维修 | G2: 区间长度1205m | H2: 地铁-5 | I2: 掘进机事业部 | J2: 华东区域 | K2: 华南区域 | L2: 浙江 | M2: 5.0000000000 | N2: 浙江物产工程技术服务有限公司 | P2: 浙江物产工程技术服务有限公司 | Q2: ZTE6410-1-(2025-12-20); | R2: 2025-12-10 | S2: CNY 5,900,000.000 | T2: 唐作栋 | W2: 已完成洽谈，合同总价590万，已签订定购函 | X2: 2026年4月完成合同签订 | Y2: 合同评审 | Z2: 已完成洽谈，合同总价590万，已签订定购函 | AA2: 一般信息（Ⅲ级） | AB2: 唐作栋 | AE2: 唐作栋 | AF2: 跟进中 | AG2: 唐作栋
A3: 46114 | B3: 2021-03-22 16:17:32 | C3: XM-202103225487 | D3: 浙江金华金武永东轨道交通项目 | F3: 金武永东市域铁路预计总投资435.2亿元，线路全长111.7公里，其中地下线长约32.9公里，占比29.5%，位于金华市、武义县、永康市的中心城区和在建横店机场、横店镇；高架线及过渡段长约72.4公里，山岭隧道线长约6.4公里。全线设站26座，其中地下站14座，高架站12座。换乘站4座，平均站间距约4.5公里。 | G3: 地下线长约32.9公里 | H3: 地铁-5 | I3: 掘进机事业部 | J3: 华东区域 | K3: 华东区域 | L3: 浙江 | M3: 435.2000000000 | N3: 金华市轨道交通集团有限公司 | O3: 北京城建院 | Q3: 土压平衡盾构机-4-(/); | R3: 2027-10-30 | S3: CNY 40,000,000.000 | T3: 万赛 | U3: 万赛 | V3: 定测及初步设计阶段 | W3: 目前业主及设计单位正在准备报批工作 | X3: 持续跟进项目进展情况 | Y3: 定测及初步设计阶段 | Z3: 1、核心问题：目前项目项目还未获批； 2、工作思路：等项目获批后，与设计院及业主、施工单位开展拜访、技术交流等工作； 3、关键点：跟踪项目审批、招标等时间节点，确定设备需求型号； 4、行动计划：时刻保持与客户的联系，配合各施工单位投标工作。 | AA3: 重点信息（Ⅱ级） | AB3: 唐作栋 | AE3: 接口专用帐号 | AF3: 跟进中 | AG3: 万赛
A4: 46113 | B4: 2024-12-31 10:27:46 | C4: XM-2024123118565 | D4: 义龙庆高速公路义乌至龙泉段（金华段）▲ | F4: 全长约105.5公里，采用双向四/六车道高速公路标准，设计速度120km/h | G4: 桥隧比83% | H4: 公路-4 | I4: 特种装备事业部 | J4: 华东区域 | L4: 浙江 | M4: 372.2000000000 | N4: 浙江金华义龙庆高速公路有限公司 | R4: 2026-04-30 | S4: CNY 8,000,000.000 | T4: 万赛 | V4: 设备招标阶段 | W4: 施工已中标，一共九个标段，1公里以上的隧道要求上全电脑三臂凿岩台车，落实目前2标、3标、7标、9标有全电脑三臂凿岩台车需求，按照标书文件要求4个标段分别需要4台设备，合计16台；3标重新招标后，中标单位11月已公示，为浙江交工宏途，正式施工合同近期会完成签订。1月份跟踪各标段情况如下：9标劳务已经确定，设备需求第一台设备计划进展时间是2026年4月1日，目前正在和劳务老板洽谈中；2标、3标、7标目前劳务队还没有确定，预计年后才能完成招标，设备需求等劳务队确认后才能订设备。 | X4: 完成与2标、3标等各标段项目部及施工单位技术交流，劳务老板对接，设备需求时间确认等工作。 | Y4: 项目施工中标公示 | Z4: 9月份已完成与浙高建领导的拜访及交流，同时义龙庆汪副指挥长一同参会，计划国庆节后浙高建领导会组织去我司考察；12月份邀请指挥部及各大机施工项目经理到我司考察交流。 | AA4: 重点信息（Ⅱ级） | AB4: 万赛 | AE4: 万赛 | AF4: 跟进中 | AG4: 万赛
A5: 46113 | B5: 2022-03-30 11:56:51 | C5: XM-2022033010131 | D5: 杭州下沙至嘉兴长安城际铁路 | F5: 本项目线路总体由南向北,由杭州地铁1号线文海南路站引出，自浙江钱塘区下沙街道经海宁高新区至长安镇区，终点杭海城际铁路长安站。项目线路全长约20公里，暂定设车站7座（另预留1座），包含地上、地下车站，最高运行速度120km/h，隨道长度5.10公里，2区间 | G5: 隨道长度5.10公里，2区间 | H5: 轨道交通 | I5: 掘进机研发运营中心 | J5: 华东区域 | L5: 浙江 | M5: 96.8500000000 | N5: 海宁市轨道交通投资建设有限公司 | Q5: 土压平衡盾构机-4-(/); | R5: 2026-06-30 | S5: CNY 15,000,000.000 | T5: 唐作栋 | W5: 剩余1个地下段SG-2标暂未招标，目前已有消息项目内定给中铁十八局市政公司 | X5: 1.与十八局了解相关情况 2.配合系统内单位进行地下段投标 | Y5: 施工图设计阶段 | Z5: 剩余1个地下段SG-2标暂未招标，目前已有消息项目内定给中铁十八局市政公司 | AA5: 重点信息（Ⅱ级） | AB5: 唐作栋 | AE5: 唐作栋 | AF5: 跟进中 | AG5: 唐作栋
A6: 46113 | B6: 2021-03-22 16:17:29 | C6: XM-202103225470 | D6: 文一西路西延工程（三期） | F6: 项目西起临余桥东，与现状已建科技大道（临安段）衔接，东至南湖圩堤北6#盾构井，全长约5公里。项目分为快速路系统和地面辅道系统两部分。快速路系统重，地下快速路长约1.77公里，地面快速路长约3.25公里；地面辅道全长约3.76公里。 | G6: 其中地下快速路采用盾构法，长约1.77km，含1.24km 盾构隧道和0.53km 明挖隧道 | H6: 城建 | I6: 掘进机研发运营中心 | J6: 华东区域 | K6: 无部门 | L6: 浙江 | M6: 93.0000000000 | N6: 杭州余杭城市发展投资集团有限公司 | O6: 中国电建集团华东勘测设计研究院有限公司 | Q6: 泥水平衡盾构机-1-(2027-02-01); | R6: 2026-12-31 | S6: CNY 50,000,000.000 | T6: 唐作栋 | U6: 刘新峥 | V6: 定测及初步设计阶段 | W6: 1.中交隧道局中标施工标，我司无可租赁设备 2.中铁十五局横琴项目设备目前闲置，正在对接进行转租或进行维修改造 | X6: 跟进中交隧道局，了解设备需求情况 | Y6: 项目施工中标公示 | Z6: 1.中交隧道局中标施工标，我司无可租赁设备 2.中铁十五局横琴项目设备目前闲置，正在对接进行转租或进行维修改造 | AA6: 重点信息（Ⅱ级） | AB6: 唐作栋 | AE6: 接口专用帐号 | AF6: 跟进中 | AG6: 唐作栋
A7: 46113 | B7: 2024-03-17 00:00:10 | C7: XM-2024031716419 | D7: 杭州站经望江门越江隧道至杭州南站连接线工程 | F7: 望江门隧道是杭州铁路枢纽规划中预留的一条过江通道。北端连接杭州城站，以过江隧道的形式穿过钱塘江，进入滨江区境内，继续以地下隧道的形式向东延伸，经过萧山城区。最终向东可连接机场高铁，连通萧山机场，向南可连至火车南站。线路全长14.74km，其中地下隧道长11.7km,计划2024启动可研编制 | G7: 地下隧道长11.7km | H7: 铁路-2 | I7: 掘进机事业部 | J7: 华东区域 | L7: 浙江 | M7: 100.0000000000 | N7: 杭州铁路枢纽工程建设指挥部 | O7: 中铁第四勘察设计院集团有限公司 | Q7: ZTS13200-3-(2026-12-31); | R7: 2026-12-31 | S7: CNY 100,000,000.000 | T7: 唐作栋 | W7: 铁四院中标望江门隧道建设方案研究，已对接铁四院杭州分院了解相关情况，暂定隧道管片外径12m8 | X7: 1.持续跟进铁四院，了解项目进展 2.4月拜访杭州铁路建设枢纽指挥部，进行大直径盾构技术交流 | Y7: 定测及初步设计阶段 | Z7: 铁四院中标望江门隧道建设方案研究，已对接铁四院杭州分院了解相关情况，暂定隧道管片外径12m8 | AA7: 重点信息（Ⅱ级） | AB7: 唐作栋 | AE7: 唐作栋 | AF7: 跟进中 | AG7: 唐作栋
A8: 46113 | B8: 2024-04-01 17:44:56 | C8: XM-2024040116522 | D8: G2531杭州至上饶高速公路（杭淳开高速公路）（杭州段） | F8: 杭州至上饶高速公路中环至浙赣界（杭淳开高速公路）项目工可推荐方案起点位于富阳区银湖街道六家山村附近与杭州中环相交，起点桩号K0+000，浙江段止于浙江省开化县与江西省德兴市交界处，终点桩号K246+057，路线全长约246km（含千黄高速公路利用段约20km），新建里程约226km。工程总投资约709亿元 | G8: 隧道总长度约76km | H8: 公路-4 | I8: 特种装备事业部 | J8: 华东区域 | L8: 浙江 | M8: 709.0000000000 | N8: 浙江省交通投资集团有限公司 | O8: 浙江数智交院科技股份有限公司 | Q8: ZYS113-4-(2025-06-30); | R8: 2026-03-31 | S8: CNY 30,000,000.000 | T8: 唐作栋 | U8: 刘新峥 | W8: 3月拜访杭淳开高速杭州段建设指挥部及2、3、7、8、10、12标项目部，了解建设指挥部对大机施工设备的要求，桐庐-富阳段3月26日给各项目部宣贯设备要求，淳安段2月底已向各项目部下发设备要求通知。目前各项目部正在与劳务分包签订合同，设备均由劳务队自带。 | X8: 1.从建设指挥部切入，在3km以上长大隧道，推行全电脑三臂凿岩台车 2.与各项目部及分包老板进行设备采购洽谈 | Y8: 施工图设计阶段 | Z8: 3月拜访杭淳开高速杭州段建设指挥部及2、3、7、8、10、12标项目部，了解建设指挥部对大机施工设备的要求，桐庐-富阳段3月26日给各项目部宣贯设备要求，淳安段2月底已向各项目部下发设备要求通知。目前各项目部正在与劳务分包签订合同，设备均由劳务队自带。 | AA8: 重点信息（Ⅱ级） | AB8: 唐作栋 | AE8: 唐作栋 | AF8: 跟进中 | AG8: 唐作栋
A9: 46112 | B9: 2021-03-22 16:17:29 | C9: XM-202103225471 | D9: 漳汕铁路项目 | F9: 1标中铁十一局一公司，门口山隧道5800m 2标中铁十二局二公司，大岭隧道13434m；3标中铁四局五公司，林萍隧道2800m； 4标中铁大桥局六公司，凤山岭隧道1870m。 | G9: / | H9: 铁路 | I9: 特种装备事业部 | J9: 华东区域 | K9: 无部门 | L9: 福建 | M9: 210.0000000000 | N9: 东南沿海铁路福建公司 | O9: 铁二院 | P9: 待定 | R9: 2026-06-30 | S9: CNY 14,000,000.000 | T9: 杨志胜 | V9: 定测及初步设计阶段 | W9: 因施工单价原因，浙江万慧詹总还未确定是否使用大机施工，需求待定。 | X9: 配合经销商继续保持跟进。 | Y9: 商务交流 | Z9: 因施工单价原因，浙江万慧詹总还未确定是否使用大机施工，需求待定。 | AA9: 重点信息（Ⅱ级） | AB9: 杨志胜 | AE9: 接口专用帐号 | AF9: 跟进中 | AG9: 杨志胜
A10: 46112 | B10: 2023-06-04 14:11:20 | C10: XM-2023060413963 | D10: 铅山抽水蓄能项目 | F10: 铅山县高桥抽水蓄能电站位于铅山县境内，电站拟建规模为200～240万千瓦。项目动态投资约200亿元 | G10: 引水洞、交通洞，通风安全洞等 | H10: 水利水电-0 | I10: 掘进机事业部 | J10: 华东区域 | L10: 江西 | M10: 200.0000000000 | N10: 中广核风电有限公司 | O10: 中国电建华东勘测设计院 | P10: 待定 | Q10: 掘进机-1-(/); | R10: 2026-09-30 | S10: CNY 0.000 | T10: 杨志胜 | W10: 本项目原投资主体已退出，11月3日已发布了投资主体优选公告，计划12月底前确定新的投资主体。本项目原投资主体国电投已退出，新的投资人已确定为中广核风电有限公司，项目后续进展待跟进。 | X10: 计划对接中广核风电公司项目负责人。 | Y10: 定测及初步设计阶段 | Z10: 本项目原投资主体已退出，11月3日已发布了投资主体优选公告，计划12月底前确定新的投资主体。本项目原投资主体国电投已退出，新的投资人已确定为中广核风电有限公司，项目后续进展待跟进。 | AA10: 一般信息（Ⅲ级） | AB10: 杨志胜 | AE10: 郭亚楠 | AF10: 跟进中 | AG10: 杨志胜
A11: 46112 | B11: 2023-06-04 15:23:57 | C11: XM-2023060413977 | D11: 遂川抽水蓄能电站 | F11: 进厂交通洞1786m，断面8*8.8，通风安全洞1087m，断面7*6.5，施工支洞共3782m. | G11: 进厂交通洞1786m，断面8*8.8，通风安全洞1087m，断面7*6.5，施工支洞共3782m. | H11: 水利水电-0 | I11: 特种装备事业部 | J11: 华东区域 | L11: 江西 | M11: 110.0000000000 | N11: 江西省投资集团 | O11: 中国电建华东勘测设计院 | P11: 待定 | R11: 2026-09-30 | S11: CNY 0.000 | T11: 杨志胜 | W11: 本项目原投资主体已退出，11月3日已发布了投资主体优选公告，计划12月底前确定新的投资主体。新的投资人确定为江西省投资集团，已拜访江西省投资集团下属峰山抽水蓄能公司朱胜江总和王志刚总，项目预计年底前招先期标。 | X11: 拜访江西省投资集团下属峰山抽蓄公司领导，跟进项目推进计划，开展相关技术交流。 | Y11: 定测及初步设计阶段 | Z11: 已拜访江西省投资集团下属峰山抽水蓄能公司朱胜江总和王志刚总，项目预计年底前招先期标。 | AA11: 一般信息（Ⅲ级） | AB11: 杨志胜 | AE11: 郭亚楠 | AF11: 跟进中 | AG11: 杨志胜
A12: 46112 | B12: 2023-06-04 15:25:58 | C12: XM-2023060413982 | D12: 永新抽水蓄能电站 | F12: 进厂交通洞1485m，断面尺寸8*8.5，通风安全洞1138m，断面尺寸7*6.5，采用钻爆法全断面开挖。自流排水洞4011m,断面3*3，拟采用TBM施工。 | G12: 进厂交通洞1485m，断面尺寸8*8.5，通风安全洞1138m，断面尺寸7*6.5，采用钻爆法全断面开挖。自流排水洞4011m,断面3*3，拟采用TBM施工。 | H12: 水利水电-0 | I12: 掘进机事业部 | J12: 华东区域 | L12: 江西 | M12: 80.0000000000 | N12: 华能（永新）抽水蓄能有限责任公司 | O12: 中国电建华东勘测设计院 | P12: 安能二局 | R12: 2026-06-30 | S12: CNY 0.000 | T12: 杨志胜 | W12: 已对接安能二局市场部杨邑文，安能二局中标筹建期进厂交通洞兼通风安全洞工程，TBM标段暂未招标。本月无最新进展。 | X12: 近期计划拜访永新抽蓄公司范庆龙总，交流钻爆法及盾构机施工。 | Y12: 定测及初步设计阶段 | Z12: 已对接安能二局市场部杨邑文，安能二局中标筹建期进厂交通洞兼通风安全洞工程，TBM标段暂未招标。本月无最新进展。 | AA12: 一般信息（Ⅲ级） | AB12: 杨志胜 | AE12: 郭亚楠 | AF12: 跟进中 | AG12: 杨志胜
A13: 46112 | B13: 2023-06-04 15:28:00 | C13: XM-2023060413978 | D13: 永丰抽水蓄能电站 | F13: 电站总装机容量1200MW（4×300MW）为一等大（1）型工程。枢纽工程主要建筑物由上水库、下水库、输水系统、地下厂房和开关站等组成。 | G13: / | H13: 水利水电-0 | I13: 特种装备事业部 | J13: 华东区域 | L13: 江西 | M13: 80.0000000000 | N13: 江西华电抽水蓄能有限公司 | O13: 中国电建集团华东勘测设计研究院有限公司 | P13: 待定 | R13: 2026-12-31 | S13: CNY 0.000 | T13: 杨志胜 | W13: 2025年3月，水电水利规划设计总院主持评审，预可研通过，同意1200兆瓦方案。现处于可研阶段。暂无明确推进计划。 | X13: 1、对接华东院，了解项目概况及关键信息。 2、对接股份赣南中心，了解系统内单位跟进情况。 | Y13: 项目立项阶段（预可研，初测及可研，环评） | Z13: 已通过铁建赣南经营中心了解项目进展，属于中远期项目，保持关注。 | AA13: 一般信息（Ⅲ级） | AB13: 杨志胜 | AE13: 郭亚楠 | AF13: 跟进中 | AG13: 杨志胜
A14: 46112 | B14: 2024-04-29 14:12:35 | C14: XM-2024042916696 | D14: 厦门钨业武宁县大湖塘北区钨矿20000t/d采选工程 | F14: 现有生产系统为地下开采，平硐开拓，留矿法采矿。本次矿山建设开采方式为露天开采。建设规模：采选矿规模为20000t/d。 | G14: / | H14: 非煤矿山-11 | I14: 矿山装备事业部 | J14: 华东区域 | L14: 江西 | M14: 50.0000000000 | N14: 厦门钨业（江西巨通实业） | O14: 中国瑞林 | P14: 待定 | Q14: 廊道皮带机-1-(/); | R14: 2026-12-31 | S14: CNY 0.000 | T14: 杨志胜 | W14: 因矿区发现了稀土储量，该项目暂时停滞，后续推进计划暂不明确。该项目重新纳入了江西省2026年预备开工项目。 | X14: 计划近期拜访中国瑞林门总，了解项目最新进展，适时开展技术交流。 | Y14: 项目立项阶段（预可研，初测及可研，环评） | Z14: 前期拜访了中国瑞林矿山事业部门总，因矿区发现了稀土储量，该项目暂时停滞，后续推进计划暂不明确。现该项目重新纳入了江西省2026年预备开工项目。 | AA14: 一般信息（Ⅲ级） | AB14: 杨志胜 | AE14: 郭亚楠 | AF14: 跟进中 | AG14: 杨志胜
A15: 46112 | B15: 2025-05-30 22:27:47 | C15: XM-2025053019572 | D15: 市域供水联通保障工程（九溪水厂过江通道） | F15: 本项目投资估算 37733.75万元，建设规模 ：本项目建设内容为（1）滨江区与西湖区实现互联互通新建管线，主要为新建供水管道DN1600mm长度约3.2公里，新建供水管DN1200mm长度约1.1公里；（2）新建过江盾构管廊一座内径5.5m，外径6.2m，长度约为1.8公里 。 | G15: 新建过江盾构管廊一座，内径5.5m，外径6.2m， 长度约为1.8公里 | H15: 市政管廊-6 | I15: 掘进机事业部 | J15: 华东区域 | L15: 浙江 | M15: 3.7700000000 | N15: 杭州滨江水务有限公司 | O15: 中国电建集团华东勘测设计研究院有限公司 | P15: 中建三局集团有限公司 | Q15: ZTS6410-1-(2026-12-31); | R15: 2026-12-31 | S15: CNY 9,000,000.000 | T15: 唐作栋 | W15: 中建三局中标施工标，正在对接中建三局了解设备需求情况 | X15: 跟进了解是否有可用设备 | Y15: 项目施工中标公示 | Z15: 中建三局中标施工标，正在对接中建三局了解设备需求情况 | AA15: 一般信息（Ⅲ级） | AB15: 唐作栋 | AE15: 唐作栋 | AF15: 跟进中 | AG15: 唐作栋
A16: 46112 | B16: 2025-03-31 10:42:11 | C16: XM-2025033119073 | D16: 赣州市中心城区供水一体化项目取水及隧洞建设工程（上犹江水资源配置工程） | F16: 骨干引调水线路总长108.6km，其中引水隧洞27.0km、城乡供水输水管道长63.1km、灌溉输水干管长18.5km。引水隧洞拟采用TBM施工。 | G16: 引水隧洞27.0km，采用TBM施工，开挖直径5米。 | H16: 市政管廊-6 | I16: 掘进机事业部 | J16: 华东区域 | L16: 江西 | M16: 58.0000000000 | N16: 赣州市市政公用集团 | O16: 上海市政院 | Q16: ZTT5260-2-(/);ZTE5260-2-(/); | R16: 2026-09-30 | S16: CNY 100,000,000.000 | T16: 杨志胜 | W16: 引水隧洞27公里，采用TBM施工，开挖直径5米。项目业主单位调整为赣州市市政公用集团，计划2026年6月份启动招标，系统内11局、18局、14局均在跟进。已对接赣州市水务集团和上海市政院，并为设计院提供了TBM和盾构机选型建议及专家。 | X16: 1、协同18局隧道公司对接业主单位赣州市水务集团； 2、拜访上海市政院，交流TBM施工。 3、参加业主和设计院组织的设备选型专家评审会。 | Y16: 项目立项阶段（预可研，初测及可研，环评） | Z16: 已对接赣州市水务集团和上海市政院，并为设计院提供了TBM和盾构机选型建议及专家。 | AA16: 重点信息（Ⅱ级） | AB16: 杨志胜 | AE16: 杨志胜 | AF16: 跟进中 | AG16: 杨志胜
A17: 46112 | B17: 2024-12-30 19:58:12 | C17: XM-2024123018582 | D17: 浙江特高压交流环网嘉兴-宁波段跨越钱塘江输电工程GIL管廊 | F17: 项目处于可研阶段，管廊长度约4.9km，采用11m6管片外径泥水平衡盾构机施工 | G17: 隧道长度约4.9km，采用11m6管片外径泥水平衡盾构机施工 | H17: 电力-14 | I17: 掘进机事业部 | J17: 华东区域 | L17: 浙江 | M17: 100.0000000000 | N17: 国网浙江省电力有限公司 | O17: 中国电力工程顾问集团华东电力设计院有限公司 | Q17: ZTS12000-1-(/); | R17: 2026-12-31 | S17: CNY 100,000,000.000 | T17: 唐作栋 | W17: 1.中铁十四局大盾构公司已中标施工标，投标时为保证业绩分，使用海瑞克技术方案投标。 2.已拜访业主单位，业主暂未强制要求使用进口设备或投标厂商设备，国网特高压事业部拟考察国产设备厂商设备。 | X17: 1.与十四局进行对接洽谈，了解十四局拟使用设备情况 2.邀请业主前往我司进行考察 | Y17: 项目施工中标公示 | Z17: 1.中铁十四局大盾构公司已中标施工标，投标时为保证业绩分，使用海瑞克技术方案投标。 2.已拜访业主单位，业主暂未强制要求使用进口设备或投标厂商设备，国网特高压事业部拟考察国产设备厂商设备。 | AA17: 重点信息（Ⅱ级） | AB17: 唐作栋 | AE17: 唐作栋 | AF17: 跟进中 | AG17: 唐作栋
A18: 46112 | B18: 2025-04-27 17:35:04 | C18: XM-2025042719283 | D18: 上饶市广丰区壶峤砂岩矿绿色开发运营一体化项目 | F18: 规划建设生产规模不低于600万吨/年，建设期1年，合作期20年，由中铁十九局和上饶市泽海建材有限公司联合中标，十九局中标金额76.84亿元，由广州公司实施。 | G18: 略 | H18: 非煤矿山-11 | I18: 矿山装备事业部 | J18: 华东区域 | L18: 江西 | M18: 89.0000000000 | N18: 上饶市建广绿色建筑材料有限公司 | P18: 中铁十九局广州公司 | Q18: DG600-YS-1-(/); | R18: 2026-09-30 | S18: CNY 30,000,000.000 | T18: 杨志胜 | W18: 该项目具体由十九局广州公司实施，已拜访了十九局江西经营部贾总和项目经理张洋，计划由联合体成员方上饶市泽海建材负责销售及设备采购。 | X18: 计划近期前往现场拜访项目经理张洋，让其引荐合作方泽海建材，交流设备需求。 | Y18: 商务交流 | Z18: 该项目具体由十九局广州公司实施，已拜访了十九局江西经营部贾总和项目经理张洋，计划由联合体成员方上饶市泽海建材负责销售及设备采购。 | AA18: 一般信息（Ⅲ级） | AB18: 杨志胜 | AE18: 杨志胜 | AF18: 跟进中 | AG18: 杨志胜
A19: 46112 | B19: 2024-12-30 20:10:19 | C19: XM-2024123018564 | D19: 沪昆铁路立交(滨江区段)城市枢纽综合管网工程(江南大道 -信诚路)标段 | F19: 南环路综合管廊(东信大道-信诚路)综合管廊工程，路径总长约2.49km，设计外径8.8m | G19: 路径总长约2.49km，设计外径8.8m | H19: 市政管廊-6 | I19: 掘进机事业部 | J19: 华东区域 | L19: 浙江 | M19: 31.2000000000 | N19: 杭州滨江环境发展有限公司 | O19: 中国电建集团华东勘测设计研究院有限公司 | P19: 中国电建集团华东勘测设计研究院有限公司 | Q19: ZTE9100-1-(/); | R19: 2026-12-31 | S19: CNY 22,780,000.000 | T19: 唐作栋 | W19: 业主在2025年已上报项目财政计划并已获得批复，2026年年度投资已落实，年度任务已完成，因此对于项目招标及进度并不是很着急，项目招标时间可能延后至春节后 | X19: 4月30日前拜访中铁十八局、十六局杭州经营部了解项目跟进情况及后续计划安排 | Y19: 项目施工招标阶段 | Z19: 业主在2025年已上报项目财政计划并已获得批复，2026年年度投资已落实，年度任务已完成，因此对于项目招标及进度并不是很着急，项目招标时间可能延后至春节后 | AA19: 一般信息（Ⅲ级） | AB19: 唐作栋 | AE19: 唐作栋 | AF19: 跟进中 | AG19: 唐作栋
A20: 46112 | B20: 2025-06-28 14:14:37 | C20: XM-2025062819740 | D20: 江西漂塘钨业液压掘进台车采购需求 | F20: 江钨集团漂塘钨业计划采购1台液压掘进台车。 | G20: 略 | H20: 非煤矿山-11 | I20: 特种装备事业部 | J20: 华东区域 | L20: 江西 | M20: 10.0000000000 | N20: 江西漂塘钨业有限公司 | Q20: CYDJ45(D)-1-(/); | R20: 2025-12-31 | S20: CNY 1,190,000.000 | T20: 杨志胜 | W20: 我司提供了方案报价，但设备无法满足现场工况要求，最终客户选择采购五新装备的设备，采购价114万。 | X20: 无下一步计划。 | Y20: 设备未中标 | Z20: 供销公司已完成供应商准入的审查，我司已进入合格供应商名录。同时提供了设备技术方案及报价。 | AA20: 一般信息（Ⅲ级） | AB20: 杨志胜 | AE20: 杨志胜 | AF20: 跟进中 | AG20: 杨志胜
A21: 46112 | B21: 2025-05-30 22:36:59 | C21: XM-2025053019573 | D21: 舟山市百兆瓦潮流能发电机组并网示范项目 | F21: 舟山市百兆瓦潮流能发电机组并网示范项目，开展发电机组关键部件的制造工艺技术研究，本项目的大型结构件主要包括塔筒、基座、艇舱及端盖、总成平台等，其特点是大尺寸（单件超过30米）、大重量（单件超过100吨），全焊透Ⅰ级焊缝，并且要求热处理消除焊接应力 | G21: 无 | H21: 水利水电-0 | I21: 特种装备事业部 | J21: 华东区域 | L21: 浙江 | M21: 25.0000000000 | N21: 中铁建发展集团有限公司 | O21: 中铁第四勘察设计院集团有限公司 | Q21: 总成平台基座-40-(/); | R21: 2026-06-30 | S21: CNY 300,000,000.000 | T21: 唐作栋 | W21: 1.戴董事长拟前往发展集团考察调研，由发展集团做本项目的专项汇报后进行下一步推进，但由于时间问题，董事长暂未前往考察 2.林东新能源还在与国家能源局就并网补贴进行洽谈，目前洽谈价格为1.6元 3.暂无最新进展 | X21: 股份公司决策存在阻力，发展集团还在争取获得股份公司批准 跟进了解相关进展 | Y21: 项目立项阶段（预可研，初测及可研，环评） | Z21: 1.已完成股份公司专家评审会 | AA21: 重点信息（Ⅱ级） | AB21: 唐作栋 | AE21: 唐作栋 | AF21: 跟进中 | AG21: 唐作栋
A22: 46112 | B22: 2025-07-30 21:51:39 | C22: XM-2025073019964 | D22: 合肥至温州高速公路浙皖界至桐庐段（湖州北段） | F22: 项目起点位于湖州市长兴县泗安镇小界碑村西北侧浙皖交界处，终于与规划德安高速公路安吉昌硕至天荒坪段交叉处，合计约37.915km。全线共设置桥梁约15904m/42座，隧道约2277m/5座，全线桥隧占比约48.0%。沿线共设置枢纽式互通立体交叉1处，一般式互通立体交叉5处，服务区1处（与互通合建） | G22: 隧道约2277m/5座 | H22: 公路-4 | I22: 特种装备事业部 | J22: 华东区域 | L22: 浙江 | M22: 50.0000000000 | N22: 湖州市公路与运输管理中心 | Q22: HZS180-4-(/); | R22: 2026-12-31 | S22: CNY 8,000,000.000 | T22: 唐作栋 | W22: 初步设计项目，暂无最新进展 | X22: 4月30日前，前往数智交院进行交流，整体对初步设计项目进行了解 | Y22: 项目立项阶段（预可研，初测及可研，环评） | Z22: 初步设计项目，已拜访数智交院了解项目情况 | AA22: 一般信息（Ⅲ级） | AB22: 唐作栋 | AE22: 唐作栋 | AF22: 跟进中 | AG22: 唐作栋
A23: 46112 | B23: 2025-07-30 21:54:11 | C23: XM-2025073019965 | D23: 德清至安吉高速公路德清舞阳至安吉昌硕段 | F23: 项目推荐方案全长24.13公里，全线采用高速公路标准、双向六车道，设计速度100公里/小时。全线设枢纽互通立交2处，一般互通立交2处。共布设桥梁8208.79米/17座(含枢纽互通区及分离主线桥)，其中特大桥3293.79米/2座，大桥4465.00米/10座、中桥450.00米/5座；隧道6座，折合双洞全长11815.00米，其中:特长隧道3826.50米/1座，长隧道6835.00米/3座，中隧道870.00米/1座，短隧道283.50米/1座；全线桥隧占比82.97%。沿线设施包括互通收费站2处，路段监控通信分中心1处，桥隧监控通信站1处。 | G23: 隧道6座，折合双洞全长11815.00米 | H23: 公路-4 | I23: 特种装备事业部 | J23: 华东区域 | L23: 浙江 | M23: 80.0000000000 | N23: 安吉德安高速公路有限公司 | O23: 浙江数智交院科技股份有限公司安吉德安高速公路有限公司 | Q23: ZYS113-1-(/); | R23: 2026-12-31 | S23: CNY 8,000,000.000 | T23: 唐作栋 | W23: 项目正在中标公示中，TJ01标：浙江交工集团股份有限公司，TJ02标：中交一公局集团有限公司 | X23: 跟进中标项目单位，了解设备需求情况。 | Y23: 项目施工中标公示 | Z23: 项目正在中标公示中，TJ01标：浙江交工集团股份有限公司，TJ02标：中交一公局集团有限公司 | AA23: 一般信息（Ⅲ级） | AB23: 唐作栋 | AE23: 唐作栋 | AF23: 跟进中 | AG23: 唐作栋
A24: 46112 | B24: 2025-07-30 21:57:25 | C24: XM-2025073019966 | D24: 德清至安吉高速公路德清雷甸至舞阳段 | F24: 本项目推荐方案全长21.7公里，全线设枢纽互通立交2处，一般互通立交3处（含续建的上柏互通），设德清南互通连接线2.08km/1条，采用一级公路标准，设计速度80km/h，双向四车道，路基宽度25.5米。共布设桥梁12座，全长17832.18米（其中连续高架桥长约16.195km）；全线桥梁占比82.17%。沿线设施包括互通收费站2处，管理分中心1处，服务区1处。项目估算总投资约116.9亿元（其中涉铁费用约9亿元），建安费约57.68亿元（不含涉铁段）。 | G24: / | H24: 公路-4 | I24: 特种装备事业部 | J24: 华东区域 | L24: 浙江 | M24: 116.9000000000 | N24: 湖州市公路与运输管理中心 | Q24: HZS180K-2-(/); | R24: 2026-12-31 | S24: CNY 500.000 | T24: 唐作栋 | W24: 已拜访数智交院，项目处于前期设计阶段 | X24: 4月30日前，拜访数智交院项目设计，了解项目进展 | Y24: 项目立项阶段（预可研，初测及可研，环评） | Z24: 已拜访数智交院，项目处于前期设计阶段 | AA24: 一般信息（Ⅲ级） | AB24: 唐作栋 | AE24: 唐作栋 | AF24: 跟进中 | AG24: 唐作栋
A25: 46112 | B25: 2025-07-30 22:00:05 | C25: XM-2025073019967 | D25: S304临平至安吉公路德清县雷甸至舞阳段 | F25: 路线全长约21.3km。涉铁范围总长1290米，其中宁杭高铁、合杭高铁段690米，宣杭铁路段600米。项目拟采用双向六车道和四车道一级公路标准（兼顾城市道路功能），设计速度采用80km/h，整体式路基宽度39m、41m、47m和33.5m。桥梁总长6202.5m/16座，其中特大桥3717.5m/3座，大桥2005m/7座，项目估算总投资约30.3亿元（其中涉铁费用约4亿元），建安费约18.74亿元（不含涉铁段）。 | G25: / | H25: 公路-4 | I25: 特种装备事业部 | J25: 华东区域 | L25: 浙江 | M25: 34.0000000000 | N25: 湖州市公路与运输管理中心 | O25: 浙江数智交院科技股份有限公司 | Q25: HZS180-2-(/); | R25: 2026-12-31 | S25: CNY 5,000,000.000 | T25: 唐作栋 | W25: 已拜访数智交院，项目处于前期设计阶段，无进展 | X25: 4月30日前，拜访数智交院项目设计，了解项目进展 | Y25: 项目立项阶段（预可研，初测及可研，环评） | Z25: 1.已拜访数智交院，项目处于前期设计阶段，无进展 | AA25: 一般信息（Ⅲ级） | AB25: 唐作栋 | AE25: 唐作栋 | AF25: 跟进中 | AG25: 唐作栋
A26: 46112 | B26: 2025-08-31 18:42:24 | C26: XM-2025083120210 | D26: 文二西路提升改造工程 | F26: 项目西起运溪路，东至荆长大道，长约6.7km，工程内容包括新建下穿隧道、地面道路改造、景观品质提升等。新建文二西路隧道长约2.65km，隧道规模为双向四车道。 | G26: 新建文二西路隧道长约2.65km，隧道规模为双向四车道。 | H26: 城建-1 | I26: 掘进机事业部 | J26: 华东区域 | L26: 浙江 | M26: 25.0000000000 | N26: 杭州余杭城市发展投资集团有限公司 | O26: 中交第二公路勘察设计研究院有限公司 | Q26: ZTS11700-1-(/); | R26: 2026-12-31 | S26: CNY 100,000,000.000 | T26: 唐作栋 | W26: 项目已发布招标计划，计划4月底进行施工招标 | X26: 4月15日前拜访业主及各施工单位了解项目情况及后续建设计划 | Y26: 项目施工招标阶段 | Z26: 1.8月27日设计招标已开标， 2.8月29日已公示入围单位。 3.9月24日，中交第二公路勘察设计研究院有限公司中标项目设计 4.3月31日，项目已发布招标计划，计划4月底进行施工招标 | AA26: 一般信息（Ⅲ级） | AB26: 唐作栋 | AE26: 唐作栋 | AF26: 跟进中 | AG26: 唐作栋
A27: 46112 | B27: 2025-08-31 18:57:41 | C27: XM-2025083120211 | D27: 庄河核电厂循环水进水管道与排水管道隧道 | F27: 庄河核电厂一期工程每台机组设置 2 条循环水进水管道(GD)，循环水进水管道(GD)采用现浇钢筋混凝土管道内衬玻璃钢管道，内径尺寸为 4000mm；庄河核电厂一期工程每台机组设置 2 条循环水排水管道(GE)，循环水排水管道(GE)采用现浇钢筋混凝土管道内衬玻璃钢管道，内径尺寸为 4750mm | G27: 庄河核电厂一期工程每台机组设置 2 条循环水进水管道(GD)、 2 条循环水排水管道(GE) | H27: 其他-13 | I27: 掘进机事业部 | J27: 华东区域 | L27: 辽宁 | M27: 3,200.0000000000 | N27: 中核大唐庄河核电有限公司 | O27: 中国核电工程有限公司 | P27: 核工业井巷建设集团有限公司 | Q27: ZTT5500-1-(/);/-1-(/); | R27: 2026-06-30 | S27: CNY 30,000,000.000 | T27: 唐作栋 | W27: 3月已与核工业井巷公司进行两次技术交流，拟就非全断面连续开挖设备技术申报浙江省“尖兵”、“领雁”科研项目，目前正在进行开题报告复核，并在第二批指南中进行申报。 | X27: 核工业井巷公司拟在起其建项目中寻找一个项目，试用我司EBM设备，考察设备实用性及可靠性。 | Y27: 商务交流 | Z27: 3月已与核工业井巷公司进行两次技术交流，拟就非全断面连续开挖设备技术申报浙江省“尖兵”、“领雁”科研项目，目前正在进行开题报告复核，并在第二批指南中进行申报。 | AA27: 一般信息（Ⅲ级） | AB27: 唐作栋 | AE27: 唐作栋 | AF27: 跟进中 | AG27: 唐作栋
A28: 46112 | B28: 2025-09-28 22:31:42 | C28: XM-2025092820433 | D28: 新建上海至杭州高速铁路（沪杭高铁） | F28: 线路起自上海东站，经嘉兴进入杭州市，终至杭州西站，全线运营长度220.9km，新建线路长度182.0km，其中嘉兴境内约100公里，设平湖南、嘉兴南、桐乡三座车站。 | G28: 无隧道 | H28: 铁路-2 | I28: 特种装备事业部 | J28: 华东区域 | L28: 浙江 | M28: 400.0000000000 | N28: 杭州铁路枢纽工程建设指挥部 | O28: 中国铁路设计集团有限公司 | Q28: HZS180K-2-(/); | R28: 2026-06-30 | S28: CNY 5,000,000.000 | T28: 唐作栋 | W28: 1月14日开始施工图审查招标，施工招标26年2季度进行 | X28: 拜访业主单位，了解后续招标计划 | Y28: 项目施工招标阶段 | Z28: 1月14日开始施工图审查招标，施工招标26年2季度进行 | AA28: 一般信息（Ⅲ级） | AB28: 唐作栋 | AE28: 唐作栋 | AF28: 跟进中 | AG28: 唐作栋
A29: 46112 | B29: 2023-08-26 22:48:07 | C29: XM-2023082614800 | D29: 巴东至张家界高速沪蓉沪渝连接线项目 | F29: 巴东至张家界高速沪蓉沪渝连接线（含巴东长江二桥）起于巴东县城北侧与沪蓉高速公路设枢纽互通相接，向南跨长江，经巴东县茶店子镇、秭归县磨坪乡，止于巴东县野三关镇关镇西侧与沪渝高速公路设枢纽互通相接，路线全长约70.596km。巴东城区北互通连接线全长约4km，磨坪互通连接线长约4.3km，两处连接线均按二车道二级公路标准建设。桥梁全长16250m/35座（其中：特大桥6290m/4座，大桥9870m/30座，中桥90m/1座，其中巴东长江公路二桥主桥推荐采用主跨1150m钢箱梁悬索桥）。隧道全长40511m/16座（其中：特长隧道26743m/5座（其中信陵隧道长度10082m），长隧道11610/7座，中隧道1515/2座，短隧道643/2座）。设互通式立交7处（巴东高铁新区互通、溪丘湾枢纽、巴东城区北互通、巴东城区南互通、秭归磨坪互通、野三关北互通、野三关枢纽）、养护工区1处，服务区1处，路段管理分中心1处。技术标准：全线拟采用80km/h设计速度，四车道的高速公路设计标准，路基宽25.5m，长江大桥采用双向六车道标准。本项目估算总金额约为201亿元。 | G29: 隧道全长40511m/16座（其中：特长隧道26743m/5座（其中信陵隧道长度10082m），长隧道11610/7座，中隧道1515/2座，短隧道643/2座）。 | H29: 公路-4 | I29: 特种装备事业部 | J29: 华东区域 | K29: 华中区域 | L29: 湖北 | M29: 201.0000000000 | N29: 湖北交通投资集团有限公司 | Q29: ZY112B-2-(2026-06-01); | R29: 2026-06-30 | S29: CNY 5,000,000.000 | T29: 万赛 | W29: 3月23日从十九华东公司了解到该项目计划6月份启动。 | X29: 持续跟进，了解设备具体需求时间。 | Y29: 项目施工中标公示 | Z29: 1、核心问题：目前还未正式明确所需大机配套设备； 2、工作思路：已经要求客户到我司考察大机配套设备及技术交流； 3、关键点：项目设计还有部分为完成，项目启动资金也还未到位； 4、行动计划：时刻保持与公司及项目部的对接工作，配合该项目做好大机配套方案。 | AA29: 重点信息（Ⅱ级） | AB29: 万赛 | AE29: 万赛 | AF29: 跟进中 | AG29: 万赛
A30: 46112 | B30: 2025-03-28 09:13:07 | C30: XM-2025032819047 | D30: 宁波枢纽建设工程绕城高速改扩建项目 | F30: 起于古中路与绕城高速的交叉点，止于朝阳互通。路线全长9.4km，隧道长度5.2km，其中盾构段长度3.65km，设置2座通风塔。 | G30: 其中盾构段长度3.65km，拟采用16米级盾构机 | H30: 公路-4 | I30: 掘进机事业部 | J30: 华东区域 | L30: 浙江 | M30: 170.0000000000 | N30: 宁波市高等级高速公路建设 | O30: 待定 | P30: 待定 | Q30: 待定-1-(/); | R30: 2028-09-13 | S30: CNY 250,000,000.000 | T30: 沈腾飞 | W30: 目前已对接西枢纽和市铁办建设管理中心一处处长，项目可研阶段，拟采用盾构施工，计划近期拜访宁波西枢纽和市铁办建设管理中心前期处处长，项目规划阶段，拟采用盾构施工，考虑16米盾构方案概率较小，拟高架或明挖。项目规划中，暂无进展 | X30: 拜访业主单位及前期设计单位，梳理项目最新进展。 | Y30: 项目立项阶段（预可研，初测及可研，环评） | Z30: 核心问题：1、采用多大直径盾构机施工方案还未明确；2、最终业主单位还未明确 行动计划：拜访西枢纽管理中心前期规划处领导，了解项目情况，组织方案交流事宜。 | AA30: 重大信息（Ⅰ级） | AB30: 沈腾飞 | AE30: 沈腾飞 | AF30: 跟进中 | AG30: 沈腾飞
A31: 46112 | B31: 2021-10-22 22:28:26 | C31: XM-202110228391 | D31: 宁波至余慈市域（郊）铁路二期 | F31: 全长53.95km，全线新建车站13座，其中余姚段21km | G31: 暂未确定 | H31: 轨道交通 | I31: 掘进机研发运营中心 | J31: 华东区域 | L31: 浙江 | M31: 250.0000000000 | N31: 宁波轨道交通集团 | Q31: ZTE8600-4-(2026-07-22); | R31: 2026-05-13 | S31: CNY 30,000,000.000 | T31: 沈腾飞 | U31: 万赛 | W31: 目前项目未获批，宁象宁慈线盾构设备明年全部贯通，盾构机会用到该项目继续施工。 | X31: 跟进项目工可获批情况，预计2027年获批！ | Y31: 项目立项阶段（预可研，初测及可研，环评） | Z31: 核心问题：隧道施工潜在中标单位中铁工一/二/三/四/隧道局,铁建重工十四/十九局，系统为争取单位：中铁隆/宁波建工/龙元建设。 工作思路：配合系统内单位投标，充分利用供应链公司介入设备租赁 关键点：设备租赁价格8000-9000元/米，价格较低 行动计划：跟踪项目进展，了解区间划分情况。预计2025年启动先行标招标。 | AA31: 一般信息（Ⅲ级） | AB31: 沈腾飞 | AE31: 余广 | AF31: 跟进中 | AG31: 沈腾飞
A32: 46112 | B32: 2023-07-30 11:38:46 | C32: XM-2023073014507 | D32: 甬江流域南排通道工程 | F32: 西线工程总长约57.8公里，主要采用13米级TBM/双模盾构、土压盾构法和钻爆法进行施工。东线工程总长约42.2公里，主要采用13米级土压盾构法、13米级TBM/双模盾构和钻爆法进行施工。此外，全线设计有7口竖井，深度为45米，直径在23米至25米之间，采用竖井掘进机进行施工。 | G32: 隧道长度16km，拟采用9米敞开式TBM施工，主要以2.3类围岩为主，4.5类围岩占比15% | H32: 水利水电-0 | I32: 掘进机事业部 | J32: 华东区域 | L32: 浙江 | M32: 50.0000000000 | N32: 宁波市水库管理中心 | O32: 项目建议书为宁波市水利水电规划设计院 | P32: 待定 | Q32: 8米敞开式TBM-1-(/); | R32: 2026-01-05 | S32: CNY 140,000,000.000 | T32: 沈腾飞 | W32: 1.11月可研挂网招标，预计中标单位浙江水院和宁波水院； 2.宁波将项目列入十五五重点启动项目，前期启动； 3、3月31日已对接8米TBM同步衬砌事宜，节后技术交流。周公宅与亭下之间新建分洪隧洞启动较快 | X32: 1.同宁波水院交流8米TBM掘进衬砌同步技术，竖井布置情况等； 2.拜访浙江省水院设计负责人； 3.邀请宁波水利局到我司或大盾构项目考察。 | Y32: 项目立项阶段（预可研，初测及可研，环评） | Z32: 核心问题：项目建议书阶段，投资200亿元，是否最终获批 工作思路：告知系统内单位，共同跟进，配合项目建议书单位编制项目建议书 关键点：是否采用大盾构/TBM施工方案 行动计划：跟踪项目进展，配合浙江省水院设计院做前期项目建议书。目前项目建议书暂未批复。 | AA32: 重点信息（Ⅱ级） | AB32: 沈腾飞 | AE32: 沈腾飞 | AF32: 跟进中 | AG32: 沈腾飞
A33: 46112 | B33: 2024-10-27 12:47:44 | C33: XM-2024102718062 | D33: 甬金衢上高速公路台州段 | F33: 甬金衢上高速台州段工程路线起点设置仆船隧道内与绍兴段顺接，隧道出口后设置石梁互通及连接线，过后设置天台山1号隧道（分离式左线长9470m），进洞后路线转向西南，出洞后设置桥梁后再次进入隧道，出洞后进入天台盆地，路线继续向西于白鹤镇南端设置白鹤枢纽与上三高速交叉，跨越上三高速和104国道后，于楼外村附近设置互通与104国道相接，之后向西下穿杭绍台高铁，路线向西于上坝头村附近上跨合溪干渠，在王里溪村附近设置平桥互通及连接线与323省道连通，向西沿山脚布线，于合溪口村西侧跨越合溪，向西在杭绍台高速天台街头互通北侧上跨既有杭绍台高速，并设置街头枢纽与杭绍台高速交叉，路线继续向西沿山脚布线在后洋村附近设置街头互通与连接线与323省道连通，路线沿杨家溪南岸，沿峡谷地带靠山侧布线，采用路基为主的方案进入山区，设置庄家岙隧道、寒山湖隧道，至寒山湖隧道内台州与金华交界处与甬金衢上高速金华段顺接，路线全长约46.6km。项目估算总投资约156.7亿元，其中建安费约93.5亿元。本项目设桥梁长约12678米／30座；隧道长约18680米／6座（其中特长隧道2座、长隧道2座）；主线设枢纽2处（白鹤枢纽、街头枢纽）；互通及收费站4处（石梁互通、天台北互通、平桥互通、街头互通）；服务区1处（平桥服务区）；设置隧道管理站2处；共设置石梁互通、平桥互通与街头互通3条连接线。全线采用双向六车道高速公路设计标准，其中起点至白鹤枢纽、街头互通至终点段采用设计速度100km/h，路基宽度33.5m；白鹤枢纽至街头互通段约20km采用设计速度120km/h，路基宽度34.0m。 | G33: 隧道长约18680米／6座（其中特长隧道2座、长隧道2座） | H33: 公路-4 | I33: 特种装备事业部 | J33: 华东区域 | L33: 浙江 | M33: 93.5000000000 | N33: 天台县交通运输局 | O33: 招标中 | P33: 待定 | Q33: HZS1800-2-(2026-06-30); | R33: 2026-07-08 | S33: CNY 3,000,000.000 | T33: 沈腾飞 | W33: 数字交院中标设计，目前设计中，本标段天台县交通局出资30%，省交投出资70%，共计四个标段 2月24日拜访设计院，了解到：因业主资金未到位，设计暂停中。天台交通局暂无资金来源，还要同省交通沟通资金情况。业主同时开展其他资金引入的工作本标段天台县交通局出资30%，省交通出资70%。 | X33: 1.计划4月10日前拜访天台交通局，了解项目进展，标段划分，推荐大机配套 | Y33: 施工图设计阶段 | Z33: 核心问题：1、业主单位是否要求机械化施工；2、拨付机械化施工补贴 工作思路：引导业主单位推广机械化施工 关键点：业主是否愿意出资使用机械化设备。 行动计划：1、筹划拜访业主单位、设计单位，引导机械化施工。 | AA33: 一般信息（Ⅲ级） | AB33: 沈腾飞 | AE33: 沈腾飞 | AF33: 跟进中 | AG33: 沈腾飞
A34: 46112 | B34: 2025-04-28 09:17:32 | C34: XM-2025042819285 | D34: 宁波象山港北岸配水（一期）工程Ⅰ标段 | F34: （1）新建蒋家池头至大嵩水厂引（输）水管线，其中主管线长约 16.9 千米。输水线由蒋家池头调节站始发，向东偏北以顶管（1#管道，长约 221 米）依次下穿莼湖快速路、金溪后，在张家墈转 1#隧洞（长约 4.26 千米）下穿金娥山，在车岭水库南侧山体出洞。再次以顶管（2#管道，长约 659 米）下穿下潘村后，转入 2#隧洞（长约 11.62 千米）穿越横岭山、梅溪，甬绍东天然气管、地铁12号线，在经堂寺南侧山体出洞 | G34: 11.62 千米引水隧道，拟采用4米敞开式TBM | H34: 水利水电-0 | I34: 掘进机事业部 | J34: 华东区域 | L34: 浙江 | M34: 9.0000000000 | N34: 宁波市水利投资有限公司 | O34: 电建华东院 | P34: 广东省建筑工程集团股份有限公司;禹顺生态建设有限公司 | Q34: ZTT4030-1-(2027-01-05); | R34: 2026-05-11 | S34: CNY 30,000,000.000 | T34: 沈腾飞 | W34: 1.10月14日拜访宁波水投工程技术部，项目可研审批中，计划元旦前招标。 2.浙江隧道已中标东西线水库联通工程，设备型号一致，且项目完成业主较认可，中标概率较大。 3.12月11日拜访宁波水投工程主管，项目可研近期批复，预计2026年2-3月招标。 4、1月20日施工招标，2月10日投标截止，目前中铁十八局、十九局业绩满足。 核实设备需求时间为 2026 年 8 月，计划 10—11月实现始发。设备拟由禹顺生态采购 4 米级 TBM，并计划租赁给广东省粤水电用于施工。3 月中旬及下旬，与禹顺生态柴总进行了两次沟通交流，目前主要竞争对手为中铁装备，安徽唐兴、华隧。3 月 28 日已向禹顺生态提交设备报价及配置参数资料。禹顺生态计划于 3 月底组织外部专家对各单位提交的参数方案进行评审，预计 4 月上旬确定设备中标单位。3月30日获悉华隧自有一台设备且带施工，粤水电不参与施工、仅收取管理费，禹顺自负盈亏。粤水电负责项目的设备招采流程（租赁） 3月底客户已告知业主租赁TBM。 | X34: 1、了解租赁招标流程，启动时间等； 2、梳理TBM资源，价格等，再决策是否参与投标 | Y34: 项目施工招标阶段 | Z34: 1.10月14日拜访宁波水投工程技术部，项目可研审批中，计划元旦前招标。 2.浙江隧道已中标东西线水库联通工程，设备型号一致，且项目完成业主较认可，中标概率较大。 3.12月11日拜访宁波水投工程主管，项目可研近期批复，预计2026年2-3月招标。 4、1月20日施工招标，2月10日投标截止，目前中铁十八局、十九局业绩满足。 5.2月11日广东省建筑工程集团股份有限公司;禹顺生态建设有限公司施工中标。6.目前禹顺、金华井巷、粤水电（刘畅）及其他两家民企目前均说需要采购新机，已让研究院欧佳君在做方案，下周一给出配置方案，目前统一TBM口头报价4000万元，最终以事业部给出价格为准。 | AA34: 一般信息（Ⅲ级） | AB34: 沈腾飞 | AE34: 沈腾飞 | AF34: 跟进中 | AG34: 沈腾飞
A35: 46112 | B35: 2024-07-09 16:48:49 | C35: XM-2024070917264 | D35: 乌岩港大桥及接线公路工程 | F35: 乌岩港大桥及接线公路工程项目为二级公路，起点位于鹤浦镇黄岩庄，与石三线十字交叉，沿线途经黄金盘、楼屋、大湾塘、小外湾等村庄，在后龙头村南侧跨越乌岩港进入高塘乡，终点接石三线引桥桥头。路线全长约10.567km，采用双向两车道二级公路标准，设计速度60km/h，路面采用沥青混凝土路面。项目预计于2026年动工开建，计划建设周期36个月。 | G35: 1.77km特大桥。 | H35: 公路-4 | I35: 特种装备事业部 | J35: 华东区域 | L35: 浙江 | M35: 10.0000000000 | N35: 象山县交投 | O35: 宁波市交通规划设计院 | P35: 暂定中铁建大桥局三公司 | Q35: 180-2-(2026-06-30); | R35: 2026-09-01 | S35: CNY 3,000,000.000 | T35: 沈腾飞 | U35: 万赛 | W35: 目前设计阶段，已拜访中铁建大桥局宁波办事处，项目拟需求两套海工180搅拌站，铁建大桥三公司跟踪中标概率较大。目前初步设计暂未获批。因资金未到位，项目推迟到2026年下半年。暂无最新进展 | X35: 跟进并配合系统等潜在中标单位投标。 | Y35: 项目施工招标阶段 | Z35: 核心问题：因桥墩在海中施工，混凝土要求较高，业主采购新设备 工作思路：配合系统内单位投标 关键点：系统内单位中标概率较大，铁建大桥局三公司项目经理业主较认可 行动计划：配合大桥局项目投标，提前沟通搅拌站需求。初步设计暂未获批，资金仍未到位。 | AA35: 一般信息（Ⅲ级） | AB35: 沈腾飞 | AE35: 沈腾飞 | AF35: 跟进中 | AG35: 沈腾飞
A36: 46112 | B36: 2025-06-27 09:01:24 | C36: XM-2025062719731 | D36: 机场路(通途西路-规划空港大道)综合管廊工程 | F36: 机场路(通途西路-规划空港大道)综合管廊工程位于海曙区，北起通途西路管廊预留工作井，南至规划空港大道，全长约9.6公里。管廊规划基本位于道路两侧防护绿带内，标准段采用圆形盾构断面形式(分高压舱和综合舱)，规划预留电力、再生水、给水、压力污水、通信等管位入廊空间。 | G36: 9.6公里，采用ZTE6950盾构机施工 | H36: 市政管廊-6 | I36: 掘进机事业部 | J36: 华东区域 | L36: 浙江 | M36: 11.7500000000 | N36: 宁波城市地下空间投资有限公司 | O36: 宁波建筑设计院 | P36: 宁波建工建乐 | Q36: ZTE6950-2-(/); | R36: 2026-05-13 | S36: CNY 10,000,000.000 | T36: 沈腾飞 | W36: 2025年12月16日中标公示，1标中标单位宁波建工建乐+中铁六局；2标中标单位中铁隧道局，自有改造设备，预计需求时间2026年12月。 | X36: 1.了解宁波建工建乐设备需求时间，设备要求；2.了解盾构分包模式。 | Y36: 设计联络 | Z36: 拜访中铁隧道局及宁波建工建乐，了解设备需求情 | AA36: 一般信息（Ⅲ级） | AB36: 沈腾飞 | AE36: 沈腾飞 | AF36: 跟进中 | AG36: 沈腾飞
A37: 46112 | B37: 2025-06-27 08:55:23 | C37: XM-2025062719730 | D37: 环城南路(联丰中路-世纪大道)综合管廊工程 | F37: 环城南路(联丰中路-世纪大道)综合管廊工程位于海曙区、鄞州区，西起联丰中路，东至世纪大道，全长约13公里。管廊规划基本位于道路两侧防护绿带内，标准段采用圆形盾构断面形式(分高压舱和综合舱)，规划预留电力、再生水、给水、压力污水、通信等管位入廊空间。 项目规模：估算总投资约259492.01万元,其中工程费用约170046.97万元。 | G37: 全长约13公里，采用6.7米土压平衡盾构机掘进 | H37: 市政管廊-6 | I37: 掘进机事业部 | J37: 华东区域 | L37: 浙江 | M37: 17.0000000000 | N37: 宁波城市地下空间投资有限公司 | O37: 上海市政院 | P37: 待定 | Q37: ZTE6950-4-(/); | R37: 2026-04-14 | S37: CNY 10,000,000.000 | T37: 沈腾飞 | W37: 上海市政院中标设计。目前设计中。暂定3个标段，11月6日施工招标审查预公告，11月12日招标资格预审查，12月18日中标结果:中铁二十二局+中铁十局，宁波市政+铁四局，中交水电+中天建设，中天建设施工盾构区间，自有2台海瑞克设备。宁波市政区间长度5km，拟考虑采购一台旧机，3月23日已报价。 | X37: 1.跟踪宁波市政向领导汇报情况，后续再组织设备考察及交流；5月15日前完成 2、了解宁波建工建乐和中铁六局分工情况，4月30日前完成。 | Y37: 设计联络 | Z37: 已拜访业主单位及部分潜在中标设计单位 | AA37: 一般信息（Ⅲ级） | AB37: 沈腾飞 | AE37: 沈腾飞 | AF37: 跟进中 | AG37: 沈腾飞
A38: 46112 | B38: 2023-07-30 11:03:50 | C38: XM-2023073014506 | D38: 台州市中心大道路过江通道 | F38: 台州市椒江城市发展投资集团有限公司投资的世纪大道路过江隧道，隧道长度2.1km，由椒江区投资，项目已立项完成，采用16.3米泥水平衡盾构机。 | G38: 隧道长度2.1km，拟采用16.3米泥水盾构机施工 | H38: 城建-1 | I38: 掘进机事业部 | J38: 华东区域 | L38: 浙江 | M38: 28.0000000000 | N38: 台州市椒江城市发展投资集团有限公司 | O38: 湖南交规院 | P38: 待定 | Q38: 泥水平衡盾构机-1-(2026-12-07); | R38: 2026-12-04 | S38: CNY 200,000,000.000 | T38: 沈腾飞 | W38: 1.2025年6月拜访设计单位及项目专班，交流盾构机选型； 2.跟踪初步审查进展，2025年11月已完成初步审查； 3、资金来源采用专项债，目前到账3亿元，已启动前期道路项目； 4、预计2026年2季度施工招标； 5.隧道延米设计概算42万元/米； 6.目前台州市政府拟改造一桥，项目存在推迟风险，预计2026年下半年施工招标。 | X38: 1.了解代建单位招标时间、招标条件设置、业主资金到位情况等； 2.配合十四局接待业主到海太项目考察。 | Y38: 施工图设计阶段 | Z38: 核心问题：1.设计阶段、施工方暂未明确；2、盾构机区间约2km，大概率设备租赁。3.中铁隧道局正在施工解放路过江隧道，如投标，有较大价格优势。 工作思路：配合系统内单位共同跟进项目进展，拜访业主，核实业主对设备新旧等要求。 关键点：设备市场存有量较大，业主暂定设备新制，是否会被变更。 行动计划：拜访业主单位，配合系统内单位跟踪项目进展。 | AA38: 重点信息（Ⅱ级） | AB38: 沈腾飞 | AE38: 沈腾飞 | AF38: 跟进中 | AG38: 沈腾飞
A39: 46112 | B39: 2024-12-30 20:33:31 | C39: XM-2024123018583 | D39: 中铁二十一局集团川气东送项目 | F39: 该项目其中温州市区和瑞安市区有下穿瓯江和飞云江盾构段，长度分别为918米、737米。隧道断面分别为4.25米、3.08米。预计需求两台不同直径泥水盾构，需进一步了解施工单位设备来源。 | G39: 其中温州市区和瑞安市区有下穿瓯江和飞云江盾构段，长度分别为918米、737米。 | H39: 其他-13 | I39: 掘进机事业部 | J39: 华东区域 | L39: 浙江 | M39: 10.0000000000 | N39: 国家石油天然气管网集团有限公司西气东输分公司 | Q39: ZTS5040-1-(/);ZTS3770-1-(/); | R39: 2025-06-30 | S39: CNY 8,000,000.000 | T39: 袁志凌 | W39: 目前施工已中标，中标单位为中铁二十一局路桥公司，项目部正在选址；其中温州市区和瑞安市区有下穿瓯江和飞云江盾构段，长度分别为918米、737米。已与项目部进行交流洽谈，目前因市面上没有合适机型暂未确认设备来源，21局拟采用劳务专业分包，由分包队带设备，目前还在队伍洽谈中。暂无新进展。 该项目已于河北某劳务队洽谈设备租赁，由于未签订合同，项目部暂未告知公司名称。 项目已明确轨道公司分包劳务。设备拟采用安徽唐兴旧机维修改造。 | X39: 了解拟租设备及租赁合同价格 | Y39: 设计联络 | Z39: 已与项目部总工、设备部长对接，并邀请业主、设计和项目部到公司考察。由于隧道短，客户拟采用安徽唐兴旧机维修改造。 | AA39: 一般信息（Ⅲ级） | AB39: 袁志凌 | AE39: 袁志凌 | AF39: 跟进中 | AG39: 袁志凌
A40: 46112 | B40: 2024-03-11 11:18:15 | C40: XM-2024031116383 | D40: 中铁二十二局义龙庆7标项目部 | F40: 本项目主线右幅YK176+700～YK186+560段长约9.86公里、左幅ZK176+700～ZK186+550段长约9.85公里的路基、桥梁（含伸缩缝安装）、涵洞、隧道（含高位水池，不含隧道机电）、改路改河改渠（含改路路面）等的实施、完成、缺陷责任期缺陷修复等 | G40: 大淤山隧道：1475m；大丘田隧道：3452.5m | H40: 公路-4 | I40: 特种装备事业部 | J40: 华东区域 | L40: 浙江 | M40: 200.0000000000 | N40: 浙江省高速建设管理有限公司 | Q40: SCC2000-1-(/); | R40: 2024-08-20 | S40: CNY 16,000,000.000 | T40: 袁志凌 | W40: 已与项目业主和施工单位开展了技术交流和设备需求了解，该项目拟采用劳务专业分包，根据客户描述：由于设备昂贵，垫资成本过高，劳务队不能接受设备施工，目前项目部还在与劳务队沟通中 | X40: 跟进除尘台车需求，了解需求时间及设备考虑情况 继续跟进除尘台车需求 跟进是否有除尘台车需求 核实是否还有除尘台车采购需求 | Y40: 项目施工中标公示 | Z40: 核心问题：业主交代必须使用进口凿岩台车，设备基本由劳务队自带，劳务队更多考虑价格偏低厂家，我司设备没有价格和明显技术优势 工作思路：跟进好各标段劳务队设备需求及意向情况，联同研究院与其进行交流，凸显我司产品特征优势，紧密对接好部分有我司产品采购意向的单位和劳务队； 关键点：该项目智能化设备应用程度高，部分标段目前仍未确定采购进口凿岩台车，我司需紧密动态对接和跟进； 行动计划：联合研究院逐项对接项目部和劳务队，摸排劳务队设备持有及需求情况。 | AA40: 重点信息（Ⅱ级） | AB40: 袁志凌 | AE40: 袁志凌 | AF40: 跟进中 | AG40: 袁志凌
...

Sheet Sheet1
A1: 最后修改时间 | B1: (多项)
A3: 最后修改人 | B3: 计数项:项目名称
A4: 陈浩 | B4: 1
A5: 刘新峥 | B5: 10
A6: 沈腾飞 | B6: 9
A7: 唐作栋 | B7: 11
A8: 万赛 | B8: 1
A9: 杨志胜 | B9: 10
A10: 袁志凌 | B10: 3
A11: 赵宇瑄 | B11: 14
A12: 周斌 | B12: 14
A13: 总计 | B13: 73

Sheet Sheet3
A1: 责任人 | B1: 项目数量 | C1: 更新项目数量 | D1: 更新数量排名 | E1: 更新率 | F1: 更新率排名 | G1: 综合排名 （各占50%）
A2: 陈浩 | B2: 13 | C2: =VLOOKUP(A2,Sheet1!$A$3:$B$12,2,FALSE) -> 1 | D2: 8 | E2: =C2/B2 -> 0.076923077 | F2: 9 | G2: =D2*0.5+F2*0.5 -> 8.5
A3: 刘新峥 | B3: 11 | C3: 11 | D3: 3 | E3: =C3/B3 -> 1 | F3: 1 | G3: =D3*0.5+F3*0.5 -> 2
A4: 穆华清 | B4: 4 | C4: 0 | D4: 10 | E4: 0 | F4: 10 | G4: =D4*0.5+F4*0.5 -> 10
A5: 沈腾飞 | B5: 11 | C5: 10 | D5: 5 | E5: =C5/B5 -> 0.90909091 | F5: 4 | G5: =D5*0.5+F5*0.5 -> 4.5
A6: 唐作栋 | B6: 24 | C6: =VLOOKUP(A6,Sheet1!$A$3:$B$12,2,FALSE) -> 11 | D6: 3 | E6: =C6/B6 -> 0.45833333 | F6: 6 | G6: =D6*0.5+F6*0.5 -> 4.5
A7: 万赛 | B7: 7 | C7: =VLOOKUP(A7,Sheet1!$A$3:$B$12,2,FALSE) -> 1 | D7: 8 | E7: =C7/B7 -> 0.14285714 | F7: 8 | G7: =D7*0.5+F7*0.5 -> 8
A8: 杨志胜 | B8: 28 | C8: =VLOOKUP(A8,Sheet1!$A$3:$B$12,2,FALSE) -> 10 | D8: 5 | E8: =C8/B8 -> 0.35714286 | F8: 7 | G8: =D8*0.5+F8*0.5 -> 6
A9: 袁志凌 | B9: 3 | C9: =VLOOKUP(A9,Sheet1!$A$3:$B$12,2,FALSE) -> 3 | D9: 7 | E9: =C9/B9 -> 1 | F9: 1 | G9: =D9*0.5+F9*0.5 -> 4
A10: 赵宇瑄 | B10: 18 | C10: 15 | D10: 1 | E10: =C10/B10 -> 0.83333333 | F10: 5 | G10: =D10*0.5+F10*0.5 -> 3
A11: 周斌 | B11: 15 | C11: =VLOOKUP(A11,Sheet1!$A$3:$B$12,2,FALSE) -> 14 | D11: 2 | E11: =C11/B11 -> 0.93333333 | F11: 3 | G11: =D11*0.5+F11*0.5 -> 2.5
